Workbook
Name 作業リスト: '前日確定'!$B$26:$B$45
Name 船名リスト: OFFSET(マスター!$A$6,0,0,MAX(1,COUNTA(マスター!$A$6:$A$125)),1)
Name 会社リスト: OFFSET(マスター!$P$6,0,0,MAX(1,COUNTA(マスター!$P$6:$P$45)),1)
Name 基地港リスト: OFFSET(マスター!$U$6,0,0,MAX(1,COUNTA(マスター!$U$6:$U$25)),1)
Name 選択_確認状況: OFFSET(マスター!$X$6,0,0,MAX(1,COUNTA(マスター!$X$6:$X$25)),1)
Name 選択_照合: OFFSET(マスター!$Y$6,0,0,MAX(1,COUNTA(マスター!$Y$6:$Y$25)),1)
Name 選択_取消時点: OFFSET(マスター!$Z$6,0,0,MAX(1,COUNTA(マスター!$Z$6:$Z$25)),1)
Name 選択_理由: OFFSET(マスター!$AA$6,0,0,MAX(1,COUNTA(マスター!$AA$6:$AA$25)),1)
Name 選択_時間調整: OFFSET(マスター!$AB$6,0,0,MAX(1,COUNTA(マスター!$AB$6:$AB$25)),1)
Name 選択_呼出理由: OFFSET(マスター!$AC$6,0,0,MAX(1,COUNTA(マスター!$AC$6:$AC$25)),1)
Name 選択_作業内容: OFFSET(マスター!$AD$6,0,0,MAX(1,COUNTA(マスター!$AD$6:$AD$25)),1)
Name 選択_時刻基準: OFFSET(マスター!$AE$6,0,0,MAX(1,COUNTA(マスター!$AE$6:$AE$25)),1)
Name 選択_種類: OFFSET(マスター!$AF$6,0,0,MAX(1,COUNTA(マスター!$AF$6:$AF$25)),1)
Name 選択_時刻確認: OFFSET(マスター!$AG$6,0,0,MAX(1,COUNTA(マスター!$AG$6:$AG$25)),1)
Name 選択_会社区分: OFFSET(マスター!$AH$6,0,0,MAX(1,COUNTA(マスター!$AH$6:$AH$25)),1)
Name 選択_日確認: OFFSET(マスター!$AI$6,0,0,MAX(1,COUNTA(マスター!$AI$6:$AI$25)),1)

Sheet はじめに
B1: 八幡地区 常駐体制検証 入力試作 v01
B3: 目的 | C3: 製鉄曳船の3隻と4隻で対応の差を説明するための基礎データを集めます。この試作は、入力と集計のつながりを試すためのものです。4隻の必要性を証明するものではありません。
B4: 対象 | C4: 元帳R7年度のうち、同時3隻以上の候補日 2025年12月06日 の1日分（実績17行・9作業）。元帳の時刻は「候補・時刻要確認」です。
B5: 最初の操作 | C5: 下の青い文字を押すと、最初の入力欄（前日確定シートC7：根拠の予定表）へ移動します。
B6: 入力の順番 | C6: ①前日確定 → ②変更・キャンセル → ③入渠・他港作業・他社配置 → ④標準時間。船名や会社が選択肢にないときは、先にマスターへ追加します。
B7: 担当者 | C7: 前日確定・変更・キャンセル・製鉄曳船の入渠・八幡タグの標準時間：上田さん／西日本海運の他港作業・入渠・標準時間：西日本海運担当者／他社配置：分かる範囲で上田さん
B8: 色の意味 | C8: 薄い黄色＝入力する欄（見出しに【入力】）／薄い灰色＝自動表示（見出しに【自動】）。灰色の欄は入力しません。
B9: 選び方 | C9: 船名・会社・理由などはセルを選ぶと出る▼の一覧から選びます。○の欄は▼から○を選びます。ボタンやマクロは使っていません。
B10: 未確認の意味 | C10: 資料で確かめられていないことです。推測で埋めず「未確認」のまま残します。確認できたら「確認済み」に変えます。
B11: 再入力しない | C11: 本船名・タグ名・実績時刻は元帳から自動表示します。作業番号の入力は不要で、作業は▼の一覧から選びます。
B12: 前日確定と変更 | C12: 前日最終の予定は「前日確定」に入れ、変更があっても上書きしません。変更は「変更・キャンセル」に1回ごとに1行追加します。
B13: 実績のない取消し | C13: 予定表にあって元帳にない作業は、「前日確定」の下の空き行に本船名などを入れて追加し、「変更・キャンセル」で選んで取消しを入力します。
B14: 安瀬 | C14: 安瀬は若松との按分配船です。応援とは別に数えます（品名「支給炭」を安瀬候補として仮に表示。要確認）。
... B19: 色見本 | C19: 入力する欄【入力】
C20: 自動表示の欄【自動】
B22: シートの役割
B23: 実績 | C23: 元帳の取り込み（見るだけ）
B24: 前日確定 | C24: 前日最終の予定・予定タグ・翌日の出勤手配
B25: 変更・キャンセル | C25: 日ごとの変更確認、休船からの呼出、変更・取消しの記録
B26: 入渠 | C26: 作業に使えない期間
B27: 他港作業 | C27: 西日本海運の全他港作業
B28: 他社配置 | C28: 若松・関門等の他社の体制
B29: 標準時間 | C29: 基地発～基地着の見込み時間
B30: マスター | C30: 会社・船名・基地港・選択肢の追加
B31: 集計 | C31: 対比結果と不足情報（自動）

Sheet 実績
A1: 実績（元帳から自動表示・再入力しない）
A2: 誰が：全員が見るだけ 何を見て：元帳「作業実績R6.4～」シート「R7年度」 どこへ：入力欄はありません（休船からの呼出は「変更・キャンセル」で最初に対応した作業を選びます）
A3: 対象日 2025/12/06。時刻は元帳の「作業時間」で、基地発・基地着かは未確認のため「候補・時刻要確認」。集計先：「集計」「前日確定」「変更・キャンセル」
A5: 作業キー【自動】 | B5: 作業の表示名【自動】 | C5: 作業の先頭行【自動】 | D5: 作業日【自動】 | E5: 元帳の行番号【自動】 | F5: 元帳No【自動】 | G5: 本船名【自動】 | H5: G/T【自動】 | I5: 代理店（参考・会社判定に使わない）【自動】 | J5: 入出転【自動】 | K5: 六/部【自動】 | L5: バース【自動】 | M5: 品名【自動】 | N5: 予定時間（元帳・定義未確認）【自動】 | O5: 作業開始（元帳）【自動】 | P5: 作業終了（元帳）【自動】 | Q5: 終了が翌日【自動】 | R5: タグ（元帳の記号）【自動】 | S5: S列の記号（参考）【自動】 | T5: 備考1（元帳）【自動】 | U5: 取消しの記載【自動】 | V5: 時刻の扱い【自動】 | W5: 集計船名【自動】 | X5: 会社【自動】 | Y5: 会社区分【自動】 | Z5: 船名・会社の確認状況【自動】 | AA5: 船の種類【自動】 | AB5: 安瀬の扱い【自動】 | AC5: 開始（分）【自動】 | AD5: 終了（分）【自動】 | AE5: 同時稼働に含む【自動】 | AF5: 作業の開始（分）【自動】 | AG5: 作業の終了（分）【自動】 | AH5: 重複配船の警告【自動】
A6: 2025-12-06#01 | B6: 12/06 #01 07:30 入 GRAND MUSE（OT） | C6: ○ | D6: 45997 | E6: 2083 | F6: 20 | G6: GRAND MUSE | H6: 1137 | I6: 矢野 | J6: 入 | K6: 六 | L6: OT | M6: その他 | N6: 0.3125 | O6: 0.32291667 | P6: 0.38541667 | R6: P | V6: 候補・時刻要確認 | W6: =IFERROR(INDEX(マスター!$J$6:$J$125,MATCH(R6,マスター!$M$6:$M$125,0)),R6) | X6: =IFERROR(IF(INDEX(マスター!$C$6:$C$125,MATCH(R6,マスター!$M$6:$M$125,0))="","未確認",INDEX(マスター!$C$6:$C$125,MATCH(R6,マスター!$M$6:$M$125,0))),"マスター未登録") | Y6: =IFERROR(INDEX(マスター!$K$6:$K$125,MATCH(R6,マスター!$M$6:$M$125,0)),"マスター未登録") | Z6: =IFERROR(IF(INDEX(マスター!$I$6:$I$125,MATCH(R6,マスター!$M$6:$M$125,0))="","未確認",INDEX(マスター!$I$6:$I$125,MATCH(R6,マスター!$M$6:$M$125,0))),"マスター未登録") | AA6: =IFERROR(IF(INDEX(マスター!$D$6:$D$125,MATCH(R6,マスター!$M$6:$M$125,0))="","未確認",INDEX(マスター!$D$6:$D$125,MATCH(R6,マスター!$M$6:$M$125,0))),"マスター未登録") | AB6: =IF(M6="支給炭","安瀬候補（要確認）","") | AC6: =IF(OR(O6="",V6<>"候補・時刻要確認"),"",ROUND((D6-集計!$C$5)*1440+O6*1440,0)) | AD6: =IF(OR(P6="",V6<>"候補・時刻要確認"),"",ROUND((D6-集計!$C$5)*1440+P6*1440+IF(Q6="○",1440,0),0)) | AE6: =IF(AND(AC6<>"",AD6<>"",U6<>"○",AA6<>"通船・警戒船"),"○","") | AF6: =IF(C6<>"○","",IF(COUNTIFS($A$6:$A$505,A6,$AE$6:$AE$505,"○")=0,"",_xlfn.MINIFS($AC$6:$AC$505,$A$6:$A$505,A6,$AE$6:$AE$505,"○"))) | AG6: =IF(C6<>"○","",IF(COUNTIFS($A$6:$A$505,A6,$AE$6:$AE$505,"○")=0,"",_xlfn.MAXIFS($AD$6:$AD$505,$A$6:$A$505,A6,$AE$6:$AE$505,"○"))) | AH6: =IF(AE6<>"○","",IF(COUNTIFS($W$6:$W$505,W6,$AC$6:$AC$505,"<"&AD6,$AD$6:$AD$505,">"&AC6,$AE$6:$AE$505,"○")>1,"同じ船の時間が重なっています",""))
A7: 2025-12-06#02 | B7: 12/06 #02 07:30 入 RICH SEA（OD2） | C7: ○ | D7: 45997 | E7: 2084 | F7: 21 | G7: RICH SEA | H7: 4334 | I7: 矢野 | J7: 入 | K7: 六 | L7: OD2 | M7: その他 | N7: 0.3125 | O7: 0.32291667 | P7: 0.38541667 | R7: M | V7: 候補・時刻要確認 | W7: =IFERROR(INDEX(マスター!$J$6:$J$125,MATCH(R7,マスター!$M$6:$M$125,0)),R7) | X7: =IFERROR(IF(INDEX(マスター!$C$6:$C$125,MATCH(R7,マスター!$M$6:$M$125,0))="","未確認",INDEX(マスター!$C$6:$C$125,MATCH(R7,マスター!$M$6:$M$125,0))),"マスター未登録") | Y7: =IFERROR(INDEX(マスター!$K$6:$K$125,MATCH(R7,マスター!$M$6:$M$125,0)),"マスター未登録") | Z7: =IFERROR(IF(INDEX(マスター!$I$6:$I$125,MATCH(R7,マスター!$M$6:$M$125,0))="","未確認",INDEX(マスター!$I$6:$I$125,MATCH(R7,マスター!$M$6:$M$125,0))),"マスター未登録") | AA7: =IFERROR(IF(INDEX(マスター!$D$6:$D$125,MATCH(R7,マスター!$M$6:$M$125,0))="","未確認",INDEX(マスター!$D$6:$D$125,MATCH(R7,マスター!$M$6:$M$125,0))),"マスター未登録") | AB7: =IF(M7="支給炭","安瀬候補（要確認）","") | AC7: =IF(OR(O7="",V7<>"候補・時刻要確認"),"",ROUND((D7-集計!$C$5)*1440+O7*1440,0)) | AD7: =IF(OR(P7="",V7<>"候補・時刻要確認"),"",ROUND((D7-集計!$C$5)*1440+P7*1440+IF(Q7="○",1440,0),0)) | AE7: =IF(AND(AC7<>"",AD7<>"",U7<>"○",AA7<>"通船・警戒船"),"○","") | AF7: =IF(C7<>"○","",IF(COUNTIFS($A$6:$A$505,A7,$AE$6:$AE$505,"○")=0,"",_xlfn.MINIFS($AC$6:$AC$505,$A$6:$A$505,A7,$AE$6:$AE$505,"○"))) | AG7: =IF(C7<>"○","",IF(COUNTIFS($A$6:$A$505,A7,$AE$6:$AE$505,"○")=0,"",_xlfn.MAXIFS($AD$6:$AD$505,$A$6:$A$505,A7,$AE$6:$AE$505,"○"))) | AH7: =IF(AE7<>"○","",IF(COUNTIFS($W$6:$W$505,W7,$AC$6:$AC$505,"<"&AD7,$AD$6:$AD$505,">"&AC7,$AE$6:$AE$505,"○")>1,"同じ船の時間が重なっています",""))
A8: 2025-12-06#03 | B8: 12/06 #03 08:00 転 KAIROS TRIUMPH（N5-Y15） | C8: ○ | D8: 45997 | E8: 2085 | F8: 22 | G8: KAIROS TRIUMPH | H8: 7135 | I8: 日本製鉄 | J8: 転 | L8: N5-Y15 | M8: 鋼材 | N8: 0.33333333 | O8: 0.29166667 | P8: 0.35416667 | R8: T | V8: 候補・時刻要確認 | W8: =IFERROR(INDEX(マスター!$J$6:$J$125,MATCH(R8,マスター!$M$6:$M$125,0)),R8) | X8: =IFERROR(IF(INDEX(マスター!$C$6:$C$125,MATCH(R8,マスター!$M$6:$M$125,0))="","未確認",INDEX(マスター!$C$6:$C$125,MATCH(R8,マスター!$M$6:$M$125,0))),"マスター未登録") | Y8: =IFERROR(INDEX(マスター!$K$6:$K$125,MATCH(R8,マスター!$M$6:$M$125,0)),"マスター未登録") | Z8: =IFERROR(IF(INDEX(マスター!$I$6:$I$125,MATCH(R8,マスター!$M$6:$M$125,0))="","未確認",INDEX(マスター!$I$6:$I$125,MATCH(R8,マスター!$M$6:$M$125,0))),"マスター未登録") | AA8: =IFERROR(IF(INDEX(マスター!$D$6:$D$125,MATCH(R8,マスター!$M$6:$M$125,0))="","未確認",INDEX(マスター!$D$6:$D$125,MATCH(R8,マスター!$M$6:$M$125,0))),"マスター未登録") | AB8: =IF(M8="支給炭","安瀬候補（要確認）","") | AC8: =IF(OR(O8="",V8<>"候補・時刻要確認"),"",ROUND((D8-集計!$C$5)*1440+O8*1440,0)) | AD8: =IF(OR(P8="",V8<>"候補・時刻要確認"),"",ROUND((D8-集計!$C$5)*1440+P8*1440+IF(Q8="○",1440,0),0)) | AE8: =IF(AND(AC8<>"",AD8<>"",U8<>"○",AA8<>"通船・警戒船"),"○","") | AF8: =IF(C8<>"○","",IF(COUNTIFS($A$6:$A$505,A8,$AE$6:$AE$505,"○")=0,"",_xlfn.MINIFS($AC$6:$AC$505,$A$6:$A$505,A8,$AE$6:$AE$505,"○"))) | AG8: =IF(C8<>"○","",IF(COUNTIFS($A$6:$A$505,A8,$AE$6:$AE$505,"○")=0,"",_xlfn.MAXIFS($AD$6:$AD$505,$A$6:$A$505,A8,$AE$6:$AE$505,"○"))) | AH8: =IF(AE8<>"○","",IF(COUNTIFS($W$6:$W$505,W8,$AC$6:$AC$505,"<"&AD8,$AD$6:$AD$505,">"&AC8,$AE$6:$AE$505,"○")>1,"同じ船の時間が重なっています",""))
A9: 2025-12-06#03 | B9: 12/06 #03 08:00 転 KAIROS TRIUMPH（N5-Y15） | D9: 45997 | E9: 2086 | G9: KAIROS TRIUMPH | H9: 7135 | I9: 日本製鉄 | J9: 転 | L9: N5-Y15 | M9: 鋼材 | N9: 0.33333333 | O9: 0.29166667 | P9: 0.35416667 | R9: Y | V9: 候補・時刻要確認 | W9: =IFERROR(INDEX(マスター!$J$6:$J$125,MATCH(R9,マスター!$M$6:$M$125,0)),R9) | X9: =IFERROR(IF(INDEX(マスター!$C$6:$C$125,MATCH(R9,マスター!$M$6:$M$125,0))="","未確認",INDEX(マスター!$C$6:$C$125,MATCH(R9,マスター!$M$6:$M$125,0))),"マスター未登録") | Y9: =IFERROR(INDEX(マスター!$K$6:$K$125,MATCH(R9,マスター!$M$6:$M$125,0)),"マスター未登録") | Z9: =IFERROR(IF(INDEX(マスター!$I$6:$I$125,MATCH(R9,マスター!$M$6:$M$125,0))="","未確認",INDEX(マスター!$I$6:$I$125,MATCH(R9,マスター!$M$6:$M$125,0))),"マスター未登録") | AA9: =IFERROR(IF(INDEX(マスター!$D$6:$D$125,MATCH(R9,マスター!$M$6:$M$125,0))="","未確認",INDEX(マスター!$D$6:$D$125,MATCH(R9,マスター!$M$6:$M$125,0))),"マスター未登録") | AB9: =IF(M9="支給炭","安瀬候補（要確認）","") | AC9: =IF(OR(O9="",V9<>"候補・時刻要確認"),"",ROUND((D9-集計!$C$5)*1440+O9*1440,0)) | AD9: =IF(OR(P9="",V9<>"候補・時刻要確認"),"",ROUND((D9-集計!$C$5)*1440+P9*1440+IF(Q9="○",1440,0),0)) | AE9: =IF(AND(AC9<>"",AD9<>"",U9<>"○",AA9<>"通船・警戒船"),"○","") | AF9: =IF(C9<>"○","",IF(COUNTIFS($A$6:$A$505,A9,$AE$6:$AE$505,"○")=0,"",_xlfn.MINIFS($AC$6:$AC$505,$A$6:$A$505,A9,$AE$6:$AE$505,"○"))) | AG9: =IF(C9<>"○","",IF(COUNTIFS($A$6:$A$505,A9,$AE$6:$AE$505,"○")=0,"",_xlfn.MAXIFS($AD$6:$AD$505,$A$6:$A$505,A9,$AE$6:$AE$505,"○"))) | AH9: =IF(AE9<>"○","",IF(COUNTIFS($W$6:$W$505,W9,$AC$6:$AC$505,"<"&AD9,$AD$6:$AD$505,">"&AC9,$AE$6:$AE$505,"○")>1,"同じ船の時間が重なっています",""))
A10: 2025-12-06#04 | B10: 12/06 #04 08:00 入 FIRST AI（N5） | C10: ○ | D10: 45997 | E10: 2087 | F10: 23 | G10: FIRST AI | H10: 1501 | I10: 門港 | J10: 入 | K10: 六 | L10: N5 | M10: 鋼材 | N10: 0.33333333 | O10: 0.3125 | P10: 0.38888889 | R10: S | V10: 候補・時刻要確認 | W10: =IFERROR(INDEX(マスター!$J$6:$J$125,MATCH(R10,マスター!$M$6:$M$125,0)),R10) | X10: =IFERROR(IF(INDEX(マスター!$C$6:$C$125,MATCH(R10,マスター!$M$6:$M$125,0))="","未確認",INDEX(マスター!$C$6:$C$125,MATCH(R10,マスター!$M$6:$M$125,0))),"マスター未登録") | Y10: =IFERROR(INDEX(マスター!$K$6:$K$125,MATCH(R10,マスター!$M$6:$M$125,0)),"マスター未登録") | Z10: =IFERROR(IF(INDEX(マスター!$I$6:$I$125,MATCH(R10,マスター!$M$6:$M$125,0))="","未確認",INDEX(マスター!$I$6:$I$125,MATCH(R10,マスター!$M$6:$M$125,0))),"マスター未登録") | AA10: =IFERROR(IF(INDEX(マスター!$D$6:$D$125,MATCH(R10,マスター!$M$6:$M$125,0))="","未確認",INDEX(マスター!$D$6:$D$125,MATCH(R10,マスター!$M$6:$M$125,0))),"マスター未登録") | AB10: =IF(M10="支給炭","安瀬候補（要確認）","") | AC10: =IF(OR(O10="",V10<>"候補・時刻要確認"),"",ROUND((D10-集計!$C$5)*1440+O10*1440,0)) | AD10: =IF(OR(P10="",V10<>"候補・時刻要確認"),"",ROUND((D10-集計!$C$5)*1440+P10*1440+IF(Q10="○",1440,0),0)) | AE10: =IF(AND(AC10<>"",AD10<>"",U10<>"○",AA10<>"通船・警戒船"),"○","") | AF10: =IF(C10<>"○","",IF(COUNTIFS($A$6:$A$505,A10,$AE$6:$AE$505,"○")=0,"",_xlfn.MINIFS($AC$6:$AC$505,$A$6:$A$505,A10,$AE$6:$AE$505,"○"))) | AG10: =IF(C10<>"○","",IF(COUNTIFS($A$6:$A$505,A10,$AE$6:$AE$505,"○")=0,"",_xlfn.MAXIFS($AD$6:$AD$505,$A$6:$A$505,A10,$AE$6:$AE$505,"○"))) | AH10: =IF(AE10<>"○","",IF(COUNTIFS($W$6:$W$505,W10,$AC$6:$AC$505,"<"&AD10,$AD$6:$AD$505,">"&AC10,$AE$6:$AE$505,"○")>1,"同じ船の時間が重なっています",""))
A11: 2025-12-06#05 | B11: 12/06 #05 12:15 出 NEW NATION（N4） | C11: ○ | D11: 45997 | E11: 2088 | F11: 24 | G11: NEW NATION | H11: 25855 | I11: 東 | J11: 出 | L11: N4 | M11: 鋼材 | N11: 0.51041667 | O11: 0.46875 | P11: 0.52430556 | R11: 関 | S11: 西 | V11: 候補・時刻要確認 | W11: =IFERROR(INDEX(マスター!$J$6:$J$125,MATCH(R11,マスター!$M$6:$M$125,0)),R11) | X11: =IFERROR(IF(INDEX(マスター!$C$6:$C$125,MATCH(R11,マスター!$M$6:$M$125,0))="","未確認",INDEX(マスター!$C$6:$C$125,MATCH(R11,マスター!$M$6:$M$125,0))),"マスター未登録") | Y11: =IFERROR(INDEX(マスター!$K$6:$K$125,MATCH(R11,マスター!$M$6:$M$125,0)),"マスター未登録") | Z11: =IFERROR(IF(INDEX(マスター!$I$6:$I$125,MATCH(R11,マスター!$M$6:$M$125,0))="","未確認",INDEX(マスター!$I$6:$I$125,MATCH(R11,マスター!$M$6:$M$125,0))),"マスター未登録") | AA11: =IFERROR(IF(INDEX(マスター!$D$6:$D$125,MATCH(R11,マスター!$M$6:$M$125,0))="","未確認",INDEX(マスター!$D$6:$D$125,MATCH(R11,マスター!$M$6:$M$125,0))),"マスター未登録") | AB11: =IF(M11="支給炭","安瀬候補（要確認）","") | AC11: =IF(OR(O11="",V11<>"候補・時刻要確認"),"",ROUND((D11-集計!$C$5)*1440+O11*1440,0)) | AD11: =IF(OR(P11="",V11<>"候補・時刻要確認"),"",ROUND((D11-集計!$C$5)*1440+P11*1440+IF(Q11="○",1440,0),0)) | AE11: =IF(AND(AC11<>"",AD11<>"",U11<>"○",AA11<>"通船・警戒船"),"○","") | AF11: =IF(C11<>"○","",IF(COUNTIFS($A$6:$A$505,A11,$AE$6:$AE$505,"○")=0,"",_xlfn.MINIFS($AC$6:$AC$505,$A$6:$A$505,A11,$AE$6:$AE$505,"○"))) | AG11: =IF(C11<>"○","",IF(COUNTIFS($A$6:$A$505,A11,$AE$6:$AE$505,"○")=0,"",_xlfn.MAXIFS($AD$6:$AD$505,$A$6:$A$505,A11,$AE$6:$AE$505,"○"))) | AH11: =IF(AE11<>"○","",IF(COUNTIFS($W$6:$W$505,W11,$AC$6:$AC$505,"<"&AD11,$AD$6:$AD$505,">"&AC11,$AE$6:$AE$505,"○")>1,"同じ船の時間が重なっています",""))
A12: 2025-12-06#05 | B12: 12/06 #05 12:15 出 NEW NATION（N4） | D12: 45997 | E12: 2089 | G12: NEW NATION | H12: 25855 | I12: 東 | J12: 出 | L12: N4 | M12: 鋼材 | N12: 0.51041667 | O12: 0.46875 | P12: 0.52430556 | R12: 長 | S12: 西 | V12: 候補・時刻要確認 | W12: =IFERROR(INDEX(マスター!$J$6:$J$125,MATCH(R12,マスター!$M$6:$M$125,0)),R12) | X12: =IFERROR(IF(INDEX(マスター!$C$6:$C$125,MATCH(R12,マスター!$M$6:$M$125,0))="","未確認",INDEX(マスター!$C$6:$C$125,MATCH(R12,マスター!$M$6:$M$125,0))),"マスター未登録") | Y12: =IFERROR(INDEX(マスター!$K$6:$K$125,MATCH(R12,マスター!$M$6:$M$125,0)),"マスター未登録") | Z12: =IFERROR(IF(INDEX(マスター!$I$6:$I$125,MATCH(R12,マスター!$M$6:$M$125,0))="","未確認",INDEX(マスター!$I$6:$I$125,MATCH(R12,マスター!$M$6:$M$125,0))),"マスター未登録") | AA12: =IFERROR(IF(INDEX(マスター!$D$6:$D$125,MATCH(R12,マスター!$M$6:$M$125,0))="","未確認",INDEX(マスター!$D$6:$D$125,MATCH(R12,マスター!$M$6:$M$125,0))),"マスター未登録") | AB12: =IF(M12="支給炭","安瀬候補（要確認）","") | AC12: =IF(OR(O12="",V12<>"候補・時刻要確認"),"",ROUND((D12-集計!$C$5)*1440+O12*1440,0)) | AD12: =IF(OR(P12="",V12<>"候補・時刻要確認"),"",ROUND((D12-集計!$C$5)*1440+P12*1440+IF(Q12="○",1440,0),0)) | AE12: =IF(AND(AC12<>"",AD12<>"",U12<>"○",AA12<>"通船・警戒船"),"○","") | AF12: =IF(C12<>"○","",IF(COUNTIFS($A$6:$A$505,A12,$AE$6:$AE$505,"○")=0,"",_xlfn.MINIFS($AC$6:$AC$505,$A$6:$A$505,A12,$AE$6:$AE$505,"○"))) | AG12: =IF(C12<>"○","",IF(COUNTIFS($A$6:$A$505,A12,$AE$6:$AE$505,"○")=0,"",_xlfn.MAXIFS($AD$6:$AD$505,$A$6:$A$505,A12,$AE$6:$AE$505,"○"))) | AH12: =IF(AE12<>"○","",IF(COUNTIFS($W$6:$W$505,W12,$AC$6:$AC$505,"<"&AD12,$AD$6:$AD$505,">"&AC12,$AE$6:$AE$505,"○")>1,"同じ船の時間が重なっています",""))
A13: 2025-12-06#06 | B13: 12/06 #06 12:30 入 TEXAS HARMONY（N4） | C13: ○ | D13: 45997 | E13: 2090 | F13: 25 | G13: TEXAS HARMONY | H13: 24331 | I13: 東 | J13: 入 | K13: 六 | L13: N4 | M13: 鋼材 | N13: 0.52083333 | O13: 0.5 | P13: 0.58333333 | R13: 竜山 | S13: 矢 | V13: 候補・時刻要確認 | W13: =IFERROR(INDEX(マスター!$J$6:$J$125,MATCH(R13,マスター!$M$6:$M$125,0)),R13) | X13: =IFERROR(IF(INDEX(マスター!$C$6:$C$125,MATCH(R13,マスター!$M$6:$M$125,0))="","未確認",INDEX(マスター!$C$6:$C$125,MATCH(R13,マスター!$M$6:$M$125,0))),"マスター未登録") | Y13: =IFERROR(INDEX(マスター!$K$6:$K$125,MATCH(R13,マスター!$M$6:$M$125,0)),"マスター未登録") | Z13: =IFERROR(IF(INDEX(マスター!$I$6:$I$125,MATCH(R13,マスター!$M$6:$M$125,0))="","未確認",INDEX(マスター!$I$6:$I$125,MATCH(R13,マスター!$M$6:$M$125,0))),"マスター未登録") | AA13: =IFERROR(IF(INDEX(マスター!$D$6:$D$125,MATCH(R13,マスター!$M$6:$M$125,0))="","未確認",INDEX(マスター!$D$6:$D$125,MATCH(R13,マスター!$M$6:$M$125,0))),"マスター未登録") | AB13: =IF(M13="支給炭","安瀬候補（要確認）","") | AC13: =IF(OR(O13="",V13<>"候補・時刻要確認"),"",ROUND((D13-集計!$C$5)*1440+O13*1440,0)) | AD13: =IF(OR(P13="",V13<>"候補・時刻要確認"),"",ROUND((D13-集計!$C$5)*1440+P13*1440+IF(Q13="○",1440,0),0)) | AE13: =IF(AND(AC13<>"",AD13<>"",U13<>"○",AA13<>"通船・警戒船"),"○","") | AF13: =IF(C13<>"○","",IF(COUNTIFS($A$6:$A$505,A13,$AE$6:$AE$505,"○")=0,"",_xlfn.MINIFS($AC$6:$AC$505,$A$6:$A$505,A13,$AE$6:$AE$505,"○"))) | AG13: =IF(C13<>"○","",IF(COUNTIFS($A$6:$A$505,A13,$AE$6:$AE$505,"○")=0,"",_xlfn.MAXIFS($AD$6:$AD$505,$A$6:$A$505,A13,$AE$6:$AE$505,"○"))) | AH13: =IF(AE13<>"○","",IF(COUNTIFS($W$6:$W$505,W13,$AC$6:$AC$505,"<"&AD13,$AD$6:$AD$505,">"&AC13,$AE$6:$AE$505,"○")>1,"同じ船の時間が重なっています",""))
A14: 2025-12-06#06 | B14: 12/06 #06 12:30 入 TEXAS HARMONY（N4） | D14: 45997 | E14: 2091 | G14: TEXAS HARMONY | H14: 24331 | I14: 東 | J14: 入 | K14: 六 | L14: N4 | M14: 鋼材 | N14: 0.52083333 | O14: 0.5 | P14: 0.58333333 | R14: さくら | S14: 洞 | V14: 候補・時刻要確認 | W14: =IFERROR(INDEX(マスター!$J$6:$J$125,MATCH(R14,マスター!$M$6:$M$125,0)),R14) | X14: =IFERROR(IF(INDEX(マスター!$C$6:$C$125,MATCH(R14,マスター!$M$6:$M$125,0))="","未確認",INDEX(マスター!$C$6:$C$125,MATCH(R14,マスター!$M$6:$M$125,0))),"マスター未登録") | Y14: =IFERROR(INDEX(マスター!$K$6:$K$125,MATCH(R14,マスター!$M$6:$M$125,0)),"マスター未登録") | Z14: =IFERROR(IF(INDEX(マスター!$I$6:$I$125,MATCH(R14,マスター!$M$6:$M$125,0))="","未確認",INDEX(マスター!$I$6:$I$125,MATCH(R14,マスター!$M$6:$M$125,0))),"マスター未登録") | AA14: =IFERROR(IF(INDEX(マスター!$D$6:$D$125,MATCH(R14,マスター!$M$6:$M$125,0))="","未確認",INDEX(マスター!$D$6:$D$125,MATCH(R14,マスター!$M$6:$M$125,0))),"マスター未登録") | AB14: =IF(M14="支給炭","安瀬候補（要確認）","") | AC14: =IF(OR(O14="",V14<>"候補・時刻要確認"),"",ROUND((D14-集計!$C$5)*1440+O14*1440,0)) | AD14: =IF(OR(P14="",V14<>"候補・時刻要確認"),"",ROUND((D14-集計!$C$5)*1440+P14*1440+IF(Q14="○",1440,0),0)) | AE14: =IF(AND(AC14<>"",AD14<>"",U14<>"○",AA14<>"通船・警戒船"),"○","") | AF14: =IF(C14<>"○","",IF(COUNTIFS($A$6:$A$505,A14,$AE$6:$AE$505,"○")=0,"",_xlfn.MINIFS($AC$6:$AC$505,$A$6:$A$505,A14,$AE$6:$AE$505,"○"))) | AG14: =IF(C14<>"○","",IF(COUNTIFS($A$6:$A$505,A14,$AE$6:$AE$505,"○")=0,"",_xlfn.MAXIFS($AD$6:$AD$505,$A$6:$A$505,A14,$AE$6:$AE$505,"○"))) | AH14: =IF(AE14<>"○","",IF(COUNTIFS($W$6:$W$505,W14,$AC$6:$AC$505,"<"&AD14,$AD$6:$AD$505,">"&AC14,$AE$6:$AE$505,"○")>1,"同じ船の時間が重なっています",""))
A15: 2025-12-06#07 | B15: 12/06 #07 13:00 入 LNG MARS（ZL） | C15: ○ | D15: 45997 | E15: 2092 | F15: 26 | G15: LNG MARS | H15: 136710 | I15: GS | J15: 入 | K15: 六 | L15: ZL | M15: LNG | N15: 0.54166667 | O15: 0.45833333 | P15: 0.6875 | R15: S | V15: 候補・時刻要確認 | W15: =IFERROR(INDEX(マスター!$J$6:$J$125,MATCH(R15,マスター!$M$6:$M$125,0)),R15) | X15: =IFERROR(IF(INDEX(マスター!$C$6:$C$125,MATCH(R15,マスター!$M$6:$M$125,0))="","未確認",INDEX(マスター!$C$6:$C$125,MATCH(R15,マスター!$M$6:$M$125,0))),"マスター未登録") | Y15: =IFERROR(INDEX(マスター!$K$6:$K$125,MATCH(R15,マスター!$M$6:$M$125,0)),"マスター未登録") | Z15: =IFERROR(IF(INDEX(マスター!$I$6:$I$125,MATCH(R15,マスター!$M$6:$M$125,0))="","未確認",INDEX(マスター!$I$6:$I$125,MATCH(R15,マスター!$M$6:$M$125,0))),"マスター未登録") | AA15: =IFERROR(IF(INDEX(マスター!$D$6:$D$125,MATCH(R15,マスター!$M$6:$M$125,0))="","未確認",INDEX(マスター!$D$6:$D$125,MATCH(R15,マスター!$M$6:$M$125,0))),"マスター未登録") | AB15: =IF(M15="支給炭","安瀬候補（要確認）","") | AC15: =IF(OR(O15="",V15<>"候補・時刻要確認"),"",ROUND((D15-集計!$C$5)*1440+O15*1440,0)) | AD15: =IF(OR(P15="",V15<>"候補・時刻要確認"),"",ROUND((D15-集計!$C$5)*1440+P15*1440+IF(Q15="○",1440,0),0)) | AE15: =IF(AND(AC15<>"",AD15<>"",U15<>"○",AA15<>"通船・警戒船"),"○","") | AF15: =IF(C15<>"○","",IF(COUNTIFS($A$6:$A$505,A15,$AE$6:$AE$505,"○")=0,"",_xlfn.MINIFS($AC$6:$AC$505,$A$6:$A$505,A15,$AE$6:$AE$505,"○"))) | AG15: =IF(C15<>"○","",IF(COUNTIFS($A$6:$A$505,A15,$AE$6:$AE$505,"○")=0,"",_xlfn.MAXIFS($AD$6:$AD$505,$A$6:$A$505,A15,$AE$6:$AE$505,"○"))) | AH15: =IF(AE15<>"○","",IF(COUNTIFS($W$6:$W$505,W15,$AC$6:$AC$505,"<"&AD15,$AD$6:$AD$505,">"&AC15,$AE$6:$AE$505,"○")>1,"同じ船の時間が重なっています",""))
A16: 2025-12-06#07 | B16: 12/06 #07 13:00 入 LNG MARS（ZL） | D16: 45997 | E16: 2093 | G16: LNG MARS | H16: 136710 | I16: GS | J16: 入 | K16: 六 | L16: ZL | M16: LNG | N16: 0.54166667 | O16: 0.5 | P16: 0.6875 | R16: T | V16: 候補・時刻要確認 | W16: =IFERROR(INDEX(マスター!$J$6:$J$125,MATCH(R16,マスター!$M$6:$M$125,0)),R16) | X16: =IFERROR(IF(INDEX(マスター!$C$6:$C$125,MATCH(R16,マスター!$M$6:$M$125,0))="","未確認",INDEX(マスター!$C$6:$C$125,MATCH(R16,マスター!$M$6:$M$125,0))),"マスター未登録") | Y16: =IFERROR(INDEX(マスター!$K$6:$K$125,MATCH(R16,マスター!$M$6:$M$125,0)),"マスター未登録") | Z16: =IFERROR(IF(INDEX(マスター!$I$6:$I$125,MATCH(R16,マスター!$M$6:$M$125,0))="","未確認",INDEX(マスター!$I$6:$I$125,MATCH(R16,マスター!$M$6:$M$125,0))),"マスター未登録") | AA16: =IFERROR(IF(INDEX(マスター!$D$6:$D$125,MATCH(R16,マスター!$M$6:$M$125,0))="","未確認",INDEX(マスター!$D$6:$D$125,MATCH(R16,マスター!$M$6:$M$125,0))),"マスター未登録") | AB16: =IF(M16="支給炭","安瀬候補（要確認）","") | AC16: =IF(OR(O16="",V16<>"候補・時刻要確認"),"",ROUND((D16-集計!$C$5)*1440+O16*1440,0)) | AD16: =IF(OR(P16="",V16<>"候補・時刻要確認"),"",ROUND((D16-集計!$C$5)*1440+P16*1440+IF(Q16="○",1440,0),0)) | AE16: =IF(AND(AC16<>"",AD16<>"",U16<>"○",AA16<>"通船・警戒船"),"○","") | AF16: =IF(C16<>"○","",IF(COUNTIFS($A$6:$A$505,A16,$AE$6:$AE$505,"○")=0,"",_xlfn.MINIFS($AC$6:$AC$505,$A$6:$A$505,A16,$AE$6:$AE$505,"○"))) | AG16: =IF(C16<>"○","",IF(COUNTIFS($A$6:$A$505,A16,$AE$6:$AE$505,"○")=0,"",_xlfn.MAXIFS($AD$6:$AD$505,$A$6:$A$505,A16,$AE$6:$AE$505,"○"))) | AH16: =IF(AE16<>"○","",IF(COUNTIFS($W$6:$W$505,W16,$AC$6:$AC$505,"<"&AD16,$AD$6:$AD$505,">"&AC16,$AE$6:$AE$505,"○")>1,"同じ船の時間が重なっています",""))
A17: 2025-12-06#07 | B17: 12/06 #07 13:00 入 LNG MARS（ZL） | D17: 45997 | E17: 2094 | G17: LNG MARS | H17: 136710 | I17: GS | J17: 入 | K17: 六 | L17: ZL | M17: LNG | N17: 0.54166667 | O17: 0.5 | P17: 0.6875 | R17: M | V17: 候補・時刻要確認 | W17: =IFERROR(INDEX(マスター!$J$6:$J$125,MATCH(R17,マスター!$M$6:$M$125,0)),R17) | X17: =IFERROR(IF(INDEX(マスター!$C$6:$C$125,MATCH(R17,マスター!$M$6:$M$125,0))="","未確認",INDEX(マスター!$C$6:$C$125,MATCH(R17,マスター!$M$6:$M$125,0))),"マスター未登録") | Y17: =IFERROR(INDEX(マスター!$K$6:$K$125,MATCH(R17,マスター!$M$6:$M$125,0)),"マスター未登録") | Z17: =IFERROR(IF(INDEX(マスター!$I$6:$I$125,MATCH(R17,マスター!$M$6:$M$125,0))="","未確認",INDEX(マスター!$I$6:$I$125,MATCH(R17,マスター!$M$6:$M$125,0))),"マスター未登録") | AA17: =IFERROR(IF(INDEX(マスター!$D$6:$D$125,MATCH(R17,マスター!$M$6:$M$125,0))="","未確認",INDEX(マスター!$D$6:$D$125,MATCH(R17,マスター!$M$6:$M$125,0))),"マスター未登録") | AB17: =IF(M17="支給炭","安瀬候補（要確認）","") | AC17: =IF(OR(O17="",V17<>"候補・時刻要確認"),"",ROUND((D17-集計!$C$5)*1440+O17*1440,0)) | AD17: =IF(OR(P17="",V17<>"候補・時刻要確認"),"",ROUND((D17-集計!$C$5)*1440+P17*1440+IF(Q17="○",1440,0),0)) | AE17: =IF(AND(AC17<>"",AD17<>"",U17<>"○",AA17<>"通船・警戒船"),"○","") | AF17: =IF(C17<>"○","",IF(COUNTIFS($A$6:$A$505,A17,$AE$6:$AE$505,"○")=0,"",_xlfn.MINIFS($AC$6:$AC$505,$A$6:$A$505,A17,$AE$6:$AE$505,"○"))) | AG17: =IF(C17<>"○","",IF(COUNTIFS($A$6:$A$505,A17,$AE$6:$AE$505,"○")=0,"",_xlfn.MAXIFS($AD$6:$AD$505,$A$6:$A$505,A17,$AE$6:$AE$505,"○"))) | AH17: =IF(AE17<>"○","",IF(COUNTIFS($W$6:$W$505,W17,$AC$6:$AC$505,"<"&AD17,$AD$6:$AD$505,">"&AC17,$AE$6:$AE$505,"○")>1,"同じ船の時間が重なっています",""))
A18: 2025-12-06#07 | B18: 12/06 #07 13:00 入 LNG MARS（ZL） | D18: 45997 | E18: 2095 | G18: LNG MARS | H18: 136710 | I18: GS | J18: 入 | K18: 六 | L18: ZL | M18: LNG | N18: 0.54166667 | O18: 0.5 | P18: 0.6875 | R18: P | V18: 候補・時刻要確認 | W18: =IFERROR(INDEX(マスター!$J$6:$J$125,MATCH(R18,マスター!$M$6:$M$125,0)),R18) | X18: =IFERROR(IF(INDEX(マスター!$C$6:$C$125,MATCH(R18,マスター!$M$6:$M$125,0))="","未確認",INDEX(マスター!$C$6:$C$125,MATCH(R18,マスター!$M$6:$M$125,0))),"マスター未登録") | Y18: =IFERROR(INDEX(マスター!$K$6:$K$125,MATCH(R18,マスター!$M$6:$M$125,0)),"マスター未登録") | Z18: =IFERROR(IF(INDEX(マスター!$I$6:$I$125,MATCH(R18,マスター!$M$6:$M$125,0))="","未確認",INDEX(マスター!$I$6:$I$125,MATCH(R18,マスター!$M$6:$M$125,0))),"マスター未登録") | AA18: =IFERROR(IF(INDEX(マスター!$D$6:$D$125,MATCH(R18,マスター!$M$6:$M$125,0))="","未確認",INDEX(マスター!$D$6:$D$125,MATCH(R18,マスター!$M$6:$M$125,0))),"マスター未登録") | AB18: =IF(M18="支給炭","安瀬候補（要確認）","") | AC18: =IF(OR(O18="",V18<>"候補・時刻要確認"),"",ROUND((D18-集計!$C$5)*1440+O18*1440,0)) | AD18: =IF(OR(P18="",V18<>"候補・時刻要確認"),"",ROUND((D18-集計!$C$5)*1440+P18*1440+IF(Q18="○",1440,0),0)) | AE18: =IF(AND(AC18<>"",AD18<>"",U18<>"○",AA18<>"通船・警戒船"),"○","") | AF18: =IF(C18<>"○","",IF(COUNTIFS($A$6:$A$505,A18,$AE$6:$AE$505,"○")=0,"",_xlfn.MINIFS($AC$6:$AC$505,$A$6:$A$505,A18,$AE$6:$AE$505,"○"))) | AG18: =IF(C18<>"○","",IF(COUNTIFS($A$6:$A$505,A18,$AE$6:$AE$505,"○")=0,"",_xlfn.MAXIFS($AD$6:$AD$505,$A$6:$A$505,A18,$AE$6:$AE$505,"○"))) | AH18: =IF(AE18<>"○","",IF(COUNTIFS($W$6:$W$505,W18,$AC$6:$AC$505,"<"&AD18,$AD$6:$AD$505,">"&AC18,$AE$6:$AE$505,"○")>1,"同じ船の時間が重なっています",""))
A19: 2025-12-06#07 | B19: 12/06 #07 13:00 入 LNG MARS（ZL） | D19: 45997 | E19: 2096 | G19: LNG MARS | H19: 136710 | I19: GS | J19: 入 | K19: 六 | L19: ZL | M19: LNG | N19: 0.54166667 | O19: 0.56944444 | P19: 0.6875 | R19: Y | V19: 候補・時刻要確認 | W19: =IFERROR(INDEX(マスター!$J$6:$J$125,MATCH(R19,マスター!$M$6:$M$125,0)),R19) | X19: =IFERROR(IF(INDEX(マスター!$C$6:$C$125,MATCH(R19,マスター!$M$6:$M$125,0))="","未確認",INDEX(マスター!$C$6:$C$125,MATCH(R19,マスター!$M$6:$M$125,0))),"マスター未登録") | Y19: =IFERROR(INDEX(マスター!$K$6:$K$125,MATCH(R19,マスター!$M$6:$M$125,0)),"マスター未登録") | Z19: =IFERROR(IF(INDEX(マスター!$I$6:$I$125,MATCH(R19,マスター!$M$6:$M$125,0))="","未確認",INDEX(マスター!$I$6:$I$125,MATCH(R19,マスター!$M$6:$M$125,0))),"マスター未登録") | AA19: =IFERROR(IF(INDEX(マスター!$D$6:$D$125,MATCH(R19,マスター!$M$6:$M$125,0))="","未確認",INDEX(マスター!$D$6:$D$125,MATCH(R19,マスター!$M$6:$M$125,0))),"マスター未登録") | AB19: =IF(M19="支給炭","安瀬候補（要確認）","") | AC19: =IF(OR(O19="",V19<>"候補・時刻要確認"),"",ROUND((D19-集計!$C$5)*1440+O19*1440,0)) | AD19: =IF(OR(P19="",V19<>"候補・時刻要確認"),"",ROUND((D19-集計!$C$5)*1440+P19*1440+IF(Q19="○",1440,0),0)) | AE19: =IF(AND(AC19<>"",AD19<>"",U19<>"○",AA19<>"通船・警戒船"),"○","") | AF19: =IF(C19<>"○","",IF(COUNTIFS($A$6:$A$505,A19,$AE$6:$AE$505,"○")=0,"",_xlfn.MINIFS($AC$6:$AC$505,$A$6:$A$505,A19,$AE$6:$AE$505,"○"))) | AG19: =IF(C19<>"○","",IF(COUNTIFS($A$6:$A$505,A19,$AE$6:$AE$505,"○")=0,"",_xlfn.MAXIFS($AD$6:$AD$505,$A$6:$A$505,A19,$AE$6:$AE$505,"○"))) | AH19: =IF(AE19<>"○","",IF(COUNTIFS($W$6:$W$505,W19,$AC$6:$AC$505,"<"&AD19,$AD$6:$AD$505,">"&AC19,$AE$6:$AE$505,"○")>1,"同じ船の時間が重なっています",""))
A20: 2025-12-06#08 | B20: 12/06 #08 18:30 出 FIRST AI（N5） | C20: ○ | D20: 45997 | E20: 2097 | F20: 27 | G20: FIRST AI | H20: 1501 | I20: 門港 | J20: 出 | L20: N5 | M20: 鋼材 | N20: 0.77083333 | O20: 0.72916667 | P20: 0.78125 | R20: P | V20: 候補・時刻要確認 | W20: =IFERROR(INDEX(マスター!$J$6:$J$125,MATCH(R20,マスター!$M$6:$M$125,0)),R20) | X20: =IFERROR(IF(INDEX(マスター!$C$6:$C$125,MATCH(R20,マスター!$M$6:$M$125,0))="","未確認",INDEX(マスター!$C$6:$C$125,MATCH(R20,マスター!$M$6:$M$125,0))),"マスター未登録") | Y20: =IFERROR(INDEX(マスター!$K$6:$K$125,MATCH(R20,マスター!$M$6:$M$125,0)),"マスター未登録") | Z20: =IFERROR(IF(INDEX(マスター!$I$6:$I$125,MATCH(R20,マスター!$M$6:$M$125,0))="","未確認",INDEX(マスター!$I$6:$I$125,MATCH(R20,マスター!$M$6:$M$125,0))),"マスター未登録") | AA20: =IFERROR(IF(INDEX(マスター!$D$6:$D$125,MATCH(R20,マスター!$M$6:$M$125,0))="","未確認",INDEX(マスター!$D$6:$D$125,MATCH(R20,マスター!$M$6:$M$125,0))),"マスター未登録") | AB20: =IF(M20="支給炭","安瀬候補（要確認）","") | AC20: =IF(OR(O20="",V20<>"候補・時刻要確認"),"",ROUND((D20-集計!$C$5)*1440+O20*1440,0)) | AD20: =IF(OR(P20="",V20<>"候補・時刻要確認"),"",ROUND((D20-集計!$C$5)*1440+P20*1440+IF(Q20="○",1440,0),0)) | AE20: =IF(AND(AC20<>"",AD20<>"",U20<>"○",AA20<>"通船・警戒船"),"○","") | AF20: =IF(C20<>"○","",IF(COUNTIFS($A$6:$A$505,A20,$AE$6:$AE$505,"○")=0,"",_xlfn.MINIFS($AC$6:$AC$505,$A$6:$A$505,A20,$AE$6:$AE$505,"○"))) | AG20: =IF(C20<>"○","",IF(COUNTIFS($A$6:$A$505,A20,$AE$6:$AE$505,"○")=0,"",_xlfn.MAXIFS($AD$6:$AD$505,$A$6:$A$505,A20,$AE$6:$AE$505,"○"))) | AH20: =IF(AE20<>"○","",IF(COUNTIFS($W$6:$W$505,W20,$AC$6:$AC$505,"<"&AD20,$AD$6:$AD$505,">"&AC20,$AE$6:$AE$505,"○")>1,"同じ船の時間が重なっています",""))
A21: 2025-12-06#09 | B21: 12/06 #09 19:30 入 ZENITH AURORA（N5） | C21: ○ | D21: 45997 | E21: 2098 | F21: 28 | G21: ZENITH AURORA | H21: 4477 | I21: コスモ | J21: 入 | K21: 六 | L21: N5 | M21: 鋼材 | N21: 0.8125 | O21: 0.79166667 | P21: 0.87152778 | R21: T | V21: 候補・時刻要確認 | W21: =IFERROR(INDEX(マスター!$J$6:$J$125,MATCH(R21,マスター!$M$6:$M$125,0)),R21) | X21: =IFERROR(IF(INDEX(マスター!$C$6:$C$125,MATCH(R21,マスター!$M$6:$M$125,0))="","未確認",INDEX(マスター!$C$6:$C$125,MATCH(R21,マスター!$M$6:$M$125,0))),"マスター未登録") | Y21: =IFERROR(INDEX(マスター!$K$6:$K$125,MATCH(R21,マスター!$M$6:$M$125,0)),"マスター未登録") | Z21: =IFERROR(IF(INDEX(マスター!$I$6:$I$125,MATCH(R21,マスター!$M$6:$M$125,0))="","未確認",INDEX(マスター!$I$6:$I$125,MATCH(R21,マスター!$M$6:$M$125,0))),"マスター未登録") | AA21: =IFERROR(IF(INDEX(マスター!$D$6:$D$125,MATCH(R21,マスター!$M$6:$M$125,0))="","未確認",INDEX(マスター!$D$6:$D$125,MATCH(R21,マスター!$M$6:$M$125,0))),"マスター未登録") | AB21: =IF(M21="支給炭","安瀬候補（要確認）","") | AC21: =IF(OR(O21="",V21<>"候補・時刻要確認"),"",ROUND((D21-集計!$C$5)*1440+O21*1440,0)) | AD21: =IF(OR(P21="",V21<>"候補・時刻要確認"),"",ROUND((D21-集計!$C$5)*1440+P21*1440+IF(Q21="○",1440,0),0)) | AE21: =IF(AND(AC21<>"",AD21<>"",U21<>"○",AA21<>"通船・警戒船"),"○","") | AF21: =IF(C21<>"○","",IF(COUNTIFS($A$6:$A$505,A21,$AE$6:$AE$505,"○")=0,"",_xlfn.MINIFS($AC$6:$AC$505,$A$6:$A$505,A21,$AE$6:$AE$505,"○"))) | AG21: =IF(C21<>"○","",IF(COUNTIFS($A$6:$A$505,A21,$AE$6:$AE$505,"○")=0,"",_xlfn.MAXIFS($AD$6:$AD$505,$A$6:$A$505,A21,$AE$6:$AE$505,"○"))) | AH21: =IF(AE21<>"○","",IF(COUNTIFS($W$6:$W$505,W21,$AC$6:$AC$505,"<"&AD21,$AD$6:$AD$505,">"&AC21,$AE$6:$AE$505,"○")>1,"同じ船の時間が重なっています",""))
A22: 2025-12-06#09 | B22: 12/06 #09 19:30 入 ZENITH AURORA（N5） | D22: 45997 | E22: 2099 | G22: ZENITH AURORA | H22: 4477 | I22: コスモ | J22: 入 | K22: 六 | L22: N5 | M22: 鋼材 | N22: 0.8125 | O22: 0.79166667 | P22: 0.87152778 | R22: P | V22: 候補・時刻要確認 | W22: =IFERROR(INDEX(マスター!$J$6:$J$125,MATCH(R22,マスター!$M$6:$M$125,0)),R22) | X22: =IFERROR(IF(INDEX(マスター!$C$6:$C$125,MATCH(R22,マスター!$M$6:$M$125,0))="","未確認",INDEX(マスター!$C$6:$C$125,MATCH(R22,マスター!$M$6:$M$125,0))),"マスター未登録") | Y22: =IFERROR(INDEX(マスター!$K$6:$K$125,MATCH(R22,マスター!$M$6:$M$125,0)),"マスター未登録") | Z22: =IFERROR(IF(INDEX(マスター!$I$6:$I$125,MATCH(R22,マスター!$M$6:$M$125,0))="","未確認",INDEX(マスター!$I$6:$I$125,MATCH(R22,マスター!$M$6:$M$125,0))),"マスター未登録") | AA22: =IFERROR(IF(INDEX(マスター!$D$6:$D$125,MATCH(R22,マスター!$M$6:$M$125,0))="","未確認",INDEX(マスター!$D$6:$D$125,MATCH(R22,マスター!$M$6:$M$125,0))),"マスター未登録") | AB22: =IF(M22="支給炭","安瀬候補（要確認）","") | AC22: =IF(OR(O22="",V22<>"候補・時刻要確認"),"",ROUND((D22-集計!$C$5)*1440+O22*1440,0)) | AD22: =IF(OR(P22="",V22<>"候補・時刻要確認"),"",ROUND((D22-集計!$C$5)*1440+P22*1440+IF(Q22="○",1440,0),0)) | AE22: =IF(AND(AC22<>"",AD22<>"",U22<>"○",AA22<>"通船・警戒船"),"○","") | AF22: =IF(C22<>"○","",IF(COUNTIFS($A$6:$A$505,A22,$AE$6:$AE$505,"○")=0,"",_xlfn.MINIFS($AC$6:$AC$505,$A$6:$A$505,A22,$AE$6:$AE$505,"○"))) | AG22: =IF(C22<>"○","",IF(COUNTIFS($A$6:$A$505,A22,$AE$6:$AE$505,"○")=0,"",_xlfn.MAXIFS($AD$6:$AD$505,$A$6:$A$505,A22,$AE$6:$AE$505,"○"))) | AH22: =IF(AE22<>"○","",IF(COUNTIFS($W$6:$W$505,W22,$AC$6:$AC$505,"<"&AD22,$AD$6:$AD$505,">"&AC22,$AE$6:$AE$505,"○")>1,"同じ船の時間が重なっています",""))

Sheet 前日確定
A1: 前日確定（対象日の前日最終の予定表と翌日の出勤手配）
A2: 誰が：上田 何を見て：対象日の前日に翌日の出勤を手配した最終の作業予定表 どこへ：①C7～C10 ②出勤手配（B14～） ③作業ごとの予定（J列～T列）。予定表にあって実績にない作業は36行目以降の空き行へ追加
A3: 集計先：「集計」の予定・出勤手配、「変更・キャンセル」の変更前の時刻・タグ。ここに入れた前日最終の値は変更があっても上書きしません。
A5: ■ 対象日の予定表
A6: 対象日【自動】 | C6: =集計!$C$5
A7: 根拠の予定表（ファイル名・版）【入力】 | F7: ◀ 最初の入力はここ（対象日の前日最終の予定表のファイル名・版。2025年度分は本一式に含まれていないため、上田さんの照合で入力）
A8: 予定表の確定時点（日時）【入力】
A9: 照合した人【入力】
A10: 照合の状況【入力・選択】 | C10: 未確認
A12: ■ 翌日の出勤手配（対象日の前日に手配した船）
A13: No | B13: 船名【入力・選択】 | C13: 会社【自動】 | D13: 手配した日時【入力】 | E13: 情報元【入力】
A14: 1 | C14: =IF(B14="","",IFERROR(INDEX(マスター!$C$6:$C$125,MATCH(B14,マスター!$M$6:$M$125,0))&"","マスター未登録"))
A15: 2 | C15: =IF(B15="","",IFERROR(INDEX(マスター!$C$6:$C$125,MATCH(B15,マスター!$M$6:$M$125,0))&"","マスター未登録"))
A16: 3 | C16: =IF(B16="","",IFERROR(INDEX(マスター!$C$6:$C$125,MATCH(B16,マスター!$M$6:$M$125,0))&"","マスター未登録"))
A17: 4 | C17: =IF(B17="","",IFERROR(INDEX(マスター!$C$6:$C$125,MATCH(B17,マスター!$M$6:$M$125,0))&"","マスター未登録"))
A18: 5 | C18: =IF(B18="","",IFERROR(INDEX(マスター!$C$6:$C$125,MATCH(B18,マスター!$M$6:$M$125,0))&"","マスター未登録"))
A19: 6 | C19: =IF(B19="","",IFERROR(INDEX(マスター!$C$6:$C$125,MATCH(B19,マスター!$M$6:$M$125,0))&"","マスター未登録"))
A20: 7 | C20: =IF(B20="","",IFERROR(INDEX(マスター!$C$6:$C$125,MATCH(B20,マスター!$M$6:$M$125,0))&"","マスター未登録"))
A21: 8 | C21: =IF(B21="","",IFERROR(INDEX(マスター!$C$6:$C$125,MATCH(B21,マスター!$M$6:$M$125,0))&"","マスター未登録"))
A22: 出勤手配隻数【自動】 | C22: =IF(COUNTA(B14:B21)=0,0,SUMPRODUCT((B14:B21<>"")/COUNTIF(B14:B21,B14:B21&"")))
A24: ■ 作業ごとの前日最終予定（実績の作業は自動表示。予定表にだけある作業は下の空き行へ追加）
A25: 区分【自動】 | B25: 作業の表示名【自動】 | C25: 作業キー【自動】 | D25: 本船名【自動／予定のみは入力】 | E25: 入出転【自動／予定のみは入力】 | F25: バース【自動／予定のみは入力】 | G25: 実績のタグ（元帳）【自動】 | H25: 実績タグ数【自動】 | I25: 元帳の予定時間（参考・前日確定とは限らない）【自動】 | J25: 前日最終の予定時刻【入力】 | K25: 予定タグ①【入力・選択】 | L25: 予定タグ②【入力・選択】 | M25: 予定タグ③【入力・選択】 | N25: 予定タグ④【入力・選択】 | O25: 予定タグ⑤【入力・選択】 | P25: 予定タグ⑥【入力・選択】 | Q25: 予定タグ数【自動】 | R25: 予定タグ（まとめ）【自動】 | S25: 照合の状況【入力・選択】 | T25: 備考【入力】 | U25: 変更回数【自動】 | V25: 変更後の最終時刻【自動】 | W25: 取消し【自動】
A26: 実績あり | B26: 12/06 #01 07:30 入 GRAND MUSE（OT） | C26: 2025-12-06#01 | D26: GRAND MUSE | E26: 入 | F26: OT | G26: P | H26: =IF(C26="","",COUNTIF(実績!$A$6:$A$505,C26)) | I26: 0.3125 | Q26: =IF(C26="","",COUNTA(K26:P26)) | R26: =_xlfn.TEXTJOIN("・",TRUE,K26:P26) | S26: 未確認 | U26: =IF(C26="","",COUNTIF('変更・キャンセル'!$B$26:$B$85,C26)) | V26: =IF(OR(C26="",U26=0),"",INDEX('変更・キャンセル'!$AA$26:$AA$85,MATCH(C26&"#"&U26,'変更・キャンセル'!$Z$26:$Z$85,0))) | W26: =IF(C26="","",IF(COUNTIFS('変更・キャンセル'!$B$26:$B$85,C26,'変更・キャンセル'!$R$26:$R$85,"○")>0,"○",""))
A27: 実績あり | B27: 12/06 #02 07:30 入 RICH SEA（OD2） | C27: 2025-12-06#02 | D27: RICH SEA | E27: 入 | F27: OD2 | G27: M | H27: =IF(C27="","",COUNTIF(実績!$A$6:$A$505,C27)) | I27: 0.3125 | Q27: =IF(C27="","",COUNTA(K27:P27)) | R27: =_xlfn.TEXTJOIN("・",TRUE,K27:P27) | S27: 未確認 | U27: =IF(C27="","",COUNTIF('変更・キャンセル'!$B$26:$B$85,C27)) | V27: =IF(OR(C27="",U27=0),"",INDEX('変更・キャンセル'!$AA$26:$AA$85,MATCH(C27&"#"&U27,'変更・キャンセル'!$Z$26:$Z$85,0))) | W27: =IF(C27="","",IF(COUNTIFS('変更・キャンセル'!$B$26:$B$85,C27,'変更・キャンセル'!$R$26:$R$85,"○")>0,"○",""))
A28: 実績あり | B28: 12/06 #03 08:00 転 KAIROS TRIUMPH（N5-Y15） | C28: 2025-12-06#03 | D28: KAIROS TRIUMPH | E28: 転 | F28: N5-Y15 | G28: T・Y | H28: =IF(C28="","",COUNTIF(実績!$A$6:$A$505,C28)) | I28: 0.33333333 | Q28: =IF(C28="","",COUNTA(K28:P28)) | R28: =_xlfn.TEXTJOIN("・",TRUE,K28:P28) | S28: 未確認 | U28: =IF(C28="","",COUNTIF('変更・キャンセル'!$B$26:$B$85,C28)) | V28: =IF(OR(C28="",U28=0),"",INDEX('変更・キャンセル'!$AA$26:$AA$85,MATCH(C28&"#"&U28,'変更・キャンセル'!$Z$26:$Z$85,0))) | W28: =IF(C28="","",IF(COUNTIFS('変更・キャンセル'!$B$26:$B$85,C28,'変更・キャンセル'!$R$26:$R$85,"○")>0,"○",""))
A29: 実績あり | B29: 12/06 #04 08:00 入 FIRST AI（N5） | C29: 2025-12-06#04 | D29: FIRST AI | E29: 入 | F29: N5 | G29: S | H29: =IF(C29="","",COUNTIF(実績!$A$6:$A$505,C29)) | I29: 0.33333333 | Q29: =IF(C29="","",COUNTA(K29:P29)) | R29: =_xlfn.TEXTJOIN("・",TRUE,K29:P29) | S29: 未確認 | U29: =IF(C29="","",COUNTIF('変更・キャンセル'!$B$26:$B$85,C29)) | V29: =IF(OR(C29="",U29=0),"",INDEX('変更・キャンセル'!$AA$26:$AA$85,MATCH(C29&"#"&U29,'変更・キャンセル'!$Z$26:$Z$85,0))) | W29: =IF(C29="","",IF(COUNTIFS('変更・キャンセル'!$B$26:$B$85,C29,'変更・キャンセル'!$R$26:$R$85,"○")>0,"○",""))
A30: 実績あり | B30: 12/06 #05 12:15 出 NEW NATION（N4） | C30: 2025-12-06#05 | D30: NEW NATION | E30: 出 | F30: N4 | G30: 関・長 | H30: =IF(C30="","",COUNTIF(実績!$A$6:$A$505,C30)) | I30: 0.51041667 | Q30: =IF(C30="","",COUNTA(K30:P30)) | R30: =_xlfn.TEXTJOIN("・",TRUE,K30:P30) | S30: 未確認 | U30: =IF(C30="","",COUNTIF('変更・キャンセル'!$B$26:$B$85,C30)) | V30: =IF(OR(C30="",U30=0),"",INDEX('変更・キャンセル'!$AA$26:$AA$85,MATCH(C30&"#"&U30,'変更・キャンセル'!$Z$26:$Z$85,0))) | W30: =IF(C30="","",IF(COUNTIFS('変更・キャンセル'!$B$26:$B$85,C30,'変更・キャンセル'!$R$26:$R$85,"○")>0,"○",""))
A31: 実績あり | B31: 12/06 #06 12:30 入 TEXAS HARMONY（N4） | C31: 2025-12-06#06 | D31: TEXAS HARMONY | E31: 入 | F31: N4 | G31: 竜山・さくら | H31: =IF(C31="","",COUNTIF(実績!$A$6:$A$505,C31)) | I31: 0.52083333 | Q31: =IF(C31="","",COUNTA(K31:P31)) | R31: =_xlfn.TEXTJOIN("・",TRUE,K31:P31) | S31: 未確認 | U31: =IF(C31="","",COUNTIF('変更・キャンセル'!$B$26:$B$85,C31)) | V31: =IF(OR(C31="",U31=0),"",INDEX('変更・キャンセル'!$AA$26:$AA$85,MATCH(C31&"#"&U31,'変更・キャンセル'!$Z$26:$Z$85,0))) | W31: =IF(C31="","",IF(COUNTIFS('変更・キャンセル'!$B$26:$B$85,C31,'変更・キャンセル'!$R$26:$R$85,"○")>0,"○",""))
A32: 実績あり | B32: 12/06 #07 13:00 入 LNG MARS（ZL） | C32: 2025-12-06#07 | D32: LNG MARS | E32: 入 | F32: ZL | G32: S・T・M・P・Y | H32: =IF(C32="","",COUNTIF(実績!$A$6:$A$505,C32)) | I32: 0.54166667 | Q32: =IF(C32="","",COUNTA(K32:P32)) | R32: =_xlfn.TEXTJOIN("・",TRUE,K32:P32) | S32: 未確認 | U32: =IF(C32="","",COUNTIF('変更・キャンセル'!$B$26:$B$85,C32)) | V32: =IF(OR(C32="",U32=0),"",INDEX('変更・キャンセル'!$AA$26:$AA$85,MATCH(C32&"#"&U32,'変更・キャンセル'!$Z$26:$Z$85,0))) | W32: =IF(C32="","",IF(COUNTIFS('変更・キャンセル'!$B$26:$B$85,C32,'変更・キャンセル'!$R$26:$R$85,"○")>0,"○",""))
A33: 実績あり | B33: 12/06 #08 18:30 出 FIRST AI（N5） | C33: 2025-12-06#08 | D33: FIRST AI | E33: 出 | F33: N5 | G33: P | H33: =IF(C33="","",COUNTIF(実績!$A$6:$A$505,C33)) | I33: 0.77083333 | Q33: =IF(C33="","",COUNTA(K33:P33)) | R33: =_xlfn.TEXTJOIN("・",TRUE,K33:P33) | S33: 未確認 | U33: =IF(C33="","",COUNTIF('変更・キャンセル'!$B$26:$B$85,C33)) | V33: =IF(OR(C33="",U33=0),"",INDEX('変更・キャンセル'!$AA$26:$AA$85,MATCH(C33&"#"&U33,'変更・キャンセル'!$Z$26:$Z$85,0))) | W33: =IF(C33="","",IF(COUNTIFS('変更・キャンセル'!$B$26:$B$85,C33,'変更・キャンセル'!$R$26:$R$85,"○")>0,"○",""))
A34: 実績あり | B34: 12/06 #09 19:30 入 ZENITH AURORA（N5） | C34: 2025-12-06#09 | D34: ZENITH AURORA | E34: 入 | F34: N5 | G34: T・P | H34: =IF(C34="","",COUNTIF(実績!$A$6:$A$505,C34)) | I34: 0.8125 | Q34: =IF(C34="","",COUNTA(K34:P34)) | R34: =_xlfn.TEXTJOIN("・",TRUE,K34:P34) | S34: 未確認 | U34: =IF(C34="","",COUNTIF('変更・キャンセル'!$B$26:$B$85,C34)) | V34: =IF(OR(C34="",U34=0),"",INDEX('変更・キャンセル'!$AA$26:$AA$85,MATCH(C34&"#"&U34,'変更・キャンセル'!$Z$26:$Z$85,0))) | W34: =IF(C34="","",IF(COUNTIFS('変更・キャンセル'!$B$26:$B$85,C34,'変更・キャンセル'!$R$26:$R$85,"○")>0,"○","")) | X34: ▼ ここから下は予定表にだけある作業（実績のない取消し等）を追加する行
A35: =IF(D35="","","予定のみ") | B35: =IF(D35="","","12/06 予定のみ#01 "&IF(J35="","--:--",TEXT(J35,"hh:mm"))&" "&E35&" "&D35) | C35: =IF(D35="","","2025-12-06予定のみ#01") | G35: =IF(D35="","","（実績なし）") | H35: =IF(C35="","",COUNTIF(実績!$A$6:$A$505,C35)) | Q35: =IF(C35="","",COUNTA(K35:P35)) | R35: =_xlfn.TEXTJOIN("・",TRUE,K35:P35) | U35: =IF(C35="","",COUNTIF('変更・キャンセル'!$B$26:$B$85,C35)) | V35: =IF(OR(C35="",U35=0),"",INDEX('変更・キャンセル'!$AA$26:$AA$85,MATCH(C35&"#"&U35,'変更・キャンセル'!$Z$26:$Z$85,0))) | W35: =IF(C35="","",IF(COUNTIFS('変更・キャンセル'!$B$26:$B$85,C35,'変更・キャンセル'!$R$26:$R$85,"○")>0,"○",""))
A36: =IF(D36="","","予定のみ") | B36: =IF(D36="","","12/06 予定のみ#02 "&IF(J36="","--:--",TEXT(J36,"hh:mm"))&" "&E36&" "&D36) | C36: =IF(D36="","","2025-12-06予定のみ#02") | G36: =IF(D36="","","（実績なし）") | H36: =IF(C36="","",COUNTIF(実績!$A$6:$A$505,C36)) | Q36: =IF(C36="","",COUNTA(K36:P36)) | R36: =_xlfn.TEXTJOIN("・",TRUE,K36:P36) | U36: =IF(C36="","",COUNTIF('変更・キャンセル'!$B$26:$B$85,C36)) | V36: =IF(OR(C36="",U36=0),"",INDEX('変更・キャンセル'!$AA$26:$AA$85,MATCH(C36&"#"&U36,'変更・キャンセル'!$Z$26:$Z$85,0))) | W36: =IF(C36="","",IF(COUNTIFS('変更・キャンセル'!$B$26:$B$85,C36,'変更・キャンセル'!$R$26:$R$85,"○")>0,"○",""))
A37: =IF(D37="","","予定のみ") | B37: =IF(D37="","","12/06 予定のみ#03 "&IF(J37="","--:--",TEXT(J37,"hh:mm"))&" "&E37&" "&D37) | C37: =IF(D37="","","2025-12-06予定のみ#03") | G37: =IF(D37="","","（実績なし）") | H37: =IF(C37="","",COUNTIF(実績!$A$6:$A$505,C37)) | Q37: =IF(C37="","",COUNTA(K37:P37)) | R37: =_xlfn.TEXTJOIN("・",TRUE,K37:P37) | U37: =IF(C37="","",COUNTIF('変更・キャンセル'!$B$26:$B$85,C37)) | V37: =IF(OR(C37="",U37=0),"",INDEX('変更・キャンセル'!$AA$26:$AA$85,MATCH(C37&"#"&U37,'変更・キャンセル'!$Z$26:$Z$85,0))) | W37: =IF(C37="","",IF(COUNTIFS('変更・キャンセル'!$B$26:$B$85,C37,'変更・キャンセル'!$R$26:$R$85,"○")>0,"○",""))
A38: =IF(D38="","","予定のみ") | B38: =IF(D38="","","12/06 予定のみ#04 "&IF(J38="","--:--",TEXT(J38,"hh:mm"))&" "&E38&" "&D38) | C38: =IF(D38="","","2025-12-06予定のみ#04") | G38: =IF(D38="","","（実績なし）") | H38: =IF(C38="","",COUNTIF(実績!$A$6:$A$505,C38)) | Q38: =IF(C38="","",COUNTA(K38:P38)) | R38: =_xlfn.TEXTJOIN("・",TRUE,K38:P38) | U38: =IF(C38="","",COUNTIF('変更・キャンセル'!$B$26:$B$85,C38)) | V38: =IF(OR(C38="",U38=0),"",INDEX('変更・キャンセル'!$AA$26:$AA$85,MATCH(C38&"#"&U38,'変更・キャンセル'!$Z$26:$Z$85,0))) | W38: =IF(C38="","",IF(COUNTIFS('変更・キャンセル'!$B$26:$B$85,C38,'変更・キャンセル'!$R$26:$R$85,"○")>0,"○",""))
A39: =IF(D39="","","予定のみ") | B39: =IF(D39="","","12/06 予定のみ#05 "&IF(J39="","--:--",TEXT(J39,"hh:mm"))&" "&E39&" "&D39) | C39: =IF(D39="","","2025-12-06予定のみ#05") | G39: =IF(D39="","","（実績なし）") | H39: =IF(C39="","",COUNTIF(実績!$A$6:$A$505,C39)) | Q39: =IF(C39="","",COUNTA(K39:P39)) | R39: =_xlfn.TEXTJOIN("・",TRUE,K39:P39) | U39: =IF(C39="","",COUNTIF('変更・キャンセル'!$B$26:$B$85,C39)) | V39: =IF(OR(C39="",U39=0),"",INDEX('変更・キャンセル'!$AA$26:$AA$85,MATCH(C39&"#"&U39,'変更・キャンセル'!$Z$26:$Z$85,0))) | W39: =IF(C39="","",IF(COUNTIFS('変更・キャンセル'!$B$26:$B$85,C39,'変更・キャンセル'!$R$26:$R$85,"○")>0,"○",""))
A40: =IF(D40="","","予定のみ") | B40: =IF(D40="","","12/06 予定のみ#06 "&IF(J40="","--:--",TEXT(J40,"hh:mm"))&" "&E40&" "&D40) | C40: =IF(D40="","","2025-12-06予定のみ#06") | G40: =IF(D40="","","（実績なし）") | H40: =IF(C40="","",COUNTIF(実績!$A$6:$A$505,C40)) | Q40: =IF(C40="","",COUNTA(K40:P40)) | R40: =_xlfn.TEXTJOIN("・",TRUE,K40:P40) | U40: =IF(C40="","",COUNTIF('変更・キャンセル'!$B$26:$B$85,C40)) | V40: =IF(OR(C40="",U40=0),"",INDEX('変更・キャンセル'!$AA$26:$AA$85,MATCH(C40&"#"&U40,'変更・キャンセル'!$Z$26:$Z$85,0))) | W40: =IF(C40="","",IF(COUNTIFS('変更・キャンセル'!$B$26:$B$85,C40,'変更・キャンセル'!$R$26:$R$85,"○")>0,"○",""))
A41: =IF(D41="","","予定のみ") | B41: =IF(D41="","","12/06 予定のみ#07 "&IF(J41="","--:--",TEXT(J41,"hh:mm"))&" "&E41&" "&D41) | C41: =IF(D41="","","2025-12-06予定のみ#07") | G41: =IF(D41="","","（実績なし）") | H41: =IF(C41="","",COUNTIF(実績!$A$6:$A$505,C41)) | Q41: =IF(C41="","",COUNTA(K41:P41)) | R41: =_xlfn.TEXTJOIN("・",TRUE,K41:P41) | U41: =IF(C41="","",COUNTIF('変更・キャンセル'!$B$26:$B$85,C41)) | V41: =IF(OR(C41="",U41=0),"",INDEX('変更・キャンセル'!$AA$26:$AA$85,MATCH(C41&"#"&U41,'変更・キャンセル'!$Z$26:$Z$85,0))) | W41: =IF(C41="","",IF(COUNTIFS('変更・キャンセル'!$B$26:$B$85,C41,'変更・キャンセル'!$R$26:$R$85,"○")>0,"○",""))
A42: =IF(D42="","","予定のみ") | B42: =IF(D42="","","12/06 予定のみ#08 "&IF(J42="","--:--",TEXT(J42,"hh:mm"))&" "&E42&" "&D42) | C42: =IF(D42="","","2025-12-06予定のみ#08") | G42: =IF(D42="","","（実績なし）") | H42: =IF(C42="","",COUNTIF(実績!$A$6:$A$505,C42)) | Q42: =IF(C42="","",COUNTA(K42:P42)) | R42: =_xlfn.TEXTJOIN("・",TRUE,K42:P42) | U42: =IF(C42="","",COUNTIF('変更・キャンセル'!$B$26:$B$85,C42)) | V42: =IF(OR(C42="",U42=0),"",INDEX('変更・キャンセル'!$AA$26:$AA$85,MATCH(C42&"#"&U42,'変更・キャンセル'!$Z$26:$Z$85,0))) | W42: =IF(C42="","",IF(COUNTIFS('変更・キャンセル'!$B$26:$B$85,C42,'変更・キャンセル'!$R$26:$R$85,"○")>0,"○",""))
A43: =IF(D43="","","予定のみ") | B43: =IF(D43="","","12/06 予定のみ#09 "&IF(J43="","--:--",TEXT(J43,"hh:mm"))&" "&E43&" "&D43) | C43: =IF(D43="","","2025-12-06予定のみ#09") | G43: =IF(D43="","","（実績なし）") | H43: =IF(C43="","",COUNTIF(実績!$A$6:$A$505,C43)) | Q43: =IF(C43="","",COUNTA(K43:P43)) | R43: =_xlfn.TEXTJOIN("・",TRUE,K43:P43) | U43: =IF(C43="","",COUNTIF('変更・キャンセル'!$B$26:$B$85,C43)) | V43: =IF(OR(C43="",U43=0),"",INDEX('変更・キャンセル'!$AA$26:$AA$85,MATCH(C43&"#"&U43,'変更・キャンセル'!$Z$26:$Z$85,0))) | W43: =IF(C43="","",IF(COUNTIFS('変更・キャンセル'!$B$26:$B$85,C43,'変更・キャンセル'!$R$26:$R$85,"○")>0,"○",""))
...

Sheet 変更・キャンセル
A1: 変更・キャンセル（全作業。1回の変更を1行。前日確定は上書きしない）
A2: 誰が：上田 何を見て：当日の変更連絡・変更分の予定表・配船記録 どこへ：①日ごとの確認（A7～）②休船からの呼出（A15～）③変更の記録（A26～で作業を選ぶ）。実績3隻未満の日・全船休航の日も①へ入力
A3: 集計先：「前日確定」の変更回数・最終時刻・取消し、「集計」の変更・取消し・呼出。実績のない取消しは「前日確定」の下の空き行へ作業を追加してから選びます。
A5: ■ 日ごとの変更確認（変更なしと確認できた日と未確認の日を区別）
A6: 日付【入力】 | B6: その日の変更確認【入力・選択】 | C6: 全船休航【入力・○】 | D6: 実績の最大同時稼働（候補）【自動】 | E6: 情報元【入力】 | F6: 確認者【入力】
A7: 45997 | B7: 未確認 | D7: =IF(A7="","",IF(A7=集計!$C$5,集計!$C$14,"この試作では対象日のみ計算"))
D8: =IF(A8="","",IF(A8=集計!$C$5,集計!$C$14,"この試作では対象日のみ計算"))
D9: =IF(A9="","",IF(A9=集計!$C$5,集計!$C$14,"この試作では対象日のみ計算"))
D10: =IF(A10="","",IF(A10=集計!$C$5,集計!$C$14,"この試作では対象日のみ計算"))
D11: =IF(A11="","",IF(A11=集計!$C$5,集計!$C$14,"この試作では対象日のみ計算"))
A13: ■ 休船からの呼出（製鉄曳船・西日本海運。1隻ごとに1行。同じ船の同じ呼出は1回と数える）
A14: 呼出した船【入力・選択】 | B14: 会社【自動】 | C14: 呼出日時【入力】 | D14: 最初に対応した作業【入力・選択】 | E14: 呼出の理由【入力・選択】 | F14: 情報元【入力】 | G14: 確認状況【入力・選択】 | H14: 同一呼出の判定【自動】 | I14: 対象会社の判定【自動】
B15: =IF(A15="","",IFERROR(INDEX(マスター!$C$6:$C$125,MATCH(A15,マスター!$M$6:$M$125,0))&"","マスター未登録")) | H15: =IF(A15="","",IF(COUNTIFS(A$15:A15,A15,C$15:C15,C15)>1,"同一呼出（1回と数える）","")) | I15: =IF(A15="","",IF(OR(B15="製鉄曳船",B15="西日本海運"),"","製鉄曳船・西日本海運以外の船です"))
B16: =IF(A16="","",IFERROR(INDEX(マスター!$C$6:$C$125,MATCH(A16,マスター!$M$6:$M$125,0))&"","マスター未登録")) | H16: =IF(A16="","",IF(COUNTIFS(A$15:A16,A16,C$15:C16,C16)>1,"同一呼出（1回と数える）","")) | I16: =IF(A16="","",IF(OR(B16="製鉄曳船",B16="西日本海運"),"","製鉄曳船・西日本海運以外の船です"))
B17: =IF(A17="","",IFERROR(INDEX(マスター!$C$6:$C$125,MATCH(A17,マスター!$M$6:$M$125,0))&"","マスター未登録")) | H17: =IF(A17="","",IF(COUNTIFS(A$15:A17,A17,C$15:C17,C17)>1,"同一呼出（1回と数える）","")) | I17: =IF(A17="","",IF(OR(B17="製鉄曳船",B17="西日本海運"),"","製鉄曳船・西日本海運以外の船です"))
B18: =IF(A18="","",IFERROR(INDEX(マスター!$C$6:$C$125,MATCH(A18,マスター!$M$6:$M$125,0))&"","マスター未登録")) | H18: =IF(A18="","",IF(COUNTIFS(A$15:A18,A18,C$15:C18,C18)>1,"同一呼出（1回と数える）","")) | I18: =IF(A18="","",IF(OR(B18="製鉄曳船",B18="西日本海運"),"","製鉄曳船・西日本海運以外の船です"))
B19: =IF(A19="","",IFERROR(INDEX(マスター!$C$6:$C$125,MATCH(A19,マスター!$M$6:$M$125,0))&"","マスター未登録")) | H19: =IF(A19="","",IF(COUNTIFS(A$15:A19,A19,C$15:C19,C19)>1,"同一呼出（1回と数える）","")) | I19: =IF(A19="","",IF(OR(B19="製鉄曳船",B19="西日本海運"),"","製鉄曳船・西日本海運以外の船です"))
B20: =IF(A20="","",IFERROR(INDEX(マスター!$C$6:$C$125,MATCH(A20,マスター!$M$6:$M$125,0))&"","マスター未登録")) | H20: =IF(A20="","",IF(COUNTIFS(A$15:A20,A20,C$15:C20,C20)>1,"同一呼出（1回と数える）","")) | I20: =IF(A20="","",IF(OR(B20="製鉄曳船",B20="西日本海運"),"","製鉄曳船・西日本海運以外の船です"))
B21: =IF(A21="","",IFERROR(INDEX(マスター!$C$6:$C$125,MATCH(A21,マスター!$M$6:$M$125,0))&"","マスター未登録")) | H21: =IF(A21="","",IF(COUNTIFS(A$15:A21,A21,C$15:C21,C21)>1,"同一呼出（1回と数える）","")) | I21: =IF(A21="","",IF(OR(B21="製鉄曳船",B21="西日本海運"),"","製鉄曳船・西日本海運以外の船です"))
B22: =IF(A22="","",IFERROR(INDEX(マスター!$C$6:$C$125,MATCH(A22,マスター!$M$6:$M$125,0))&"","マスター未登録")) | H22: =IF(A22="","",IF(COUNTIFS(A$15:A22,A22,C$15:C22,C22)>1,"同一呼出（1回と数える）","")) | I22: =IF(A22="","",IF(OR(B22="製鉄曳船",B22="西日本海運"),"","製鉄曳船・西日本海運以外の船です"))
A24: ■ 変更・キャンセルの記録（作業を選ぶと本船名・前日確定・変更前が自動表示。2回目以降の変更も同じ作業を選んで行を追加）
A25: 作業の選択【入力・選択】 | B25: 作業キー【自動】 | C25: 本船名【自動】 | D25: 何回目の変更【自動】 | E25: 前日確定の時刻【自動】 | F25: 前日確定のタグ【自動】 | G25: 連絡日時【入力】 | H25: 連絡元【入力】 | I25: 変更前の時刻【自動】 | J25: 変更後の時刻【入力】 | K25: 変更前のタグ【自動】 | L25: 変更後のタグ①【入力・選択】 | M25: 変更後のタグ②【入力・選択】 | N25: 変更後のタグ③【入力・選択】 | O25: 変更後のタグ④【入力・選択】 | P25: 変更後のタグ⑤【入力・選択】 | Q25: 変更後のタグ⑥【入力・選択】 | R25: 取消し【入力・○】 | S25: 取消しの時点【入力・選択】 | T25: 理由【入力・選択】 | U25: 理由の詳細【入力】 | V25: 時間調整【入力・選択】 | W25: 時間調整の内容【入力】 | X25: 情報元【入力】 | Y25: 確認者【入力】 | Z25: 照合キー【自動】 | AA25: 変更後の時刻（有効）【自動】 | AB25: 変更後のタグ（有効）【自動】 | AC25: 前回の照合キー【自動】
B26: =IF(A26="","",IFERROR(INDEX('前日確定'!$C$26:$C$45,MATCH(A26,'前日確定'!$B$26:$B$45,0)),"作業が見つかりません")) | C26: =IF(A26="","",IFERROR(INDEX('前日確定'!$D$26:$D$45,MATCH(A26,'前日確定'!$B$26:$B$45,0)),"")) | D26: =IF(B26="","",COUNTIF(B$26:B26,B26)) | E26: =IF(A26="","",IFERROR(IF(INDEX('前日確定'!$J$26:$J$45,MATCH(A26,'前日確定'!$B$26:$B$45,0))="","",INDEX('前日確定'!$J$26:$J$45,MATCH(A26,'前日確定'!$B$26:$B$45,0))),"")) | F26: =IF(A26="","",IFERROR(INDEX('前日確定'!$R$26:$R$45,MATCH(A26,'前日確定'!$B$26:$B$45,0)),"")) | I26: =IF(A26="","",E26) | K26: =IF(A26="","",F26) | Z26: =IF(B26="","",B26&"#"&D26) | AA26: =IF(A26="","",IF(J26="",I26,J26)) | AB26: =IF(A26="","",IF(COUNTA(L26:Q26)=0,K26,_xlfn.TEXTJOIN("・",TRUE,L26:Q26))) | AC26: =IF(B26="","",B26&"#"&(D26-1))
B27: =IF(A27="","",IFERROR(INDEX('前日確定'!$C$26:$C$45,MATCH(A27,'前日確定'!$B$26:$B$45,0)),"作業が見つかりません")) | C27: =IF(A27="","",IFERROR(INDEX('前日確定'!$D$26:$D$45,MATCH(A27,'前日確定'!$B$26:$B$45,0)),"")) | D27: =IF(B27="","",COUNTIF(B$26:B27,B27)) | E27: =IF(A27="","",IFERROR(IF(INDEX('前日確定'!$J$26:$J$45,MATCH(A27,'前日確定'!$B$26:$B$45,0))="","",INDEX('前日確定'!$J$26:$J$45,MATCH(A27,'前日確定'!$B$26:$B$45,0))),"")) | F27: =IF(A27="","",IFERROR(INDEX('前日確定'!$R$26:$R$45,MATCH(A27,'前日確定'!$B$26:$B$45,0)),"")) | I27: =IF(A27="","",IF(D27=1,E27,IFERROR(INDEX($AA$26:$AA$26,MATCH(AC27,$Z$26:$Z$26,0)),""))) | K27: =IF(A27="","",IF(D27=1,F27,IFERROR(INDEX($AB$26:$AB$26,MATCH(AC27,$Z$26:$Z$26,0)),""))) | Z27: =IF(B27="","",B27&"#"&D27) | AA27: =IF(A27="","",IF(J27="",I27,J27)) | AB27: =IF(A27="","",IF(COUNTA(L27:Q27)=0,K27,_xlfn.TEXTJOIN("・",TRUE,L27:Q27))) | AC27: =IF(B27="","",B27&"#"&(D27-1))
B28: =IF(A28="","",IFERROR(INDEX('前日確定'!$C$26:$C$45,MATCH(A28,'前日確定'!$B$26:$B$45,0)),"作業が見つかりません")) | C28: =IF(A28="","",IFERROR(INDEX('前日確定'!$D$26:$D$45,MATCH(A28,'前日確定'!$B$26:$B$45,0)),"")) | D28: =IF(B28="","",COUNTIF(B$26:B28,B28)) | E28: =IF(A28="","",IFERROR(IF(INDEX('前日確定'!$J$26:$J$45,MATCH(A28,'前日確定'!$B$26:$B$45,0))="","",INDEX('前日確定'!$J$26:$J$45,MATCH(A28,'前日確定'!$B$26:$B$45,0))),"")) | F28: =IF(A28="","",IFERROR(INDEX('前日確定'!$R$26:$R$45,MATCH(A28,'前日確定'!$B$26:$B$45,0)),"")) | I28: =IF(A28="","",IF(D28=1,E28,IFERROR(INDEX($AA$26:$AA$27,MATCH(AC28,$Z$26:$Z$27,0)),""))) | K28: =IF(A28="","",IF(D28=1,F28,IFERROR(INDEX($AB$26:$AB$27,MATCH(AC28,$Z$26:$Z$27,0)),""))) | Z28: =IF(B28="","",B28&"#"&D28) | AA28: =IF(A28="","",IF(J28="",I28,J28)) | AB28: =IF(A28="","",IF(COUNTA(L28:Q28)=0,K28,_xlfn.TEXTJOIN("・",TRUE,L28:Q28))) | AC28: =IF(B28="","",B28&"#"&(D28-1))
B29: =IF(A29="","",IFERROR(INDEX('前日確定'!$C$26:$C$45,MATCH(A29,'前日確定'!$B$26:$B$45,0)),"作業が見つかりません")) | C29: =IF(A29="","",IFERROR(INDEX('前日確定'!$D$26:$D$45,MATCH(A29,'前日確定'!$B$26:$B$45,0)),"")) | D29: =IF(B29="","",COUNTIF(B$26:B29,B29)) | E29: =IF(A29="","",IFERROR(IF(INDEX('前日確定'!$J$26:$J$45,MATCH(A29,'前日確定'!$B$26:$B$45,0))="","",INDEX('前日確定'!$J$26:$J$45,MATCH(A29,'前日確定'!$B$26:$B$45,0))),"")) | F29: =IF(A29="","",IFERROR(INDEX('前日確定'!$R$26:$R$45,MATCH(A29,'前日確定'!$B$26:$B$45,0)),"")) | I29: =IF(A29="","",IF(D29=1,E29,IFERROR(INDEX($AA$26:$AA$28,MATCH(AC29,$Z$26:$Z$28,0)),""))) | K29: =IF(A29="","",IF(D29=1,F29,IFERROR(INDEX($AB$26:$AB$28,MATCH(AC29,$Z$26:$Z$28,0)),""))) | Z29: =IF(B29="","",B29&"#"&D29) | AA29: =IF(A29="","",IF(J29="",I29,J29)) | AB29: =IF(A29="","",IF(COUNTA(L29:Q29)=0,K29,_xlfn.TEXTJOIN("・",TRUE,L29:Q29))) | AC29: =IF(B29="","",B29&"#"&(D29-1))
B30: =IF(A30="","",IFERROR(INDEX('前日確定'!$C$26:$C$45,MATCH(A30,'前日確定'!$B$26:$B$45,0)),"作業が見つかりません")) | C30: =IF(A30="","",IFERROR(INDEX('前日確定'!$D$26:$D$45,MATCH(A30,'前日確定'!$B$26:$B$45,0)),"")) | D30: =IF(B30="","",COUNTIF(B$26:B30,B30)) | E30: =IF(A30="","",IFERROR(IF(INDEX('前日確定'!$J$26:$J$45,MATCH(A30,'前日確定'!$B$26:$B$45,0))="","",INDEX('前日確定'!$J$26:$J$45,MATCH(A30,'前日確定'!$B$26:$B$45,0))),"")) | F30: =IF(A30="","",IFERROR(INDEX('前日確定'!$R$26:$R$45,MATCH(A30,'前日確定'!$B$26:$B$45,0)),"")) | I30: =IF(A30="","",IF(D30=1,E30,IFERROR(INDEX($AA$26:$AA$29,MATCH(AC30,$Z$26:$Z$29,0)),""))) | K30: =IF(A30="","",IF(D30=1,F30,IFERROR(INDEX($AB$26:$AB$29,MATCH(AC30,$Z$26:$Z$29,0)),""))) | Z30: =IF(B30="","",B30&"#"&D30) | AA30: =IF(A30="","",IF(J30="",I30,J30)) | AB30: =IF(A30="","",IF(COUNTA(L30:Q30)=0,K30,_xlfn.TEXTJOIN("・",TRUE,L30:Q30))) | AC30: =IF(B30="","",B30&"#"&(D30-1))
B31: =IF(A31="","",IFERROR(INDEX('前日確定'!$C$26:$C$45,MATCH(A31,'前日確定'!$B$26:$B$45,0)),"作業が見つかりません")) | C31: =IF(A31="","",IFERROR(INDEX('前日確定'!$D$26:$D$45,MATCH(A31,'前日確定'!$B$26:$B$45,0)),"")) | D31: =IF(B31="","",COUNTIF(B$26:B31,B31)) | E31: =IF(A31="","",IFERROR(IF(INDEX('前日確定'!$J$26:$J$45,MATCH(A31,'前日確定'!$B$26:$B$45,0))="","",INDEX('前日確定'!$J$26:$J$45,MATCH(A31,'前日確定'!$B$26:$B$45,0))),"")) | F31: =IF(A31="","",IFERROR(INDEX('前日確定'!$R$26:$R$45,MATCH(A31,'前日確定'!$B$26:$B$45,0)),"")) | I31: =IF(A31="","",IF(D31=1,E31,IFERROR(INDEX($AA$26:$AA$30,MATCH(AC31,$Z$26:$Z$30,0)),""))) | K31: =IF(A31="","",IF(D31=1,F31,IFERROR(INDEX($AB$26:$AB$30,MATCH(AC31,$Z$26:$Z$30,0)),""))) | Z31: =IF(B31="","",B31&"#"&D31) | AA31: =IF(A31="","",IF(J31="",I31,J31)) | AB31: =IF(A31="","",IF(COUNTA(L31:Q31)=0,K31,_xlfn.TEXTJOIN("・",TRUE,L31:Q31))) | AC31: =IF(B31="","",B31&"#"&(D31-1))
B32: =IF(A32="","",IFERROR(INDEX('前日確定'!$C$26:$C$45,MATCH(A32,'前日確定'!$B$26:$B$45,0)),"作業が見つかりません")) | C32: =IF(A32="","",IFERROR(INDEX('前日確定'!$D$26:$D$45,MATCH(A32,'前日確定'!$B$26:$B$45,0)),"")) | D32: =IF(B32="","",COUNTIF(B$26:B32,B32)) | E32: =IF(A32="","",IFERROR(IF(INDEX('前日確定'!$J$26:$J$45,MATCH(A32,'前日確定'!$B$26:$B$45,0))="","",INDEX('前日確定'!$J$26:$J$45,MATCH(A32,'前日確定'!$B$26:$B$45,0))),"")) | F32: =IF(A32="","",IFERROR(INDEX('前日確定'!$R$26:$R$45,MATCH(A32,'前日確定'!$B$26:$B$45,0)),"")) | I32: =IF(A32="","",IF(D32=1,E32,IFERROR(INDEX($AA$26:$AA$31,MATCH(AC32,$Z$26:$Z$31,0)),""))) | K32: =IF(A32="","",IF(D32=1,F32,IFERROR(INDEX($AB$26:$AB$31,MATCH(AC32,$Z$26:$Z$31,0)),""))) | Z32: =IF(B32="","",B32&"#"&D32) | AA32: =IF(A32="","",IF(J32="",I32,J32)) | AB32: =IF(A32="","",IF(COUNTA(L32:Q32)=0,K32,_xlfn.TEXTJOIN("・",TRUE,L32:Q32))) | AC32: =IF(B32="","",B32&"#"&(D32-1))
B33: =IF(A33="","",IFERROR(INDEX('前日確定'!$C$26:$C$45,MATCH(A33,'前日確定'!$B$26:$B$45,0)),"作業が見つかりません")) | C33: =IF(A33="","",IFERROR(INDEX('前日確定'!$D$26:$D$45,MATCH(A33,'前日確定'!$B$26:$B$45,0)),"")) | D33: =IF(B33="","",COUNTIF(B$26:B33,B33)) | E33: =IF(A33="","",IFERROR(IF(INDEX('前日確定'!$J$26:$J$45,MATCH(A33,'前日確定'!$B$26:$B$45,0))="","",INDEX('前日確定'!$J$26:$J$45,MATCH(A33,'前日確定'!$B$26:$B$45,0))),"")) | F33: =IF(A33="","",IFERROR(INDEX('前日確定'!$R$26:$R$45,MATCH(A33,'前日確定'!$B$26:$B$45,0)),"")) | I33: =IF(A33="","",IF(D33=1,E33,IFERROR(INDEX($AA$26:$AA$32,MATCH(AC33,$Z$26:$Z$32,0)),""))) | K33: =IF(A33="","",IF(D33=1,F33,IFERROR(INDEX($AB$26:$AB$32,MATCH(AC33,$Z$26:$Z$32,0)),""))) | Z33: =IF(B33="","",B33&"#"&D33) | AA33: =IF(A33="","",IF(J33="",I33,J33)) | AB33: =IF(A33="","",IF(COUNTA(L33:Q33)=0,K33,_xlfn.TEXTJOIN("・",TRUE,L33:Q33))) | AC33: =IF(B33="","",B33&"#"&(D33-1))
B34: =IF(A34="","",IFERROR(INDEX('前日確定'!$C$26:$C$45,MATCH(A34,'前日確定'!$B$26:$B$45,0)),"作業が見つかりません")) | C34: =IF(A34="","",IFERROR(INDEX('前日確定'!$D$26:$D$45,MATCH(A34,'前日確定'!$B$26:$B$45,0)),"")) | D34: =IF(B34="","",COUNTIF(B$26:B34,B34)) | E34: =IF(A34="","",IFERROR(IF(INDEX('前日確定'!$J$26:$J$45,MATCH(A34,'前日確定'!$B$26:$B$45,0))="","",INDEX('前日確定'!$J$26:$J$45,MATCH(A34,'前日確定'!$B$26:$B$45,0))),"")) | F34: =IF(A34="","",IFERROR(INDEX('前日確定'!$R$26:$R$45,MATCH(A34,'前日確定'!$B$26:$B$45,0)),"")) | I34: =IF(A34="","",IF(D34=1,E34,IFERROR(INDEX($AA$26:$AA$33,MATCH(AC34,$Z$26:$Z$33,0)),""))) | K34: =IF(A34="","",IF(D34=1,F34,IFERROR(INDEX($AB$26:$AB$33,MATCH(AC34,$Z$26:$Z$33,0)),""))) | Z34: =IF(B34="","",B34&"#"&D34) | AA34: =IF(A34="","",IF(J34="",I34,J34)) | AB34: =IF(A34="","",IF(COUNTA(L34:Q34)=0,K34,_xlfn.TEXTJOIN("・",TRUE,L34:Q34))) | AC34: =IF(B34="","",B34&"#"&(D34-1))
B35: =IF(A35="","",IFERROR(INDEX('前日確定'!$C$26:$C$45,MATCH(A35,'前日確定'!$B$26:$B$45,0)),"作業が見つかりません")) | C35: =IF(A35="","",IFERROR(INDEX('前日確定'!$D$26:$D$45,MATCH(A35,'前日確定'!$B$26:$B$45,0)),"")) | D35: =IF(B35="","",COUNTIF(B$26:B35,B35)) | E35: =IF(A35="","",IFERROR(IF(INDEX('前日確定'!$J$26:$J$45,MATCH(A35,'前日確定'!$B$26:$B$45,0))="","",INDEX('前日確定'!$J$26:$J$45,MATCH(A35,'前日確定'!$B$26:$B$45,0))),"")) | F35: =IF(A35="","",IFERROR(INDEX('前日確定'!$R$26:$R$45,MATCH(A35,'前日確定'!$B$26:$B$45,0)),"")) | I35: =IF(A35="","",IF(D35=1,E35,IFERROR(INDEX($AA$26:$AA$34,MATCH(AC35,$Z$26:$Z$34,0)),""))) | K35: =IF(A35="","",IF(D35=1,F35,IFERROR(INDEX($AB$26:$AB$34,MATCH(AC35,$Z$26:$Z$34,0)),""))) | Z35: =IF(B35="","",B35&"#"&D35) | AA35: =IF(A35="","",IF(J35="",I35,J35)) | AB35: =IF(A35="","",IF(COUNTA(L35:Q35)=0,K35,_xlfn.TEXTJOIN("・",TRUE,L35:Q35))) | AC35: =IF(B35="","",B35&"#"&(D35-1))
B36: =IF(A36="","",IFERROR(INDEX('前日確定'!$C$26:$C$45,MATCH(A36,'前日確定'!$B$26:$B$45,0)),"作業が見つかりません")) | C36: =IF(A36="","",IFERROR(INDEX('前日確定'!$D$26:$D$45,MATCH(A36,'前日確定'!$B$26:$B$45,0)),"")) | D36: =IF(B36="","",COUNTIF(B$26:B36,B36)) | E36: =IF(A36="","",IFERROR(IF(INDEX('前日確定'!$J$26:$J$45,MATCH(A36,'前日確定'!$B$26:$B$45,0))="","",INDEX('前日確定'!$J$26:$J$45,MATCH(A36,'前日確定'!$B$26:$B$45,0))),"")) | F36: =IF(A36="","",IFERROR(INDEX('前日確定'!$R$26:$R$45,MATCH(A36,'前日確定'!$B$26:$B$45,0)),"")) | I36: =IF(A36="","",IF(D36=1,E36,IFERROR(INDEX($AA$26:$AA$35,MATCH(AC36,$Z$26:$Z$35,0)),""))) | K36: =IF(A36="","",IF(D36=1,F36,IFERROR(INDEX($AB$26:$AB$35,MATCH(AC36,$Z$26:$Z$35,0)),""))) | Z36: =IF(B36="","",B36&"#"&D36) | AA36: =IF(A36="","",IF(J36="",I36,J36)) | AB36: =IF(A36="","",IF(COUNTA(L36:Q36)=0,K36,_xlfn.TEXTJOIN("・",TRUE,L36:Q36))) | AC36: =IF(B36="","",B36&"#"&(D36-1))
B37: =IF(A37="","",IFERROR(INDEX('前日確定'!$C$26:$C$45,MATCH(A37,'前日確定'!$B$26:$B$45,0)),"作業が見つかりません")) | C37: =IF(A37="","",IFERROR(INDEX('前日確定'!$D$26:$D$45,MATCH(A37,'前日確定'!$B$26:$B$45,0)),"")) | D37: =IF(B37="","",COUNTIF(B$26:B37,B37)) | E37: =IF(A37="","",IFERROR(IF(INDEX('前日確定'!$J$26:$J$45,MATCH(A37,'前日確定'!$B$26:$B$45,0))="","",INDEX('前日確定'!$J$26:$J$45,MATCH(A37,'前日確定'!$B$26:$B$45,0))),"")) | F37: =IF(A37="","",IFERROR(INDEX('前日確定'!$R$26:$R$45,MATCH(A37,'前日確定'!$B$26:$B$45,0)),"")) | I37: =IF(A37="","",IF(D37=1,E37,IFERROR(INDEX($AA$26:$AA$36,MATCH(AC37,$Z$26:$Z$36,0)),""))) | K37: =IF(A37="","",IF(D37=1,F37,IFERROR(INDEX($AB$26:$AB$36,MATCH(AC37,$Z$26:$Z$36,0)),""))) | Z37: =IF(B37="","",B37&"#"&D37) | AA37: =IF(A37="","",IF(J37="",I37,J37)) | AB37: =IF(A37="","",IF(COUNTA(L37:Q37)=0,K37,_xlfn.TEXTJOIN("・",TRUE,L37:Q37))) | AC37: =IF(B37="","",B37&"#"&(D37-1))
B38: =IF(A38="","",IFERROR(INDEX('前日確定'!$C$26:$C$45,MATCH(A38,'前日確定'!$B$26:$B$45,0)),"作業が見つかりません")) | C38: =IF(A38="","",IFERROR(INDEX('前日確定'!$D$26:$D$45,MATCH(A38,'前日確定'!$B$26:$B$45,0)),"")) | D38: =IF(B38="","",COUNTIF(B$26:B38,B38)) | E38: =IF(A38="","",IFERROR(IF(INDEX('前日確定'!$J$26:$J$45,MATCH(A38,'前日確定'!$B$26:$B$45,0))="","",INDEX('前日確定'!$J$26:$J$45,MATCH(A38,'前日確定'!$B$26:$B$45,0))),"")) | F38: =IF(A38="","",IFERROR(INDEX('前日確定'!$R$26:$R$45,MATCH(A38,'前日確定'!$B$26:$B$45,0)),"")) | I38: =IF(A38="","",IF(D38=1,E38,IFERROR(INDEX($AA$26:$AA$37,MATCH(AC38,$Z$26:$Z$37,0)),""))) | K38: =IF(A38="","",IF(D38=1,F38,IFERROR(INDEX($AB$26:$AB$37,MATCH(AC38,$Z$26:$Z$37,0)),""))) | Z38: =IF(B38="","",B38&"#"&D38) | AA38: =IF(A38="","",IF(J38="",I38,J38)) | AB38: =IF(A38="","",IF(COUNTA(L38:Q38)=0,K38,_xlfn.TEXTJOIN("・",TRUE,L38:Q38))) | AC38: =IF(B38="","",B38&"#"&(D38-1))
B39: =IF(A39="","",IFERROR(INDEX('前日確定'!$C$26:$C$45,MATCH(A39,'前日確定'!$B$26:$B$45,0)),"作業が見つかりません")) | C39: =IF(A39="","",IFERROR(INDEX('前日確定'!$D$26:$D$45,MATCH(A39,'前日確定'!$B$26:$B$45,0)),"")) | D39: =IF(B39="","",COUNTIF(B$26:B39,B39)) | E39: =IF(A39="","",IFERROR(IF(INDEX('前日確定'!$J$26:$J$45,MATCH(A39,'前日確定'!$B$26:$B$45,0))="","",INDEX('前日確定'!$J$26:$J$45,MATCH(A39,'前日確定'!$B$26:$B$45,0))),"")) | F39: =IF(A39="","",IFERROR(INDEX('前日確定'!$R$26:$R$45,MATCH(A39,'前日確定'!$B$26:$B$45,0)),"")) | I39: =IF(A39="","",IF(D39=1,E39,IFERROR(INDEX($AA$26:$AA$38,MATCH(AC39,$Z$26:$Z$38,0)),""))) | K39: =IF(A39="","",IF(D39=1,F39,IFERROR(INDEX($AB$26:$AB$38,MATCH(AC39,$Z$26:$Z$38,0)),""))) | Z39: =IF(B39="","",B39&"#"&D39) | AA39: =IF(A39="","",IF(J39="",I39,J39)) | AB39: =IF(A39="","",IF(COUNTA(L39:Q39)=0,K39,_xlfn.TEXTJOIN("・",TRUE,L39:Q39))) | AC39: =IF(B39="","",B39&"#"&(D39-1))
B40: =IF(A40="","",IFERROR(INDEX('前日確定'!$C$26:$C$45,MATCH(A40,'前日確定'!$B$26:$B$45,0)),"作業が見つかりません")) | C40: =IF(A40="","",IFERROR(INDEX('前日確定'!$D$26:$D$45,MATCH(A40,'前日確定'!$B$26:$B$45,0)),"")) | D40: =IF(B40="","",COUNTIF(B$26:B40,B40)) | E40: =IF(A40="","",IFERROR(IF(INDEX('前日確定'!$J$26:$J$45,MATCH(A40,'前日確定'!$B$26:$B$45,0))="","",INDEX('前日確定'!$J$26:$J$45,MATCH(A40,'前日確定'!$B$26:$B$45,0))),"")) | F40: =IF(A40="","",IFERROR(INDEX('前日確定'!$R$26:$R$45,MATCH(A40,'前日確定'!$B$26:$B$45,0)),"")) | I40: =IF(A40="","",IF(D40=1,E40,IFERROR(INDEX($AA$26:$AA$39,MATCH(AC40,$Z$26:$Z$39,0)),""))) | K40: =IF(A40="","",IF(D40=1,F40,IFERROR(INDEX($AB$26:$AB$39,MATCH(AC40,$Z$26:$Z$39,0)),""))) | Z40: =IF(B40="","",B40&"#"&D40) | AA40: =IF(A40="","",IF(J40="",I40,J40)) | AB40: =IF(A40="","",IF(COUNTA(L40:Q40)=0,K40,_xlfn.TEXTJOIN("・",TRUE,L40:Q40))) | AC40: =IF(B40="","",B40&"#"&(D40-1))
B41: =IF(A41="","",IFERROR(INDEX('前日確定'!$C$26:$C$45,MATCH(A41,'前日確定'!$B$26:$B$45,0)),"作業が見つかりません")) | C41: =IF(A41="","",IFERROR(INDEX('前日確定'!$D$26:$D$45,MATCH(A41,'前日確定'!$B$26:$B$45,0)),"")) | D41: =IF(B41="","",COUNTIF(B$26:B41,B41)) | E41: =IF(A41="","",IFERROR(IF(INDEX('前日確定'!$J$26:$J$45,MATCH(A41,'前日確定'!$B$26:$B$45,0))="","",INDEX('前日確定'!$J$26:$J$45,MATCH(A41,'前日確定'!$B$26:$B$45,0))),"")) | F41: =IF(A41="","",IFERROR(INDEX('前日確定'!$R$26:$R$45,MATCH(A41,'前日確定'!$B$26:$B$45,0)),"")) | I41: =IF(A41="","",IF(D41=1,E41,IFERROR(INDEX($AA$26:$AA$40,MATCH(AC41,$Z$26:$Z$40,0)),""))) | K41: =IF(A41="","",IF(D41=1,F41,IFERROR(INDEX($AB$26:$AB$40,MATCH(AC41,$Z$26:$Z$40,0)),""))) | Z41: =IF(B41="","",B41&"#"&D41) | AA41: =IF(A41="","",IF(J41="",I41,J41)) | AB41: =IF(A41="","",IF(COUNTA(L41:Q41)=0,K41,_xlfn.TEXTJOIN("・",TRUE,L41:Q41))) | AC41: =IF(B41="","",B41&"#"&(D41-1))
B42: =IF(A42="","",IFERROR(INDEX('前日確定'!$C$26:$C$45,MATCH(A42,'前日確定'!$B$26:$B$45,0)),"作業が見つかりません")) | C42: =IF(A42="","",IFERROR(INDEX('前日確定'!$D$26:$D$45,MATCH(A42,'前日確定'!$B$26:$B$45,0)),"")) | D42: =IF(B42="","",COUNTIF(B$26:B42,B42)) | E42: =IF(A42="","",IFERROR(IF(INDEX('前日確定'!$J$26:$J$45,MATCH(A42,'前日確定'!$B$26:$B$45,0))="","",INDEX('前日確定'!$J$26:$J$45,MATCH(A42,'前日確定'!$B$26:$B$45,0))),"")) | F42: =IF(A42="","",IFERROR(INDEX('前日確定'!$R$26:$R$45,MATCH(A42,'前日確定'!$B$26:$B$45,0)),"")) | I42: =IF(A42="","",IF(D42=1,E42,IFERROR(INDEX($AA$26:$AA$41,MATCH(AC42,$Z$26:$Z$41,0)),""))) | K42: =IF(A42="","",IF(D42=1,F42,IFERROR(INDEX($AB$26:$AB$41,MATCH(AC42,$Z$26:$Z$41,0)),""))) | Z42: =IF(B42="","",B42&"#"&D42) | AA42: =IF(A42="","",IF(J42="",I42,J42)) | AB42: =IF(A42="","",IF(COUNTA(L42:Q42)=0,K42,_xlfn.TEXTJOIN("・",TRUE,L42:Q42))) | AC42: =IF(B42="","",B42&"#"&(D42-1))
