Workbook

Sheet はじめに
B1: 八幡地区 常駐体制検証 入力試作 v01
B3: 目的 | C3: 製鉄曳船の3隻と4隻で対応の差を説明するための基礎データを集めます。この試作は、入力と集計のつながりを試すためのものです。4隻の必要性を証明するものではありません。
B4: 対象 | C4: 元帳R7年度のうち、同時3隻以上の候補日 2025年11月01日 の1日分（実績4行・3作業）。元帳の時刻は「候補・時刻要確認」です。
B5: 最初の操作 | C5: 下の青い文字を押すと、最初の入力欄（前日確定シートC7：根拠の予定表）へ移動します。
B6: 入力の順番 | C6: ①前日確定 → ②変更・キャンセル → ③入渠・他港作業・他社配置 → ④標準時間。船名や会社が選択肢にないときは、先にマスターへ追加します。
B7: 担当者 | C7: 前日確定・変更・キャンセル・製鉄曳船の入渠・八幡タグの標準時間：上田さん／西日本海運の他港作業・入渠・標準時間：西日本海運担当者／他社配置：分かる範囲で上田さん
B8: 色の意味 | C8: 薄い黄色＝入力する欄（見出しに【入力】）／薄い灰色＝自動表示（見出しに【自動】）。灰色の欄は入力しません。
B9: 選び方 | C9: 船名・会社・理由などはセルを選ぶと出る▼の一覧から選びます。○の欄は▼から○を選びます。ボタンやマクロは使っていません。
B10: 未確認の意味 | C10: 資料で確かめられていないことです。推測で埋めず「未確認」のまま残します。確認できたら「確認済み」に変えます。他社の対応可否が空欄の船も未確認です。
B11: 再入力しない | C11: 本船名・タグ名・実績時刻は元帳から自動表示します。作業番号の入力は不要で、作業は▼の一覧から選びます。
B12: 前日確定と変更 | C12: 前日最終の予定は「前日確定」に入れ、変更があっても上書きしません。変更は「変更・キャンセル」に1回ごとに1行追加します。翌日にかかる時刻は日付も入れます（例：2025/12/7 0:30）。
B13: 実績のない取消し | C13: 予定表にあって元帳にない作業は、「前日確定」の下の空き行に本船名などを入れて追加し、「変更・キャンセル」で選んで取消しを入力します。全作業が取り消された日も、前日の手配と実際の出勤を残せます。
B14: 安瀬・高炉原料 | C14: 安瀬は若松との按分配船で、応援とは別に数えます。高炉原料を除いた集計は、全作業の集計とは別に表示します（品名の区分はマスターで設定。初期値は要確認）。
... B19: 色見本 | C19: 入力する欄【入力】
C20: 自動表示の欄【自動】
B22: シートの役割
B23: 実績 | C23: 元帳の取り込み（見るだけ）
B24: 前日確定 | C24: 前日最終の予定・予定タグ・翌日の出勤手配と実際の出勤
B25: 変更・キャンセル | C25: 日ごとの変更確認、休船からの呼出、変更・取消しの記録
B26: 入渠 | C26: 作業に使えない期間
B27: 他港作業 | C27: 西日本海運の全他港作業
B28: 他社配置 | C28: 若松・関門等の他社の体制と依頼への対応可否
B29: 標準時間 | C29: 基地発～基地着の見込み時間
B30: マスター | C30: 会社・船名・基地港・品名・選択肢の追加
B31: 集計 | C31: 対比結果・供給可能船・不足情報（自動）

Sheet 実績
A1: 実績（元帳から自動表示・再入力しない）
A2: 誰が：全員が見るだけ 何を見て：元帳「作業実績R6.4～」シート「R7年度」 どこへ：入力欄はありません（休船からの呼出は「変更・キャンセル」で最初に対応した作業を選びます）
A3: 対象日 2025/11/01（前日から日をまたいで続く作業も表示）。時刻は元帳の「作業時間」で、基地発・基地着かは未確認のため「候補・時刻要確認」。集計先：「集計」「前日確定」「変更・キャンセル」
A5: 作業キー【自動】 | B5: 作業の表示名【自動】 | C5: 作業の先頭行【自動】 | D5: 作業日【自動】 | E5: 元帳の行番号【自動】 | F5: 元帳No【自動】 | G5: 本船名【自動】 | H5: G/T【自動】 | I5: 代理店（参考・会社判定に使わない）【自動】 | J5: 入出転【自動】 | K5: 六/部【自動】 | L5: バース【自動】 | M5: 品名【自動】 | N5: 予定時間（元帳・定義未確認）【自動】 | O5: 作業開始（元帳）【自動】 | P5: 作業終了（元帳）【自動】 | Q5: 終了が翌日【自動】 | R5: タグ（元帳の記号）【自動】 | S5: S列の記号（参考）【自動】 | T5: 備考1（元帳）【自動】 | U5: 取消しの記載【自動】 | V5: 時刻の扱い【自動】 | W5: 集計船名【自動】 | X5: 会社【自動】 | Y5: 会社区分【自動】 | Z5: 船名・会社の確認状況【自動】 | AA5: 船の種類【自動】 | AB5: 安瀬の扱い【自動】 | AC5: 作業区分（LNG入港・出港・警戒を区別）【自動】 | AD5: 高炉原料区分【自動】 | AE5: 開始日時【自動】 | AF5: 終了日時【自動】 | AG5: 前日からの継続【自動】 | AH5: 重複の警告【自動】 | AI5: 開始（分）【自動】 | AJ5: 終了（分）【自動】 | AK5: 同時稼働に含む【自動】 | AL5: 高炉原料を除く集計に含む【自動】 | AM5: 作業の開始（分）【自動】 | AN5: 作業の終了（分）【自動】
A6: 2025-11-01#01 | B6: 11/01 #01 09:00 入 試験本船1（T1） | C6: ○ | D6: 45962 | E6: 試験 | F6: 1 | G6: 試験本船1 | H6: 1000 | I6: 試験 | J6: 入 | L6: T1 | M6: 鋼材 | N6: 0.375 | O6: 0.375 | P6: 0.41666667 | R6: 試験A船 | V6: 候補・時刻要確認 | W6: =IFERROR(INDEX(マスター!$K$6:$K$125,MATCH(R6,マスター!$N$6:$N$125,0)),R6) -> 試験A船 | X6: =IFERROR(IF(IFERROR(INDEX(マスター!$C$6:$C$125,MATCH(R6,マスター!$N$6:$N$125,0)),NA())="","未確認",IFERROR(INDEX(マスター!$C$6:$C$125,MATCH(R6,マスター!$N$6:$N$125,0)),NA())),"マスター未登録") -> 試験会社 | Y6: =IFERROR(INDEX(マスター!$L$6:$L$125,MATCH(R6,マスター!$N$6:$N$125,0)),"マスター未登録") -> 他社 | Z6: =IFERROR(IF(IFERROR(INDEX(マスター!$J$6:$J$125,MATCH(R6,マスター!$N$6:$N$125,0)),NA())="","未確認",IFERROR(INDEX(マスター!$J$6:$J$125,MATCH(R6,マスター!$N$6:$N$125,0)),NA())),"マスター未登録") -> 確認済み | AA6: =IFERROR(IF(IFERROR(INDEX(マスター!$D$6:$D$125,MATCH(R6,マスター!$N$6:$N$125,0)),NA())="","未確認",IFERROR(INDEX(マスター!$D$6:$D$125,MATCH(R6,マスター!$N$6:$N$125,0)),NA())),"マスター未登録") -> タグ | AB6: =IF(IFERROR(INDEX(マスター!$Z$6:$Z$25,MATCH(M6,マスター!$X$6:$X$25,0)),"")="○","安瀬候補（要確認）","") | AC6: =IF(J6="","",IF(M6="LNG",IF(J6="入","LNG入港",IF(J6="出","LNG出港",IF(J6="当直","LNG警戒",IF(J6="エスコート","LNGエスコート","LNG"&J6)))),IF(J6="入","入港",IF(J6="出","出港",IF(J6="転","転錨・シフト",J6))))) -> 入港 | AD6: =IF(M6="","未確認",IFERROR(INDEX(マスター!$Y$6:$Y$25,MATCH(M6,マスター!$X$6:$X$25,0))&"","未確認")) -> 高炉原料以外 | AE6: =IF(O6="","",D6+O6) -> 45962.375 | AF6: =IF(P6="","",D6+P6+IF(Q6="○",1,0)) -> 45962.417 | AG6: =IF(D6<集計!$C$5,"前日から継続","") | AH6: =IF(AK6<>"○","",IF(COUNTIFS(実績!$W$6:$W$505,W6,実績!$AI$6:$AI$505,"<"&AJ6,実績!$AJ$6:$AJ$505,">"&AI6,実績!$AK$6:$AK$505,"○",実績!$A$6:$A$505,"<>"&A6)>0,"重複配船の警告（同じ船が同じ時間に別作業）",IF(COUNTIFS(実績!$W$6:$W$505,W6,実績!$AI$6:$AI$505,"<"&AJ6,実績!$AJ$6:$AJ$505,">"&AI6,実績!$AK$6:$AK$505,"○",実績!$A$6:$A$505,A6)>1,"同一記録の重複（1隻として数える）",""))) -> 同一記録の重複（1隻として数える） | AI6: =IF(OR(O6="",V6<>"候補・時刻要確認"),"",ROUND((D6-集計!$C$5)*1440+O6*1440,0)) -> 540 | AJ6: =IF(OR(P6="",V6<>"候補・時刻要確認"),"",ROUND((D6-集計!$C$5)*1440+P6*1440+IF(Q6="○",1440,0),0)) -> 600 | AK6: =IF(AND(AI6<>"",AJ6<>"",U6<>"○",AA6<>"通船・警戒船"),"○","") -> ○ | AL6: =IF(AND(AK6="○",AD6<>"高炉原料"),"○","") -> ○ | AM6: =IF(C6<>"○","",IF(COUNTIFS(実績!$A$6:$A$505,A6,実績!$AK$6:$AK$505,"○")=0,"",_xlfn.MINIFS(実績!$AI$6:$AI$505,実績!$A$6:$A$505,A6,実績!$AK$6:$AK$505,"○"))) -> 540 | AN6: =IF(C6<>"○","",IF(COUNTIFS(実績!$A$6:$A$505,A6,実績!$AK$6:$AK$505,"○")=0,"",_xlfn.MAXIFS(実績!$AJ$6:$AJ$505,実績!$A$6:$A$505,A6,実績!$AK$6:$AK$505,"○"))) -> 600
A7: 2025-11-01#01 | B7: 11/01 #01 09:00 入 試験本船1（T1） | D7: 45962 | E7: 試験 | G7: 試験本船1 | H7: 1000 | I7: 試験 | J7: 入 | L7: T1 | M7: 鋼材 | N7: 0.375 | O7: 0.375 | P7: 0.41666667 | R7: 試験A船 | V7: 候補・時刻要確認 | W7: =IFERROR(INDEX(マスター!$K$6:$K$125,MATCH(R7,マスター!$N$6:$N$125,0)),R7) -> 試験A船 | X7: =IFERROR(IF(IFERROR(INDEX(マスター!$C$6:$C$125,MATCH(R7,マスター!$N$6:$N$125,0)),NA())="","未確認",IFERROR(INDEX(マスター!$C$6:$C$125,MATCH(R7,マスター!$N$6:$N$125,0)),NA())),"マスター未登録") -> 試験会社 | Y7: =IFERROR(INDEX(マスター!$L$6:$L$125,MATCH(R7,マスター!$N$6:$N$125,0)),"マスター未登録") -> 他社 | Z7: =IFERROR(IF(IFERROR(INDEX(マスター!$J$6:$J$125,MATCH(R7,マスター!$N$6:$N$125,0)),NA())="","未確認",IFERROR(INDEX(マスター!$J$6:$J$125,MATCH(R7,マスター!$N$6:$N$125,0)),NA())),"マスター未登録") -> 確認済み | AA7: =IFERROR(IF(IFERROR(INDEX(マスター!$D$6:$D$125,MATCH(R7,マスター!$N$6:$N$125,0)),NA())="","未確認",IFERROR(INDEX(マスター!$D$6:$D$125,MATCH(R7,マスター!$N$6:$N$125,0)),NA())),"マスター未登録") -> タグ | AB7: =IF(IFERROR(INDEX(マスター!$Z$6:$Z$25,MATCH(M7,マスター!$X$6:$X$25,0)),"")="○","安瀬候補（要確認）","") | AC7: =IF(J7="","",IF(M7="LNG",IF(J7="入","LNG入港",IF(J7="出","LNG出港",IF(J7="当直","LNG警戒",IF(J7="エスコート","LNGエスコート","LNG"&J7)))),IF(J7="入","入港",IF(J7="出","出港",IF(J7="転","転錨・シフト",J7))))) -> 入港 | AD7: =IF(M7="","未確認",IFERROR(INDEX(マスター!$Y$6:$Y$25,MATCH(M7,マスター!$X$6:$X$25,0))&"","未確認")) -> 高炉原料以外 | AE7: =IF(O7="","",D7+O7) -> 45962.375 | AF7: =IF(P7="","",D7+P7+IF(Q7="○",1,0)) -> 45962.417 | AG7: =IF(D7<集計!$C$5,"前日から継続","") | AH7: =IF(AK7<>"○","",IF(COUNTIFS(実績!$W$6:$W$505,W7,実績!$AI$6:$AI$505,"<"&AJ7,実績!$AJ$6:$AJ$505,">"&AI7,実績!$AK$6:$AK$505,"○",実績!$A$6:$A$505,"<>"&A7)>0,"重複配船の警告（同じ船が同じ時間に別作業）",IF(COUNTIFS(実績!$W$6:$W$505,W7,実績!$AI$6:$AI$505,"<"&AJ7,実績!$AJ$6:$AJ$505,">"&AI7,実績!$AK$6:$AK$505,"○",実績!$A$6:$A$505,A7)>1,"同一記録の重複（1隻として数える）",""))) -> 同一記録の重複（1隻として数える） | AI7: =IF(OR(O7="",V7<>"候補・時刻要確認"),"",ROUND((D7-集計!$C$5)*1440+O7*1440,0)) -> 540 | AJ7: =IF(OR(P7="",V7<>"候補・時刻要確認"),"",ROUND((D7-集計!$C$5)*1440+P7*1440+IF(Q7="○",1440,0),0)) -> 600 | AK7: =IF(AND(AI7<>"",AJ7<>"",U7<>"○",AA7<>"通船・警戒船"),"○","") -> ○ | AL7: =IF(AND(AK7="○",AD7<>"高炉原料"),"○","") -> ○ | AM7: =IF(C7<>"○","",IF(COUNTIFS(実績!$A$6:$A$505,A7,実績!$AK$6:$AK$505,"○")=0,"",_xlfn.MINIFS(実績!$AI$6:$AI$505,実績!$A$6:$A$505,A7,実績!$AK$6:$AK$505,"○"))) | AN7: =IF(C7<>"○","",IF(COUNTIFS(実績!$A$6:$A$505,A7,実績!$AK$6:$AK$505,"○")=0,"",_xlfn.MAXIFS(実績!$AJ$6:$AJ$505,実績!$A$6:$A$505,A7,実績!$AK$6:$AK$505,"○")))
A8: 2025-11-01#02 | B8: 11/01 #02 09:00 入 試験本船2（T1） | C8: ○ | D8: 45962 | E8: 試験 | F8: 1 | G8: 試験本船2 | H8: 1000 | I8: 試験 | J8: 入 | L8: T1 | M8: 鋼材 | N8: 0.375 | O8: 0.375 | P8: 0.41666667 | R8: 試験B船 | V8: 候補・時刻要確認 | W8: =IFERROR(INDEX(マスター!$K$6:$K$125,MATCH(R8,マスター!$N$6:$N$125,0)),R8) -> 試験B船 | X8: =IFERROR(IF(IFERROR(INDEX(マスター!$C$6:$C$125,MATCH(R8,マスター!$N$6:$N$125,0)),NA())="","未確認",IFERROR(INDEX(マスター!$C$6:$C$125,MATCH(R8,マスター!$N$6:$N$125,0)),NA())),"マスター未登録") -> 試験会社 | Y8: =IFERROR(INDEX(マスター!$L$6:$L$125,MATCH(R8,マスター!$N$6:$N$125,0)),"マスター未登録") -> 他社 | Z8: =IFERROR(IF(IFERROR(INDEX(マスター!$J$6:$J$125,MATCH(R8,マスター!$N$6:$N$125,0)),NA())="","未確認",IFERROR(INDEX(マスター!$J$6:$J$125,MATCH(R8,マスター!$N$6:$N$125,0)),NA())),"マスター未登録") -> 確認済み | AA8: =IFERROR(IF(IFERROR(INDEX(マスター!$D$6:$D$125,MATCH(R8,マスター!$N$6:$N$125,0)),NA())="","未確認",IFERROR(INDEX(マスター!$D$6:$D$125,MATCH(R8,マスター!$N$6:$N$125,0)),NA())),"マスター未登録") -> タグ | AB8: =IF(IFERROR(INDEX(マスター!$Z$6:$Z$25,MATCH(M8,マスター!$X$6:$X$25,0)),"")="○","安瀬候補（要確認）","") | AC8: =IF(J8="","",IF(M8="LNG",IF(J8="入","LNG入港",IF(J8="出","LNG出港",IF(J8="当直","LNG警戒",IF(J8="エスコート","LNGエスコート","LNG"&J8)))),IF(J8="入","入港",IF(J8="出","出港",IF(J8="転","転錨・シフト",J8))))) -> 入港 | AD8: =IF(M8="","未確認",IFERROR(INDEX(マスター!$Y$6:$Y$25,MATCH(M8,マスター!$X$6:$X$25,0))&"","未確認")) -> 高炉原料以外 | AE8: =IF(O8="","",D8+O8) -> 45962.375 | AF8: =IF(P8="","",D8+P8+IF(Q8="○",1,0)) -> 45962.417 | AG8: =IF(D8<集計!$C$5,"前日から継続","") | AH8: =IF(AK8<>"○","",IF(COUNTIFS(実績!$W$6:$W$505,W8,実績!$AI$6:$AI$505,"<"&AJ8,実績!$AJ$6:$AJ$505,">"&AI8,実績!$AK$6:$AK$505,"○",実績!$A$6:$A$505,"<>"&A8)>0,"重複配船の警告（同じ船が同じ時間に別作業）",IF(COUNTIFS(実績!$W$6:$W$505,W8,実績!$AI$6:$AI$505,"<"&AJ8,実績!$AJ$6:$AJ$505,">"&AI8,実績!$AK$6:$AK$505,"○",実績!$A$6:$A$505,A8)>1,"同一記録の重複（1隻として数える）",""))) | AI8: =IF(OR(O8="",V8<>"候補・時刻要確認"),"",ROUND((D8-集計!$C$5)*1440+O8*1440,0)) -> 540 | AJ8: =IF(OR(P8="",V8<>"候補・時刻要確認"),"",ROUND((D8-集計!$C$5)*1440+P8*1440+IF(Q8="○",1440,0),0)) -> 600 | AK8: =IF(AND(AI8<>"",AJ8<>"",U8<>"○",AA8<>"通船・警戒船"),"○","") -> ○ | AL8: =IF(AND(AK8="○",AD8<>"高炉原料"),"○","") -> ○ | AM8: =IF(C8<>"○","",IF(COUNTIFS(実績!$A$6:$A$505,A8,実績!$AK$6:$AK$505,"○")=0,"",_xlfn.MINIFS(実績!$AI$6:$AI$505,実績!$A$6:$A$505,A8,実績!$AK$6:$AK$505,"○"))) -> 540 | AN8: =IF(C8<>"○","",IF(COUNTIFS(実績!$A$6:$A$505,A8,実績!$AK$6:$AK$505,"○")=0,"",_xlfn.MAXIFS(実績!$AJ$6:$AJ$505,実績!$A$6:$A$505,A8,実績!$AK$6:$AK$505,"○"))) -> 600
A9: 2025-11-01#03 | B9: 11/01 #03 09:30 出 試験本船3（T1） | C9: ○ | D9: 45962 | E9: 試験 | F9: 1 | G9: 試験本船3 | H9: 1000 | I9: 試験 | J9: 出 | L9: T1 | M9: 鋼材 | N9: 0.39583333 | O9: 0.39583333 | P9: 0.4375 | R9: 試験C船 | V9: 候補・時刻要確認 | W9: =IFERROR(INDEX(マスター!$K$6:$K$125,MATCH(R9,マスター!$N$6:$N$125,0)),R9) -> 試験C船 | X9: =IFERROR(IF(IFERROR(INDEX(マスター!$C$6:$C$125,MATCH(R9,マスター!$N$6:$N$125,0)),NA())="","未確認",IFERROR(INDEX(マスター!$C$6:$C$125,MATCH(R9,マスター!$N$6:$N$125,0)),NA())),"マスター未登録") -> 試験会社 | Y9: =IFERROR(INDEX(マスター!$L$6:$L$125,MATCH(R9,マスター!$N$6:$N$125,0)),"マスター未登録") -> 他社 | Z9: =IFERROR(IF(IFERROR(INDEX(マスター!$J$6:$J$125,MATCH(R9,マスター!$N$6:$N$125,0)),NA())="","未確認",IFERROR(INDEX(マスター!$J$6:$J$125,MATCH(R9,マスター!$N$6:$N$125,0)),NA())),"マスター未登録") -> 確認済み | AA9: =IFERROR(IF(IFERROR(INDEX(マスター!$D$6:$D$125,MATCH(R9,マスター!$N$6:$N$125,0)),NA())="","未確認",IFERROR(INDEX(マスター!$D$6:$D$125,MATCH(R9,マスター!$N$6:$N$125,0)),NA())),"マスター未登録") -> タグ | AB9: =IF(IFERROR(INDEX(マスター!$Z$6:$Z$25,MATCH(M9,マスター!$X$6:$X$25,0)),"")="○","安瀬候補（要確認）","") | AC9: =IF(J9="","",IF(M9="LNG",IF(J9="入","LNG入港",IF(J9="出","LNG出港",IF(J9="当直","LNG警戒",IF(J9="エスコート","LNGエスコート","LNG"&J9)))),IF(J9="入","入港",IF(J9="出","出港",IF(J9="転","転錨・シフト",J9))))) -> 出港 | AD9: =IF(M9="","未確認",IFERROR(INDEX(マスター!$Y$6:$Y$25,MATCH(M9,マスター!$X$6:$X$25,0))&"","未確認")) -> 高炉原料以外 | AE9: =IF(O9="","",D9+O9) -> 45962.396 | AF9: =IF(P9="","",D9+P9+IF(Q9="○",1,0)) -> 45962.438 | AG9: =IF(D9<集計!$C$5,"前日から継続","") | AH9: =IF(AK9<>"○","",IF(COUNTIFS(実績!$W$6:$W$505,W9,実績!$AI$6:$AI$505,"<"&AJ9,実績!$AJ$6:$AJ$505,">"&AI9,実績!$AK$6:$AK$505,"○",実績!$A$6:$A$505,"<>"&A9)>0,"重複配船の警告（同じ船が同じ時間に別作業）",IF(COUNTIFS(実績!$W$6:$W$505,W9,実績!$AI$6:$AI$505,"<"&AJ9,実績!$AJ$6:$AJ$505,">"&AI9,実績!$AK$6:$AK$505,"○",実績!$A$6:$A$505,A9)>1,"同一記録の重複（1隻として数える）",""))) | AI9: =IF(OR(O9="",V9<>"候補・時刻要確認"),"",ROUND((D9-集計!$C$5)*1440+O9*1440,0)) -> 570 | AJ9: =IF(OR(P9="",V9<>"候補・時刻要確認"),"",ROUND((D9-集計!$C$5)*1440+P9*1440+IF(Q9="○",1440,0),0)) -> 630 | AK9: =IF(AND(AI9<>"",AJ9<>"",U9<>"○",AA9<>"通船・警戒船"),"○","") -> ○ | AL9: =IF(AND(AK9="○",AD9<>"高炉原料"),"○","") -> ○ | AM9: =IF(C9<>"○","",IF(COUNTIFS(実績!$A$6:$A$505,A9,実績!$AK$6:$AK$505,"○")=0,"",_xlfn.MINIFS(実績!$AI$6:$AI$505,実績!$A$6:$A$505,A9,実績!$AK$6:$AK$505,"○"))) -> 570 | AN9: =IF(C9<>"○","",IF(COUNTIFS(実績!$A$6:$A$505,A9,実績!$AK$6:$AK$505,"○")=0,"",_xlfn.MAXIFS(実績!$AJ$6:$AJ$505,実績!$A$6:$A$505,A9,実績!$AK$6:$AK$505,"○"))) -> 630

Sheet 前日確定
A1: 前日確定（対象日の前日最終の予定表と翌日の出勤手配）
A2: 誰が：上田 何を見て：対象日の前日に翌日の出勤を手配した最終の作業予定表 どこへ：①C7～C10 ②出勤手配（B14～） ③作業ごとの予定（J列～T列）。予定表にあって実績にない作業は下の空き行へ追加
A3: 集計先：「集計」の予定・出勤手配、「変更・キャンセル」の変更前の時刻・タグ。ここに入れた前日最終の値は変更があっても上書きしません。
A5: ■ 対象日の予定表
A6: 対象日【自動（取込時に設定）】 | C6: 45962
A7: 根拠の予定表（ファイル名・版）【入力】 | F7: ◀ 最初の入力はここ（対象日の前日最終の予定表のファイル名・版。2025年度分は本一式に含まれていないため、上田さんの照合で入力）
A8: 予定表の確定時点（日時）【入力】
A9: 照合した人【入力】
A10: 照合の状況【入力・選択】 | C10: 未確認
A12: ■ 翌日の出勤手配（対象日の前日に手配した船）と、実際に出勤・待機したか
A13: No | B13: 船名【入力・選択】 | C13: 会社【自動】 | D13: 基地港【自動】 | E13: 手配した日時【入力】 | F13: 実際の出勤・待機【入力・選択】 | G13: 情報元【入力】
A14: 1 | C14: =IF(B14="","",IFERROR(IF(IFERROR(INDEX(マスター!$C$6:$C$125,MATCH(B14,マスター!$N$6:$N$125,0)),NA())="","未確認",IFERROR(INDEX(マスター!$C$6:$C$125,MATCH(B14,マスター!$N$6:$N$125,0)),NA())),"マスター未登録")) | D14: =IF(B14="","",IFERROR(IF(IFERROR(INDEX(マスター!$E$6:$E$125,MATCH(B14,マスター!$N$6:$N$125,0)),NA())="","未確認",IFERROR(INDEX(マスター!$E$6:$E$125,MATCH(B14,マスター!$N$6:$N$125,0)),NA())),"マスター未登録"))
A15: 2 | C15: =IF(B15="","",IFERROR(IF(IFERROR(INDEX(マスター!$C$6:$C$125,MATCH(B15,マスター!$N$6:$N$125,0)),NA())="","未確認",IFERROR(INDEX(マスター!$C$6:$C$125,MATCH(B15,マスター!$N$6:$N$125,0)),NA())),"マスター未登録")) | D15: =IF(B15="","",IFERROR(IF(IFERROR(INDEX(マスター!$E$6:$E$125,MATCH(B15,マスター!$N$6:$N$125,0)),NA())="","未確認",IFERROR(INDEX(マスター!$E$6:$E$125,MATCH(B15,マスター!$N$6:$N$125,0)),NA())),"マスター未登録"))
A16: 3 | C16: =IF(B16="","",IFERROR(IF(IFERROR(INDEX(マスター!$C$6:$C$125,MATCH(B16,マスター!$N$6:$N$125,0)),NA())="","未確認",IFERROR(INDEX(マスター!$C$6:$C$125,MATCH(B16,マスター!$N$6:$N$125,0)),NA())),"マスター未登録")) | D16: =IF(B16="","",IFERROR(IF(IFERROR(INDEX(マスター!$E$6:$E$125,MATCH(B16,マスター!$N$6:$N$125,0)),NA())="","未確認",IFERROR(INDEX(マスター!$E$6:$E$125,MATCH(B16,マスター!$N$6:$N$125,0)),NA())),"マスター未登録"))
A17: 4 | C17: =IF(B17="","",IFERROR(IF(IFERROR(INDEX(マスター!$C$6:$C$125,MATCH(B17,マスター!$N$6:$N$125,0)),NA())="","未確認",IFERROR(INDEX(マスター!$C$6:$C$125,MATCH(B17,マスター!$N$6:$N$125,0)),NA())),"マスター未登録")) | D17: =IF(B17="","",IFERROR(IF(IFERROR(INDEX(マスター!$E$6:$E$125,MATCH(B17,マスター!$N$6:$N$125,0)),NA())="","未確認",IFERROR(INDEX(マスター!$E$6:$E$125,MATCH(B17,マスター!$N$6:$N$125,0)),NA())),"マスター未登録"))
A18: 5 | C18: =IF(B18="","",IFERROR(IF(IFERROR(INDEX(マスター!$C$6:$C$125,MATCH(B18,マスター!$N$6:$N$125,0)),NA())="","未確認",IFERROR(INDEX(マスター!$C$6:$C$125,MATCH(B18,マスター!$N$6:$N$125,0)),NA())),"マスター未登録")) | D18: =IF(B18="","",IFERROR(IF(IFERROR(INDEX(マスター!$E$6:$E$125,MATCH(B18,マスター!$N$6:$N$125,0)),NA())="","未確認",IFERROR(INDEX(マスター!$E$6:$E$125,MATCH(B18,マスター!$N$6:$N$125,0)),NA())),"マスター未登録"))
A19: 6 | C19: =IF(B19="","",IFERROR(IF(IFERROR(INDEX(マスター!$C$6:$C$125,MATCH(B19,マスター!$N$6:$N$125,0)),NA())="","未確認",IFERROR(INDEX(マスター!$C$6:$C$125,MATCH(B19,マスター!$N$6:$N$125,0)),NA())),"マスター未登録")) | D19: =IF(B19="","",IFERROR(IF(IFERROR(INDEX(マスター!$E$6:$E$125,MATCH(B19,マスター!$N$6:$N$125,0)),NA())="","未確認",IFERROR(INDEX(マスター!$E$6:$E$125,MATCH(B19,マスター!$N$6:$N$125,0)),NA())),"マスター未登録"))
A20: 7 | C20: =IF(B20="","",IFERROR(IF(IFERROR(INDEX(マスター!$C$6:$C$125,MATCH(B20,マスター!$N$6:$N$125,0)),NA())="","未確認",IFERROR(INDEX(マスター!$C$6:$C$125,MATCH(B20,マスター!$N$6:$N$125,0)),NA())),"マスター未登録")) | D20: =IF(B20="","",IFERROR(IF(IFERROR(INDEX(マスター!$E$6:$E$125,MATCH(B20,マスター!$N$6:$N$125,0)),NA())="","未確認",IFERROR(INDEX(マスター!$E$6:$E$125,MATCH(B20,マスター!$N$6:$N$125,0)),NA())),"マスター未登録"))
A21: 8 | C21: =IF(B21="","",IFERROR(IF(IFERROR(INDEX(マスター!$C$6:$C$125,MATCH(B21,マスター!$N$6:$N$125,0)),NA())="","未確認",IFERROR(INDEX(マスター!$C$6:$C$125,MATCH(B21,マスター!$N$6:$N$125,0)),NA())),"マスター未登録")) | D21: =IF(B21="","",IFERROR(IF(IFERROR(INDEX(マスター!$E$6:$E$125,MATCH(B21,マスター!$N$6:$N$125,0)),NA())="","未確認",IFERROR(INDEX(マスター!$E$6:$E$125,MATCH(B21,マスター!$N$6:$N$125,0)),NA())),"マスター未登録"))
A22: 出勤手配隻数【自動】 | C22: =IF(COUNTA(B14:B21)=0,0,SUMPRODUCT((B14:B21<>"")/COUNTIF(B14:B21,B14:B21&""))) -> 0
A23: 実際に出勤した隻数【自動】 | C23: =IF(COUNTA(B14:B21)=0,0,SUMPRODUCT((B14:B21<>"")*(LEFT(F14:F21,4)="出勤して")/COUNTIF(B14:B21,B14:B21&""))) -> 0
A24: ■ 作業ごとの前日最終予定（実績の作業は自動表示。予定表にだけある作業は下の空き行へ追加）
A25: 区分【自動】 | B25: 作業の表示名【自動】 | C25: 作業キー【自動】 | D25: 本船名【自動／予定のみは入力】 | E25: 入出転【自動／予定のみは入力】 | F25: バース【自動／予定のみは入力】 | G25: 実績のタグ（元帳）【自動】 | H25: 実績タグ数【自動】 | I25: 元帳の予定時間（参考・前日確定とは限らない）【自動】 | J25: 前日最終の予定時刻【入力】（翌日は日付も） | K25: 予定タグ①【入力・選択】 | L25: 予定タグ②【入力・選択】 | M25: 予定タグ③【入力・選択】 | N25: 予定タグ④【入力・選択】 | O25: 予定タグ⑤【入力・選択】 | P25: 予定タグ⑥【入力・選択】 | Q25: 予定タグ数【自動】 | R25: 予定タグ（まとめ）【自動】 | S25: 照合の状況【入力・選択】 | T25: 備考【入力】 | U25: 変更回数【自動】 | V25: 変更後の最終日時【自動】 | W25: 取消し【自動】 | X25: 作業日【自動】 | Y25: 前日確定の日時【自動】
A26: 実績あり | B26: 11/01 #01 09:00 入 試験本船1（T1） | C26: 2025-11-01#01 | D26: 試験本船1 | E26: 入 | F26: T1 | G26: 試験A船・試験A船 | H26: =IF(C26="","",COUNTIF(実績!$A$6:$A$505,C26)) -> 2 | I26: 0.375 | Q26: =IF(C26="","",COUNTA(K26:P26)) -> 0 | R26: =_xlfn.TEXTJOIN("・",TRUE(),K26:P26) | S26: 未確認 | U26: =IF(C26="","",COUNTIF(変更・キャンセル!$B$26:$B$85,C26)) -> 0 | V26: =IF(OR(C26="",U26=0),"",INDEX(変更・キャンセル!$AA$26:$AA$85,MATCH(C26&"#"&U26,変更・キャンセル!$Z$26:$Z$85,0))) | W26: =IF(C26="","",IF(COUNTIFS(変更・キャンセル!$B$26:$B$85,C26,変更・キャンセル!$R$26:$R$85,"○")>0,"○","")) | X26: 45962 | Y26: =IF(OR(C26="",J26=""),"",IF(J26<1,X26+J26,J26))
A27: 実績あり | B27: 11/01 #02 09:00 入 試験本船2（T1） | C27: 2025-11-01#02 | D27: 試験本船2 | E27: 入 | F27: T1 | G27: 試験B船 | H27: =IF(C27="","",COUNTIF(実績!$A$6:$A$505,C27)) -> 1 | I27: 0.375 | Q27: =IF(C27="","",COUNTA(K27:P27)) -> 0 | R27: =_xlfn.TEXTJOIN("・",TRUE(),K27:P27) | S27: 未確認 | U27: =IF(C27="","",COUNTIF(変更・キャンセル!$B$26:$B$85,C27)) -> 0 | V27: =IF(OR(C27="",U27=0),"",INDEX(変更・キャンセル!$AA$26:$AA$85,MATCH(C27&"#"&U27,変更・キャンセル!$Z$26:$Z$85,0))) | W27: =IF(C27="","",IF(COUNTIFS(変更・キャンセル!$B$26:$B$85,C27,変更・キャンセル!$R$26:$R$85,"○")>0,"○","")) | X27: 45962 | Y27: =IF(OR(C27="",J27=""),"",IF(J27<1,X27+J27,J27))
A28: 実績あり | B28: 11/01 #03 09:30 出 試験本船3（T1） | C28: 2025-11-01#03 | D28: 試験本船3 | E28: 出 | F28: T1 | G28: 試験C船 | H28: =IF(C28="","",COUNTIF(実績!$A$6:$A$505,C28)) -> 1 | I28: 0.39583333 | Q28: =IF(C28="","",COUNTA(K28:P28)) -> 0 | R28: =_xlfn.TEXTJOIN("・",TRUE(),K28:P28) | S28: 未確認 | U28: =IF(C28="","",COUNTIF(変更・キャンセル!$B$26:$B$85,C28)) -> 0 | V28: =IF(OR(C28="",U28=0),"",INDEX(変更・キャンセル!$AA$26:$AA$85,MATCH(C28&"#"&U28,変更・キャンセル!$Z$26:$Z$85,0))) | W28: =IF(C28="","",IF(COUNTIFS(変更・キャンセル!$B$26:$B$85,C28,変更・キャンセル!$R$26:$R$85,"○")>0,"○","")) | X28: 45962 | Y28: =IF(OR(C28="",J28=""),"",IF(J28<1,X28+J28,J28)) | Z28: ▼ ここから下は予定表にだけある作業（実績のない取消し等）を追加する行
A29: =IF(D29="","","予定のみ") | B29: =IF(D29="","","11/01 予定のみ#01 "&IF(J29="","--:--",TEXT(J29,"hh:mm"))&" "&E29&" "&D29) | C29: =IF(D29="","","2025-11-01予定のみ#01") | G29: =IF(D29="","","（実績なし）") | H29: =IF(C29="","",COUNTIF(実績!$A$6:$A$505,C29)) | Q29: =IF(C29="","",COUNTA(K29:P29)) | R29: =_xlfn.TEXTJOIN("・",TRUE(),K29:P29) | U29: =IF(C29="","",COUNTIF(変更・キャンセル!$B$26:$B$85,C29)) | V29: =IF(OR(C29="",U29=0),"",INDEX(変更・キャンセル!$AA$26:$AA$85,MATCH(C29&"#"&U29,変更・キャンセル!$Z$26:$Z$85,0))) | W29: =IF(C29="","",IF(COUNTIFS(変更・キャンセル!$B$26:$B$85,C29,変更・キャンセル!$R$26:$R$85,"○")>0,"○","")) | X29: =IF(D29="","",$C$6) | Y29: =IF(OR(C29="",J29=""),"",IF(J29<1,X29+J29,J29))
A30: =IF(D30="","","予定のみ") | B30: =IF(D30="","","11/01 予定のみ#02 "&IF(J30="","--:--",TEXT(J30,"hh:mm"))&" "&E30&" "&D30) | C30: =IF(D30="","","2025-11-01予定のみ#02") | G30: =IF(D30="","","（実績なし）") | H30: =IF(C30="","",COUNTIF(実績!$A$6:$A$505,C30)) | Q30: =IF(C30="","",COUNTA(K30:P30)) | R30: =_xlfn.TEXTJOIN("・",TRUE(),K30:P30) | U30: =IF(C30="","",COUNTIF(変更・キャンセル!$B$26:$B$85,C30)) | V30: =IF(OR(C30="",U30=0),"",INDEX(変更・キャンセル!$AA$26:$AA$85,MATCH(C30&"#"&U30,変更・キャンセル!$Z$26:$Z$85,0))) | W30: =IF(C30="","",IF(COUNTIFS(変更・キャンセル!$B$26:$B$85,C30,変更・キャンセル!$R$26:$R$85,"○")>0,"○","")) | X30: =IF(D30="","",$C$6) | Y30: =IF(OR(C30="",J30=""),"",IF(J30<1,X30+J30,J30))
A31: =IF(D31="","","予定のみ") | B31: =IF(D31="","","11/01 予定のみ#03 "&IF(J31="","--:--",TEXT(J31,"hh:mm"))&" "&E31&" "&D31) | C31: =IF(D31="","","2025-11-01予定のみ#03") | G31: =IF(D31="","","（実績なし）") | H31: =IF(C31="","",COUNTIF(実績!$A$6:$A$505,C31)) | Q31: =IF(C31="","",COUNTA(K31:P31)) | R31: =_xlfn.TEXTJOIN("・",TRUE(),K31:P31) | U31: =IF(C31="","",COUNTIF(変更・キャンセル!$B$26:$B$85,C31)) | V31: =IF(OR(C31="",U31=0),"",INDEX(変更・キャンセル!$AA$26:$AA$85,MATCH(C31&"#"&U31,変更・キャンセル!$Z$26:$Z$85,0))) | W31: =IF(C31="","",IF(COUNTIFS(変更・キャンセル!$B$26:$B$85,C31,変更・キャンセル!$R$26:$R$85,"○")>0,"○","")) | X31: =IF(D31="","",$C$6) | Y31: =IF(OR(C31="",J31=""),"",IF(J31<1,X31+J31,J31))
A32: =IF(D32="","","予定のみ") | B32: =IF(D32="","","11/01 予定のみ#04 "&IF(J32="","--:--",TEXT(J32,"hh:mm"))&" "&E32&" "&D32) | C32: =IF(D32="","","2025-11-01予定のみ#04") | G32: =IF(D32="","","（実績なし）") | H32: =IF(C32="","",COUNTIF(実績!$A$6:$A$505,C32)) | Q32: =IF(C32="","",COUNTA(K32:P32)) | R32: =_xlfn.TEXTJOIN("・",TRUE(),K32:P32) | U32: =IF(C32="","",COUNTIF(変更・キャンセル!$B$26:$B$85,C32)) | V32: =IF(OR(C32="",U32=0),"",INDEX(変更・キャンセル!$AA$26:$AA$85,MATCH(C32&"#"&U32,変更・キャンセル!$Z$26:$Z$85,0))) | W32: =IF(C32="","",IF(COUNTIFS(変更・キャンセル!$B$26:$B$85,C32,変更・キャンセル!$R$26:$R$85,"○")>0,"○","")) | X32: =IF(D32="","",$C$6) | Y32: =IF(OR(C32="",J32=""),"",IF(J32<1,X32+J32,J32))
A33: =IF(D33="","","予定のみ") | B33: =IF(D33="","","11/01 予定のみ#05 "&IF(J33="","--:--",TEXT(J33,"hh:mm"))&" "&E33&" "&D33) | C33: =IF(D33="","","2025-11-01予定のみ#05") | G33: =IF(D33="","","（実績なし）") | H33: =IF(C33="","",COUNTIF(実績!$A$6:$A$505,C33)) | Q33: =IF(C33="","",COUNTA(K33:P33)) | R33: =_xlfn.TEXTJOIN("・",TRUE(),K33:P33) | U33: =IF(C33="","",COUNTIF(変更・キャンセル!$B$26:$B$85,C33)) | V33: =IF(OR(C33="",U33=0),"",INDEX(変更・キャンセル!$AA$26:$AA$85,MATCH(C33&"#"&U33,変更・キャンセル!$Z$26:$Z$85,0))) | W33: =IF(C33="","",IF(COUNTIFS(変更・キャンセル!$B$26:$B$85,C33,変更・キャンセル!$R$26:$R$85,"○")>0,"○","")) | X33: =IF(D33="","",$C$6) | Y33: =IF(OR(C33="",J33=""),"",IF(J33<1,X33+J33,J33))
A34: =IF(D34="","","予定のみ") | B34: =IF(D34="","","11/01 予定のみ#06 "&IF(J34="","--:--",TEXT(J34,"hh:mm"))&" "&E34&" "&D34) | C34: =IF(D34="","","2025-11-01予定のみ#06") | G34: =IF(D34="","","（実績なし）") | H34: =IF(C34="","",COUNTIF(実績!$A$6:$A$505,C34)) | Q34: =IF(C34="","",COUNTA(K34:P34)) | R34: =_xlfn.TEXTJOIN("・",TRUE(),K34:P34) | U34: =IF(C34="","",COUNTIF(変更・キャンセル!$B$26:$B$85,C34)) | V34: =IF(OR(C34="",U34=0),"",INDEX(変更・キャンセル!$AA$26:$AA$85,MATCH(C34&"#"&U34,変更・キャンセル!$Z$26:$Z$85,0))) | W34: =IF(C34="","",IF(COUNTIFS(変更・キャンセル!$B$26:$B$85,C34,変更・キャンセル!$R$26:$R$85,"○")>0,"○","")) | X34: =IF(D34="","",$C$6) | Y34: =IF(OR(C34="",J34=""),"",IF(J34<1,X34+J34,J34))
A35: =IF(D35="","","予定のみ") | B35: =IF(D35="","","11/01 予定のみ#07 "&IF(J35="","--:--",TEXT(J35,"hh:mm"))&" "&E35&" "&D35) | C35: =IF(D35="","","2025-11-01予定のみ#07") | G35: =IF(D35="","","（実績なし）") | H35: =IF(C35="","",COUNTIF(実績!$A$6:$A$505,C35)) | Q35: =IF(C35="","",COUNTA(K35:P35)) | R35: =_xlfn.TEXTJOIN("・",TRUE(),K35:P35) | U35: =IF(C35="","",COUNTIF(変更・キャンセル!$B$26:$B$85,C35)) | V35: =IF(OR(C35="",U35=0),"",INDEX(変更・キャンセル!$AA$26:$AA$85,MATCH(C35&"#"&U35,変更・キャンセル!$Z$26:$Z$85,0))) | W35: =IF(C35="","",IF(COUNTIFS(変更・キャンセル!$B$26:$B$85,C35,変更・キャンセル!$R$26:$R$85,"○")>0,"○","")) | X35: =IF(D35="","",$C$6) | Y35: =IF(OR(C35="",J35=""),"",IF(J35<1,X35+J35,J35))
A36: =IF(D36="","","予定のみ") | B36: =IF(D36="","","11/01 予定のみ#08 "&IF(J36="","--:--",TEXT(J36,"hh:mm"))&" "&E36&" "&D36) | C36: =IF(D36="","","2025-11-01予定のみ#08") | G36: =IF(D36="","","（実績なし）") | H36: =IF(C36="","",COUNTIF(実績!$A$6:$A$505,C36)) | Q36: =IF(C36="","",COUNTA(K36:P36)) | R36: =_xlfn.TEXTJOIN("・",TRUE(),K36:P36) | U36: =IF(C36="","",COUNTIF(変更・キャンセル!$B$26:$B$85,C36)) | V36: =IF(OR(C36="",U36=0),"",INDEX(変更・キャンセル!$AA$26:$AA$85,MATCH(C36&"#"&U36,変更・キャンセル!$Z$26:$Z$85,0))) | W36: =IF(C36="","",IF(COUNTIFS(変更・キャンセル!$B$26:$B$85,C36,変更・キャンセル!$R$26:$R$85,"○")>0,"○","")) | X36: =IF(D36="","",$C$6) | Y36: =IF(OR(C36="",J36=""),"",IF(J36<1,X36+J36,J36))
A37: =IF(D37="","","予定のみ") | B37: =IF(D37="","","11/01 予定のみ#09 "&IF(J37="","--:--",TEXT(J37,"hh:mm"))&" "&E37&" "&D37) | C37: =IF(D37="","","2025-11-01予定のみ#09") | G37: =IF(D37="","","（実績なし）") | H37: =IF(C37="","",COUNTIF(実績!$A$6:$A$505,C37)) | Q37: =IF(C37="","",COUNTA(K37:P37)) | R37: =_xlfn.TEXTJOIN("・",TRUE(),K37:P37) | U37: =IF(C37="","",COUNTIF(変更・キャンセル!$B$26:$B$85,C37)) | V37: =IF(OR(C37="",U37=0),"",INDEX(変更・キャンセル!$AA$26:$AA$85,MATCH(C37&"#"&U37,変更・キャンセル!$Z$26:$Z$85,0))) | W37: =IF(C37="","",IF(COUNTIFS(変更・キャンセル!$B$26:$B$85,C37,変更・キャンセル!$R$26:$R$85,"○")>0,"○","")) | X37: =IF(D37="","",$C$6) | Y37: =IF(OR(C37="",J37=""),"",IF(J37<1,X37+J37,J37))
A38: =IF(D38="","","予定のみ") | B38: =IF(D38="","","11/01 予定のみ#10 "&IF(J38="","--:--",TEXT(J38,"hh:mm"))&" "&E38&" "&D38) | C38: =IF(D38="","","2025-11-01予定のみ#10") | G38: =IF(D38="","","（実績なし）") | H38: =IF(C38="","",COUNTIF(実績!$A$6:$A$505,C38)) | Q38: =IF(C38="","",COUNTA(K38:P38)) | R38: =_xlfn.TEXTJOIN("・",TRUE(),K38:P38) | U38: =IF(C38="","",COUNTIF(変更・キャンセル!$B$26:$B$85,C38)) | V38: =IF(OR(C38="",U38=0),"",INDEX(変更・キャンセル!$AA$26:$AA$85,MATCH(C38&"#"&U38,変更・キャンセル!$Z$26:$Z$85,0))) | W38: =IF(C38="","",IF(COUNTIFS(変更・キャンセル!$B$26:$B$85,C38,変更・キャンセル!$R$26:$R$85,"○")>0,"○","")) | X38: =IF(D38="","",$C$6) | Y38: =IF(OR(C38="",J38=""),"",IF(J38<1,X38+J38,J38))
A39: =IF(D39="","","予定のみ") | B39: =IF(D39="","","11/01 予定のみ#11 "&IF(J39="","--:--",TEXT(J39,"hh:mm"))&" "&E39&" "&D39) | C39: =IF(D39="","","2025-11-01予定のみ#11") | G39: =IF(D39="","","（実績なし）") | H39: =IF(C39="","",COUNTIF(実績!$A$6:$A$505,C39)) | Q39: =IF(C39="","",COUNTA(K39:P39)) | R39: =_xlfn.TEXTJOIN("・",TRUE(),K39:P39) | U39: =IF(C39="","",COUNTIF(変更・キャンセル!$B$26:$B$85,C39)) | V39: =IF(OR(C39="",U39=0),"",INDEX(変更・キャンセル!$AA$26:$AA$85,MATCH(C39&"#"&U39,変更・キャンセル!$Z$26:$Z$85,0))) | W39: =IF(C39="","",IF(COUNTIFS(変更・キャンセル!$B$26:$B$85,C39,変更・キャンセル!$R$26:$R$85,"○")>0,"○","")) | X39: =IF(D39="","",$C$6) | Y39: =IF(OR(C39="",J39=""),"",IF(J39<1,X39+J39,J39))
A40: =IF(D40="","","予定のみ") | B40: =IF(D40="","","11/01 予定のみ#12 "&IF(J40="","--:--",TEXT(J40,"hh:mm"))&" "&E40&" "&D40) | C40: =IF(D40="","","2025-11-01予定のみ#12") | G40: =IF(D40="","","（実績なし）") | H40: =IF(C40="","",COUNTIF(実績!$A$6:$A$505,C40)) | Q40: =IF(C40="","",COUNTA(K40:P40)) | R40: =_xlfn.TEXTJOIN("・",TRUE(),K40:P40) | U40: =IF(C40="","",COUNTIF(変更・キャンセル!$B$26:$B$85,C40)) | V40: =IF(OR(C40="",U40=0),"",INDEX(変更・キャンセル!$AA$26:$AA$85,MATCH(C40&"#"&U40,変更・キャンセル!$Z$26:$Z$85,0))) | W40: =IF(C40="","",IF(COUNTIFS(変更・キャンセル!$B$26:$B$85,C40,変更・キャンセル!$R$26:$R$85,"○")>0,"○","")) | X40: =IF(D40="","",$C$6) | Y40: =IF(OR(C40="",J40=""),"",IF(J40<1,X40+J40,J40))
A41: =IF(D41="","","予定のみ") | B41: =IF(D41="","","11/01 予定のみ#13 "&IF(J41="","--:--",TEXT(J41,"hh:mm"))&" "&E41&" "&D41) | C41: =IF(D41="","","2025-11-01予定のみ#13") | G41: =IF(D41="","","（実績なし）") | H41: =IF(C41="","",COUNTIF(実績!$A$6:$A$505,C41)) | Q41: =IF(C41="","",COUNTA(K41:P41)) | R41: =_xlfn.TEXTJOIN("・",TRUE(),K41:P41) | U41: =IF(C41="","",COUNTIF(変更・キャンセル!$B$26:$B$85,C41)) | V41: =IF(OR(C41="",U41=0),"",INDEX(変更・キャンセル!$AA$26:$AA$85,MATCH(C41&"#"&U41,変更・キャンセル!$Z$26:$Z$85,0))) | W41: =IF(C41="","",IF(COUNTIFS(変更・キャンセル!$B$26:$B$85,C41,変更・キャンセル!$R$26:$R$85,"○")>0,"○","")) | X41: =IF(D41="","",$C$6) | Y41: =IF(OR(C41="",J41=""),"",IF(J41<1,X41+J41,J41))
A42: =IF(D42="","","予定のみ") | B42: =IF(D42="","","11/01 予定のみ#14 "&IF(J42="","--:--",TEXT(J42,"hh:mm"))&" "&E42&" "&D42) | C42: =IF(D42="","","2025-11-01予定のみ#14") | G42: =IF(D42="","","（実績なし）") | H42: =IF(C42="","",COUNTIF(実績!$A$6:$A$505,C42)) | Q42: =IF(C42="","",COUNTA(K42:P42)) | R42: =_xlfn.TEXTJOIN("・",TRUE(),K42:P42) | U42: =IF(C42="","",COUNTIF(変更・キャンセル!$B$26:$B$85,C42)) | V42: =IF(OR(C42="",U42=0),"",INDEX(変更・キャンセル!$AA$26:$AA$85,MATCH(C42&"#"&U42,変更・キャンセル!$Z$26:$Z$85,0))) | W42: =IF(C42="","",IF(COUNTIFS(変更・キャンセル!$B$26:$B$85,C42,変更・キャンセル!$R$26:$R$85,"○")>0,"○","")) | X42: =IF(D42="","",$C$6) | Y42: =IF(OR(C42="",J42=""),"",IF(J42<1,X42+J42,J42))
...

Sheet 変更・キャンセル
A1: 変更・キャンセル（全作業。1回の変更を1行。前日確定は上書きしない）
A2: 誰が：上田 何を見て：当日の変更連絡・変更分の予定表・配船記録 どこへ：①日ごとの確認（A7～）②休船からの呼出（A15～）③変更の記録（A26～で作業を選ぶ）。実績3隻未満の日・全船休航の日も①へ入力
A3: 集計先：「前日確定」の変更回数・最終日時・取消し、「集計」の変更・取消し・呼出。実績のない取消しは「前日確定」の下の空き行へ作業を追加してから選びます。
A5: ■ 日ごとの変更確認（変更なしと確認できた日と未確認の日を区別）
A6: 日付【入力】 | B6: その日の変更確認【入力・選択】 | C6: 全船休航【入力・○】 | D6: 実績の最大同時稼働（候補）【自動】 | E6: 情報元【入力】 | F6: 確認者【入力】
A7: 45962 | B7: 未確認 | D7: =IF(A7="","",IF(A7=集計!$C$5,集計!$C$14,"この試作では対象日のみ計算")) -> 3
D8: =IF(A8="","",IF(A8=集計!$C$5,集計!$C$14,"この試作では対象日のみ計算"))
D9: =IF(A9="","",IF(A9=集計!$C$5,集計!$C$14,"この試作では対象日のみ計算"))
D10: =IF(A10="","",IF(A10=集計!$C$5,集計!$C$14,"この試作では対象日のみ計算"))
D11: =IF(A11="","",IF(A11=集計!$C$5,集計!$C$14,"この試作では対象日のみ計算"))
A13: ■ 休船からの呼出（製鉄曳船・西日本海運。1隻ごとに1行。同じ船の同じ呼出は1回と数える）
A14: 呼出した船【入力・選択】 | B14: 会社【自動】 | C14: 呼出日時【入力】 | D14: 最初に対応した作業【入力・選択】 | E14: 呼出の理由【入力・選択】 | F14: 情報元【入力】 | G14: 確認状況【入力・選択】 | H14: 同一呼出の判定【自動】 | I14: 対象会社の判定【自動】 | J14: その日の従事作業数【自動】
B15: =IF(A15="","",IFERROR(IF(IFERROR(INDEX(マスター!$C$6:$C$125,MATCH(A15,マスター!$N$6:$N$125,0)),NA())="","未確認",IFERROR(INDEX(マスター!$C$6:$C$125,MATCH(A15,マスター!$N$6:$N$125,0)),NA())),"マスター未登録")) | H15: =IF(A15="","",IF(COUNTIFS(A$15:A15,A15,C$15:C15,C15)>1,"同一呼出（1回と数える）","")) | I15: =IF(A15="","",IF(OR(B15="製鉄曳船",B15="西日本海運"),"","製鉄曳船・西日本海運以外の船です")) | J15: =IF(A15="","",SUMPRODUCT((実績!$W$6:$W$505=IFERROR(INDEX(マスター!$K$6:$K$125,MATCH(A15,マスター!$N$6:$N$125,0)),A15))/COUNTIFS(実績!$A$6:$A$505,実績!$A$6:$A$505&"",実績!$W$6:$W$505,実績!$W$6:$W$505&"")))
B16: =IF(A16="","",IFERROR(IF(IFERROR(INDEX(マスター!$C$6:$C$125,MATCH(A16,マスター!$N$6:$N$125,0)),NA())="","未確認",IFERROR(INDEX(マスター!$C$6:$C$125,MATCH(A16,マスター!$N$6:$N$125,0)),NA())),"マスター未登録")) | H16: =IF(A16="","",IF(COUNTIFS(A$15:A16,A16,C$15:C16,C16)>1,"同一呼出（1回と数える）","")) | I16: =IF(A16="","",IF(OR(B16="製鉄曳船",B16="西日本海運"),"","製鉄曳船・西日本海運以外の船です")) | J16: =IF(A16="","",SUMPRODUCT((実績!$W$6:$W$505=IFERROR(INDEX(マスター!$K$6:$K$125,MATCH(A16,マスター!$N$6:$N$125,0)),A16))/COUNTIFS(実績!$A$6:$A$505,実績!$A$6:$A$505&"",実績!$W$6:$W$505,実績!$W$6:$W$505&"")))
B17: =IF(A17="","",IFERROR(IF(IFERROR(INDEX(マスター!$C$6:$C$125,MATCH(A17,マスター!$N$6:$N$125,0)),NA())="","未確認",IFERROR(INDEX(マスター!$C$6:$C$125,MATCH(A17,マスター!$N$6:$N$125,0)),NA())),"マスター未登録")) | H17: =IF(A17="","",IF(COUNTIFS(A$15:A17,A17,C$15:C17,C17)>1,"同一呼出（1回と数える）","")) | I17: =IF(A17="","",IF(OR(B17="製鉄曳船",B17="西日本海運"),"","製鉄曳船・西日本海運以外の船です")) | J17: =IF(A17="","",SUMPRODUCT((実績!$W$6:$W$505=IFERROR(INDEX(マスター!$K$6:$K$125,MATCH(A17,マスター!$N$6:$N$125,0)),A17))/COUNTIFS(実績!$A$6:$A$505,実績!$A$6:$A$505&"",実績!$W$6:$W$505,実績!$W$6:$W$505&"")))
B18: =IF(A18="","",IFERROR(IF(IFERROR(INDEX(マスター!$C$6:$C$125,MATCH(A18,マスター!$N$6:$N$125,0)),NA())="","未確認",IFERROR(INDEX(マスター!$C$6:$C$125,MATCH(A18,マスター!$N$6:$N$125,0)),NA())),"マスター未登録")) | H18: =IF(A18="","",IF(COUNTIFS(A$15:A18,A18,C$15:C18,C18)>1,"同一呼出（1回と数える）","")) | I18: =IF(A18="","",IF(OR(B18="製鉄曳船",B18="西日本海運"),"","製鉄曳船・西日本海運以外の船です")) | J18: =IF(A18="","",SUMPRODUCT((実績!$W$6:$W$505=IFERROR(INDEX(マスター!$K$6:$K$125,MATCH(A18,マスター!$N$6:$N$125,0)),A18))/COUNTIFS(実績!$A$6:$A$505,実績!$A$6:$A$505&"",実績!$W$6:$W$505,実績!$W$6:$W$505&"")))
B19: =IF(A19="","",IFERROR(IF(IFERROR(INDEX(マスター!$C$6:$C$125,MATCH(A19,マスター!$N$6:$N$125,0)),NA())="","未確認",IFERROR(INDEX(マスター!$C$6:$C$125,MATCH(A19,マスター!$N$6:$N$125,0)),NA())),"マスター未登録")) | H19: =IF(A19="","",IF(COUNTIFS(A$15:A19,A19,C$15:C19,C19)>1,"同一呼出（1回と数える）","")) | I19: =IF(A19="","",IF(OR(B19="製鉄曳船",B19="西日本海運"),"","製鉄曳船・西日本海運以外の船です")) | J19: =IF(A19="","",SUMPRODUCT((実績!$W$6:$W$505=IFERROR(INDEX(マスター!$K$6:$K$125,MATCH(A19,マスター!$N$6:$N$125,0)),A19))/COUNTIFS(実績!$A$6:$A$505,実績!$A$6:$A$505&"",実績!$W$6:$W$505,実績!$W$6:$W$505&"")))
B20: =IF(A20="","",IFERROR(IF(IFERROR(INDEX(マスター!$C$6:$C$125,MATCH(A20,マスター!$N$6:$N$125,0)),NA())="","未確認",IFERROR(INDEX(マスター!$C$6:$C$125,MATCH(A20,マスター!$N$6:$N$125,0)),NA())),"マスター未登録")) | H20: =IF(A20="","",IF(COUNTIFS(A$15:A20,A20,C$15:C20,C20)>1,"同一呼出（1回と数える）","")) | I20: =IF(A20="","",IF(OR(B20="製鉄曳船",B20="西日本海運"),"","製鉄曳船・西日本海運以外の船です")) | J20: =IF(A20="","",SUMPRODUCT((実績!$W$6:$W$505=IFERROR(INDEX(マスター!$K$6:$K$125,MATCH(A20,マスター!$N$6:$N$125,0)),A20))/COUNTIFS(実績!$A$6:$A$505,実績!$A$6:$A$505&"",実績!$W$6:$W$505,実績!$W$6:$W$505&"")))
B21: =IF(A21="","",IFERROR(IF(IFERROR(INDEX(マスター!$C$6:$C$125,MATCH(A21,マスター!$N$6:$N$125,0)),NA())="","未確認",IFERROR(INDEX(マスター!$C$6:$C$125,MATCH(A21,マスター!$N$6:$N$125,0)),NA())),"マスター未登録")) | H21: =IF(A21="","",IF(COUNTIFS(A$15:A21,A21,C$15:C21,C21)>1,"同一呼出（1回と数える）","")) | I21: =IF(A21="","",IF(OR(B21="製鉄曳船",B21="西日本海運"),"","製鉄曳船・西日本海運以外の船です")) | J21: =IF(A21="","",SUMPRODUCT((実績!$W$6:$W$505=IFERROR(INDEX(マスター!$K$6:$K$125,MATCH(A21,マスター!$N$6:$N$125,0)),A21))/COUNTIFS(実績!$A$6:$A$505,実績!$A$6:$A$505&"",実績!$W$6:$W$505,実績!$W$6:$W$505&"")))
B22: =IF(A22="","",IFERROR(IF(IFERROR(INDEX(マスター!$C$6:$C$125,MATCH(A22,マスター!$N$6:$N$125,0)),NA())="","未確認",IFERROR(INDEX(マスター!$C$6:$C$125,MATCH(A22,マスター!$N$6:$N$125,0)),NA())),"マスター未登録")) | H22: =IF(A22="","",IF(COUNTIFS(A$15:A22,A22,C$15:C22,C22)>1,"同一呼出（1回と数える）","")) | I22: =IF(A22="","",IF(OR(B22="製鉄曳船",B22="西日本海運"),"","製鉄曳船・西日本海運以外の船です")) | J22: =IF(A22="","",SUMPRODUCT((実績!$W$6:$W$505=IFERROR(INDEX(マスター!$K$6:$K$125,MATCH(A22,マスター!$N$6:$N$125,0)),A22))/COUNTIFS(実績!$A$6:$A$505,実績!$A$6:$A$505&"",実績!$W$6:$W$505,実績!$W$6:$W$505&"")))
A24: ■ 変更・キャンセルの記録（作業を選ぶと本船名・前日確定・変更前が自動表示。2回目以降の変更も同じ作業を選んで行を追加）
A25: 作業の選択【入力・選択】 | B25: 作業キー【自動】 | C25: 本船名【自動】 | D25: 何回目の変更【自動】 | E25: 前日確定の日時【自動】 | F25: 前日確定のタグ【自動】 | G25: 連絡日時【入力】 | H25: 連絡元【入力】 | I25: 変更前の日時【自動】 | J25: 変更後の時刻【入力】（翌日は日付も） | K25: 変更前のタグ【自動】 | L25: 変更後のタグ①【入力・選択】 | M25: 変更後のタグ②【入力・選択】 | N25: 変更後のタグ③【入力・選択】 | O25: 変更後のタグ④【入力・選択】 | P25: 変更後のタグ⑤【入力・選択】 | Q25: 変更後のタグ⑥【入力・選択】 | R25: 取消し【入力・○】 | S25: 取消しの時点【入力・選択】 | T25: 理由【入力・選択】 | U25: 理由の詳細【入力】 | V25: 時間調整【入力・選択】 | W25: 時間調整の内容【入力】 | X25: 情報元【入力】 | Y25: 確認者【入力】 | Z25: 照合キー【自動】 | AA25: 変更後の日時（有効）【自動】 | AB25: 変更後のタグ（有効）【自動】 | AC25: 前回の照合キー【自動】 | AD25: 作業日【自動】
B26: =IF(A26="","",IFERROR(INDEX(前日確定!$C$26:$C$45,MATCH(A26,前日確定!$B$26:$B$45,0)),"作業が見つかりません")) | C26: =IF(A26="","",IFERROR(INDEX(前日確定!$D$26:$D$45,MATCH(A26,前日確定!$B$26:$B$45,0)),"")) | D26: =IF(B26="","",COUNTIF(B$26:B26,B26)) | E26: =IF(A26="","",IFERROR(IF(INDEX(前日確定!$Y$26:$Y$45,MATCH(A26,前日確定!$B$26:$B$45,0))="","",INDEX(前日確定!$Y$26:$Y$45,MATCH(A26,前日確定!$B$26:$B$45,0))),"")) | F26: =IF(A26="","",IFERROR(INDEX(前日確定!$R$26:$R$45,MATCH(A26,前日確定!$B$26:$B$45,0)),"")) | I26: =IF(A26="","",E26) | K26: =IF(A26="","",F26) | Z26: =IF(B26="","",B26&"#"&D26) | AA26: =IF(A26="","",IF(J26="",I26,IF(J26<1,AD26+J26,J26))) | AB26: =IF(A26="","",IF(COUNTA(L26:Q26)=0,K26,_xlfn.TEXTJOIN("・",TRUE(),L26:Q26))) | AC26: =IF(B26="","",B26&"#"&(D26-1)) | AD26: =IF(A26="","",IFERROR(INDEX(前日確定!$X$26:$X$45,MATCH(A26,前日確定!$B$26:$B$45,0)),""))
B27: =IF(A27="","",IFERROR(INDEX(前日確定!$C$26:$C$45,MATCH(A27,前日確定!$B$26:$B$45,0)),"作業が見つかりません")) | C27: =IF(A27="","",IFERROR(INDEX(前日確定!$D$26:$D$45,MATCH(A27,前日確定!$B$26:$B$45,0)),"")) | D27: =IF(B27="","",COUNTIF(B$26:B27,B27)) | E27: =IF(A27="","",IFERROR(IF(INDEX(前日確定!$Y$26:$Y$45,MATCH(A27,前日確定!$B$26:$B$45,0))="","",INDEX(前日確定!$Y$26:$Y$45,MATCH(A27,前日確定!$B$26:$B$45,0))),"")) | F27: =IF(A27="","",IFERROR(INDEX(前日確定!$R$26:$R$45,MATCH(A27,前日確定!$B$26:$B$45,0)),"")) | I27: =IF(A27="","",IF(D27=1,E27,IFERROR(INDEX($AA$26:$AA$26,MATCH(AC27,$Z$26:$Z$26,0)),""))) | K27: =IF(A27="","",IF(D27=1,F27,IFERROR(INDEX($AB$26:$AB$26,MATCH(AC27,$Z$26:$Z$26,0)),""))) | Z27: =IF(B27="","",B27&"#"&D27) | AA27: =IF(A27="","",IF(J27="",I27,IF(J27<1,AD27+J27,J27))) | AB27: =IF(A27="","",IF(COUNTA(L27:Q27)=0,K27,_xlfn.TEXTJOIN("・",TRUE(),L27:Q27))) | AC27: =IF(B27="","",B27&"#"&(D27-1)) | AD27: =IF(A27="","",IFERROR(INDEX(前日確定!$X$26:$X$45,MATCH(A27,前日確定!$B$26:$B$45,0)),""))
B28: =IF(A28="","",IFERROR(INDEX(前日確定!$C$26:$C$45,MATCH(A28,前日確定!$B$26:$B$45,0)),"作業が見つかりません")) | C28: =IF(A28="","",IFERROR(INDEX(前日確定!$D$26:$D$45,MATCH(A28,前日確定!$B$26:$B$45,0)),"")) | D28: =IF(B28="","",COUNTIF(B$26:B28,B28)) | E28: =IF(A28="","",IFERROR(IF(INDEX(前日確定!$Y$26:$Y$45,MATCH(A28,前日確定!$B$26:$B$45,0))="","",INDEX(前日確定!$Y$26:$Y$45,MATCH(A28,前日確定!$B$26:$B$45,0))),"")) | F28: =IF(A28="","",IFERROR(INDEX(前日確定!$R$26:$R$45,MATCH(A28,前日確定!$B$26:$B$45,0)),"")) | I28: =IF(A28="","",IF(D28=1,E28,IFERROR(INDEX($AA$26:$AA$27,MATCH(AC28,$Z$26:$Z$27,0)),""))) | K28: =IF(A28="","",IF(D28=1,F28,IFERROR(INDEX($AB$26:$AB$27,MATCH(AC28,$Z$26:$Z$27,0)),""))) | Z28: =IF(B28="","",B28&"#"&D28) | AA28: =IF(A28="","",IF(J28="",I28,IF(J28<1,AD28+J28,J28))) | AB28: =IF(A28="","",IF(COUNTA(L28:Q28)=0,K28,_xlfn.TEXTJOIN("・",TRUE(),L28:Q28))) | AC28: =IF(B28="","",B28&"#"&(D28-1)) | AD28: =IF(A28="","",IFERROR(INDEX(前日確定!$X$26:$X$45,MATCH(A28,前日確定!$B$26:$B$45,0)),""))
B29: =IF(A29="","",IFERROR(INDEX(前日確定!$C$26:$C$45,MATCH(A29,前日確定!$B$26:$B$45,0)),"作業が見つかりません")) | C29: =IF(A29="","",IFERROR(INDEX(前日確定!$D$26:$D$45,MATCH(A29,前日確定!$B$26:$B$45,0)),"")) | D29: =IF(B29="","",COUNTIF(B$26:B29,B29)) | E29: =IF(A29="","",IFERROR(IF(INDEX(前日確定!$Y$26:$Y$45,MATCH(A29,前日確定!$B$26:$B$45,0))="","",INDEX(前日確定!$Y$26:$Y$45,MATCH(A29,前日確定!$B$26:$B$45,0))),"")) | F29: =IF(A29="","",IFERROR(INDEX(前日確定!$R$26:$R$45,MATCH(A29,前日確定!$B$26:$B$45,0)),"")) | I29: =IF(A29="","",IF(D29=1,E29,IFERROR(INDEX($AA$26:$AA$28,MATCH(AC29,$Z$26:$Z$28,0)),""))) | K29: =IF(A29="","",IF(D29=1,F29,IFERROR(INDEX($AB$26:$AB$28,MATCH(AC29,$Z$26:$Z$28,0)),""))) | Z29: =IF(B29="","",B29&"#"&D29) | AA29: =IF(A29="","",IF(J29="",I29,IF(J29<1,AD29+J29,J29))) | AB29: =IF(A29="","",IF(COUNTA(L29:Q29)=0,K29,_xlfn.TEXTJOIN("・",TRUE(),L29:Q29))) | AC29: =IF(B29="","",B29&"#"&(D29-1)) | AD29: =IF(A29="","",IFERROR(INDEX(前日確定!$X$26:$X$45,MATCH(A29,前日確定!$B$26:$B$45,0)),""))
B30: =IF(A30="","",IFERROR(INDEX(前日確定!$C$26:$C$45,MATCH(A30,前日確定!$B$26:$B$45,0)),"作業が見つかりません")) | C30: =IF(A30="","",IFERROR(INDEX(前日確定!$D$26:$D$45,MATCH(A30,前日確定!$B$26:$B$45,0)),"")) | D30: =IF(B30="","",COUNTIF(B$26:B30,B30)) | E30: =IF(A30="","",IFERROR(IF(INDEX(前日確定!$Y$26:$Y$45,MATCH(A30,前日確定!$B$26:$B$45,0))="","",INDEX(前日確定!$Y$26:$Y$45,MATCH(A30,前日確定!$B$26:$B$45,0))),"")) | F30: =IF(A30="","",IFERROR(INDEX(前日確定!$R$26:$R$45,MATCH(A30,前日確定!$B$26:$B$45,0)),"")) | I30: =IF(A30="","",IF(D30=1,E30,IFERROR(INDEX($AA$26:$AA$29,MATCH(AC30,$Z$26:$Z$29,0)),""))) | K30: =IF(A30="","",IF(D30=1,F30,IFERROR(INDEX($AB$26:$AB$29,MATCH(AC30,$Z$26:$Z$29,0)),""))) | Z30: =IF(B30="","",B30&"#"&D30) | AA30: =IF(A30="","",IF(J30="",I30,IF(J30<1,AD30+J30,J30))) | AB30: =IF(A30="","",IF(COUNTA(L30:Q30)=0,K30,_xlfn.TEXTJOIN("・",TRUE(),L30:Q30))) | AC30: =IF(B30="","",B30&"#"&(D30-1)) | AD30: =IF(A30="","",IFERROR(INDEX(前日確定!$X$26:$X$45,MATCH(A30,前日確定!$B$26:$B$45,0)),""))
B31: =IF(A31="","",IFERROR(INDEX(前日確定!$C$26:$C$45,MATCH(A31,前日確定!$B$26:$B$45,0)),"作業が見つかりません")) | C31: =IF(A31="","",IFERROR(INDEX(前日確定!$D$26:$D$45,MATCH(A31,前日確定!$B$26:$B$45,0)),"")) | D31: =IF(B31="","",COUNTIF(B$26:B31,B31)) | E31: =IF(A31="","",IFERROR(IF(INDEX(前日確定!$Y$26:$Y$45,MATCH(A31,前日確定!$B$26:$B$45,0))="","",INDEX(前日確定!$Y$26:$Y$45,MATCH(A31,前日確定!$B$26:$B$45,0))),"")) | F31: =IF(A31="","",IFERROR(INDEX(前日確定!$R$26:$R$45,MATCH(A31,前日確定!$B$26:$B$45,0)),"")) | I31: =IF(A31="","",IF(D31=1,E31,IFERROR(INDEX($AA$26:$AA$30,MATCH(AC31,$Z$26:$Z$30,0)),""))) | K31: =IF(A31="","",IF(D31=1,F31,IFERROR(INDEX($AB$26:$AB$30,MATCH(AC31,$Z$26:$Z$30,0)),""))) | Z31: =IF(B31="","",B31&"#"&D31) | AA31: =IF(A31="","",IF(J31="",I31,IF(J31<1,AD31+J31,J31))) | AB31: =IF(A31="","",IF(COUNTA(L31:Q31)=0,K31,_xlfn.TEXTJOIN("・",TRUE(),L31:Q31))) | AC31: =IF(B31="","",B31&"#"&(D31-1)) | AD31: =IF(A31="","",IFERROR(INDEX(前日確定!$X$26:$X$45,MATCH(A31,前日確定!$B$26:$B$45,0)),""))
B32: =IF(A32="","",IFERROR(INDEX(前日確定!$C$26:$C$45,MATCH(A32,前日確定!$B$26:$B$45,0)),"作業が見つかりません")) | C32: =IF(A32="","",IFERROR(INDEX(前日確定!$D$26:$D$45,MATCH(A32,前日確定!$B$26:$B$45,0)),"")) | D32: =IF(B32="","",COUNTIF(B$26:B32,B32)) | E32: =IF(A32="","",IFERROR(IF(INDEX(前日確定!$Y$26:$Y$45,MATCH(A32,前日確定!$B$26:$B$45,0))="","",INDEX(前日確定!$Y$26:$Y$45,MATCH(A32,前日確定!$B$26:$B$45,0))),"")) | F32: =IF(A32="","",IFERROR(INDEX(前日確定!$R$26:$R$45,MATCH(A32,前日確定!$B$26:$B$45,0)),"")) | I32: =IF(A32="","",IF(D32=1,E32,IFERROR(INDEX($AA$26:$AA$31,MATCH(AC32,$Z$26:$Z$31,0)),""))) | K32: =IF(A32="","",IF(D32=1,F32,IFERROR(INDEX($AB$26:$AB$31,MATCH(AC32,$Z$26:$Z$31,0)),""))) | Z32: =IF(B32="","",B32&"#"&D32) | AA32: =IF(A32="","",IF(J32="",I32,IF(J32<1,AD32+J32,J32))) | AB32: =IF(A32="","",IF(COUNTA(L32:Q32)=0,K32,_xlfn.TEXTJOIN("・",TRUE(),L32:Q32))) | AC32: =IF(B32="","",B32&"#"&(D32-1)) | AD32: =IF(A32="","",IFERROR(INDEX(前日確定!$X$26:$X$45,MATCH(A32,前日確定!$B$26:$B$45,0)),""))
B33: =IF(A33="","",IFERROR(INDEX(前日確定!$C$26:$C$45,MATCH(A33,前日確定!$B$26:$B$45,0)),"作業が見つかりません")) | C33: =IF(A33="","",IFERROR(INDEX(前日確定!$D$26:$D$45,MATCH(A33,前日確定!$B$26:$B$45,0)),"")) | D33: =IF(B33="","",COUNTIF(B$26:B33,B33)) | E33: =IF(A33="","",IFERROR(IF(INDEX(前日確定!$Y$26:$Y$45,MATCH(A33,前日確定!$B$26:$B$45,0))="","",INDEX(前日確定!$Y$26:$Y$45,MATCH(A33,前日確定!$B$26:$B$45,0))),"")) | F33: =IF(A33="","",IFERROR(INDEX(前日確定!$R$26:$R$45,MATCH(A33,前日確定!$B$26:$B$45,0)),"")) | I33: =IF(A33="","",IF(D33=1,E33,IFERROR(INDEX($AA$26:$AA$32,MATCH(AC33,$Z$26:$Z$32,0)),""))) | K33: =IF(A33="","",IF(D33=1,F33,IFERROR(INDEX($AB$26:$AB$32,MATCH(AC33,$Z$26:$Z$32,0)),""))) | Z33: =IF(B33="","",B33&"#"&D33) | AA33: =IF(A33="","",IF(J33="",I33,IF(J33<1,AD33+J33,J33))) | AB33: =IF(A33="","",IF(COUNTA(L33:Q33)=0,K33,_xlfn.TEXTJOIN("・",TRUE(),L33:Q33))) | AC33: =IF(B33="","",B33&"#"&(D33-1)) | AD33: =IF(A33="","",IFERROR(INDEX(前日確定!$X$26:$X$45,MATCH(A33,前日確定!$B$26:$B$45,0)),""))
B34: =IF(A34="","",IFERROR(INDEX(前日確定!$C$26:$C$45,MATCH(A34,前日確定!$B$26:$B$45,0)),"作業が見つかりません")) | C34: =IF(A34="","",IFERROR(INDEX(前日確定!$D$26:$D$45,MATCH(A34,前日確定!$B$26:$B$45,0)),"")) | D34: =IF(B34="","",COUNTIF(B$26:B34,B34)) | E34: =IF(A34="","",IFERROR(IF(INDEX(前日確定!$Y$26:$Y$45,MATCH(A34,前日確定!$B$26:$B$45,0))="","",INDEX(前日確定!$Y$26:$Y$45,MATCH(A34,前日確定!$B$26:$B$45,0))),"")) | F34: =IF(A34="","",IFERROR(INDEX(前日確定!$R$26:$R$45,MATCH(A34,前日確定!$B$26:$B$45,0)),"")) | I34: =IF(A34="","",IF(D34=1,E34,IFERROR(INDEX($AA$26:$AA$33,MATCH(AC34,$Z$26:$Z$33,0)),""))) | K34: =IF(A34="","",IF(D34=1,F34,IFERROR(INDEX($AB$26:$AB$33,MATCH(AC34,$Z$26:$Z$33,0)),""))) | Z34: =IF(B34="","",B34&"#"&D34) | AA34: =IF(A34="","",IF(J34="",I34,IF(J34<1,AD34+J34,J34))) | AB34: =IF(A34="","",IF(COUNTA(L34:Q34)=0,K34,_xlfn.TEXTJOIN("・",TRUE(),L34:Q34))) | AC34: =IF(B34="","",B34&"#"&(D34-1)) | AD34: =IF(A34="","",IFERROR(INDEX(前日確定!$X$26:$X$45,MATCH(A34,前日確定!$B$26:$B$45,0)),""))
B35: =IF(A35="","",IFERROR(INDEX(前日確定!$C$26:$C$45,MATCH(A35,前日確定!$B$26:$B$45,0)),"作業が見つかりません")) | C35: =IF(A35="","",IFERROR(INDEX(前日確定!$D$26:$D$45,MATCH(A35,前日確定!$B$26:$B$45,0)),"")) | D35: =IF(B35="","",COUNTIF(B$26:B35,B35)) | E35: =IF(A35="","",IFERROR(IF(INDEX(前日確定!$Y$26:$Y$45,MATCH(A35,前日確定!$B$26:$B$45,0))="","",INDEX(前日確定!$Y$26:$Y$45,MATCH(A35,前日確定!$B$26:$B$45,0))),"")) | F35: =IF(A35="","",IFERROR(INDEX(前日確定!$R$26:$R$45,MATCH(A35,前日確定!$B$26:$B$45,0)),"")) | I35: =IF(A35="","",IF(D35=1,E35,IFERROR(INDEX($AA$26:$AA$34,MATCH(AC35,$Z$26:$Z$34,0)),""))) | K35: =IF(A35="","",IF(D35=1,F35,IFERROR(INDEX($AB$26:$AB$34,MATCH(AC35,$Z$26:$Z$34,0)),""))) | Z35: =IF(B35="","",B35&"#"&D35) | AA35: =IF(A35="","",IF(J35="",I35,IF(J35<1,AD35+J35,J35))) | AB35: =IF(A35="","",IF(COUNTA(L35:Q35)=0,K35,_xlfn.TEXTJOIN("・",TRUE(),L35:Q35))) | AC35: =IF(B35="","",B35&"#"&(D35-1)) | AD35: =IF(A35="","",IFERROR(INDEX(前日確定!$X$26:$X$45,MATCH(A35,前日確定!$B$26:$B$45,0)),""))
B36: =IF(A36="","",IFERROR(INDEX(前日確定!$C$26:$C$45,MATCH(A36,前日確定!$B$26:$B$45,0)),"作業が見つかりません")) | C36: =IF(A36="","",IFERROR(INDEX(前日確定!$D$26:$D$45,MATCH(A36,前日確定!$B$26:$B$45,0)),"")) | D36: =IF(B36="","",COUNTIF(B$26:B36,B36)) | E36: =IF(A36="","",IFERROR(IF(INDEX(前日確定!$Y$26:$Y$45,MATCH(A36,前日確定!$B$26:$B$45,0))="","",INDEX(前日確定!$Y$26:$Y$45,MATCH(A36,前日確定!$B$26:$B$45,0))),"")) | F36: =IF(A36="","",IFERROR(INDEX(前日確定!$R$26:$R$45,MATCH(A36,前日確定!$B$26:$B$45,0)),"")) | I36: =IF(A36="","",IF(D36=1,E36,IFERROR(INDEX($AA$26:$AA$35,MATCH(AC36,$Z$26:$Z$35,0)),""))) | K36: =IF(A36="","",IF(D36=1,F36,IFERROR(INDEX($AB$26:$AB$35,MATCH(AC36,$Z$26:$Z$35,0)),""))) | Z36: =IF(B36="","",B36&"#"&D36) | AA36: =IF(A36="","",IF(J36="",I36,IF(J36<1,AD36+J36,J36))) | AB36: =IF(A36="","",IF(COUNTA(L36:Q36)=0,K36,_xlfn.TEXTJOIN("・",TRUE(),L36:Q36))) | AC36: =IF(B36="","",B36&"#"&(D36-1)) | AD36: =IF(A36="","",IFERROR(INDEX(前日確定!$X$26:$X$45,MATCH(A36,前日確定!$B$26:$B$45,0)),""))
B37: =IF(A37="","",IFERROR(INDEX(前日確定!$C$26:$C$45,MATCH(A37,前日確定!$B$26:$B$45,0)),"作業が見つかりません")) | C37: =IF(A37="","",IFERROR(INDEX(前日確定!$D$26:$D$45,MATCH(A37,前日確定!$B$26:$B$45,0)),"")) | D37: =IF(B37="","",COUNTIF(B$26:B37,B37)) | E37: =IF(A37="","",IFERROR(IF(INDEX(前日確定!$Y$26:$Y$45,MATCH(A37,前日確定!$B$26:$B$45,0))="","",INDEX(前日確定!$Y$26:$Y$45,MATCH(A37,前日確定!$B$26:$B$45,0))),"")) | F37: =IF(A37="","",IFERROR(INDEX(前日確定!$R$26:$R$45,MATCH(A37,前日確定!$B$26:$B$45,0)),"")) | I37: =IF(A37="","",IF(D37=1,E37,IFERROR(INDEX($AA$26:$AA$36,MATCH(AC37,$Z$26:$Z$36,0)),""))) | K37: =IF(A37="","",IF(D37=1,F37,IFERROR(INDEX($AB$26:$AB$36,MATCH(AC37,$Z$26:$Z$36,0)),""))) | Z37: =IF(B37="","",B37&"#"&D37) | AA37: =IF(A37="","",IF(J37="",I37,IF(J37<1,AD37+J37,J37))) | AB37: =IF(A37="","",IF(COUNTA(L37:Q37)=0,K37,_xlfn.TEXTJOIN("・",TRUE(),L37:Q37))) | AC37: =IF(B37="","",B37&"#"&(D37-1)) | AD37: =IF(A37="","",IFERROR(INDEX(前日確定!$X$26:$X$45,MATCH(A37,前日確定!$B$26:$B$45,0)),""))
B38: =IF(A38="","",IFERROR(INDEX(前日確定!$C$26:$C$45,MATCH(A38,前日確定!$B$26:$B$45,0)),"作業が見つかりません")) | C38: =IF(A38="","",IFERROR(INDEX(前日確定!$D$26:$D$45,MATCH(A38,前日確定!$B$26:$B$45,0)),"")) | D38: =IF(B38="","",COUNTIF(B$26:B38,B38)) | E38: =IF(A38="","",IFERROR(IF(INDEX(前日確定!$Y$26:$Y$45,MATCH(A38,前日確定!$B$26:$B$45,0))="","",INDEX(前日確定!$Y$26:$Y$45,MATCH(A38,前日確定!$B$26:$B$45,0))),"")) | F38: =IF(A38="","",IFERROR(INDEX(前日確定!$R$26:$R$45,MATCH(A38,前日確定!$B$26:$B$45,0)),"")) | I38: =IF(A38="","",IF(D38=1,E38,IFERROR(INDEX($AA$26:$AA$37,MATCH(AC38,$Z$26:$Z$37,0)),""))) | K38: =IF(A38="","",IF(D38=1,F38,IFERROR(INDEX($AB$26:$AB$37,MATCH(AC38,$Z$26:$Z$37,0)),""))) | Z38: =IF(B38="","",B38&"#"&D38) | AA38: =IF(A38="","",IF(J38="",I38,IF(J38<1,AD38+J38,J38))) | AB38: =IF(A38="","",IF(COUNTA(L38:Q38)=0,K38,_xlfn.TEXTJOIN("・",TRUE(),L38:Q38))) | AC38: =IF(B38="","",B38&"#"&(D38-1)) | AD38: =IF(A38="","",IFERROR(INDEX(前日確定!$X$26:$X$45,MATCH(A38,前日確定!$B$26:$B$45,0)),""))
B39: =IF(A39="","",IFERROR(INDEX(前日確定!$C$26:$C$45,MATCH(A39,前日確定!$B$26:$B$45,0)),"作業が見つかりません")) | C39: =IF(A39="","",IFERROR(INDEX(前日確定!$D$26:$D$45,MATCH(A39,前日確定!$B$26:$B$45,0)),"")) | D39: =IF(B39="","",COUNTIF(B$26:B39,B39)) | E39: =IF(A39="","",IFERROR(IF(INDEX(前日確定!$Y$26:$Y$45,MATCH(A39,前日確定!$B$26:$B$45,0))="","",INDEX(前日確定!$Y$26:$Y$45,MATCH(A39,前日確定!$B$26:$B$45,0))),"")) | F39: =IF(A39="","",IFERROR(INDEX(前日確定!$R$26:$R$45,MATCH(A39,前日確定!$B$26:$B$45,0)),"")) | I39: =IF(A39="","",IF(D39=1,E39,IFERROR(INDEX($AA$26:$AA$38,MATCH(AC39,$Z$26:$Z$38,0)),""))) | K39: =IF(A39="","",IF(D39=1,F39,IFERROR(INDEX($AB$26:$AB$38,MATCH(AC39,$Z$26:$Z$38,0)),""))) | Z39: =IF(B39="","",B39&"#"&D39) | AA39: =IF(A39="","",IF(J39="",I39,IF(J39<1,AD39+J39,J39))) | AB39: =IF(A39="","",IF(COUNTA(L39:Q39)=0,K39,_xlfn.TEXTJOIN("・",TRUE(),L39:Q39))) | AC39: =IF(B39="","",B39&"#"&(D39-1)) | AD39: =IF(A39="","",IFERROR(INDEX(前日確定!$X$26:$X$45,MATCH(A39,前日確定!$B$26:$B$45,0)),""))
B40: =IF(A40="","",IFERROR(INDEX(前日確定!$C$26:$C$45,MATCH(A40,前日確定!$B$26:$B$45,0)),"作業が見つかりません")) | C40: =IF(A40="","",IFERROR(INDEX(前日確定!$D$26:$D$45,MATCH(A40,前日確定!$B$26:$B$45,0)),"")) | D40: =IF(B40="","",COUNTIF(B$26:B40,B40)) | E40: =IF(A40="","",IFERROR(IF(INDEX(前日確定!$Y$26:$Y$45,MATCH(A40,前日確定!$B$26:$B$45,0))="","",INDEX(前日確定!$Y$26:$Y$45,MATCH(A40,前日確定!$B$26:$B$45,0))),"")) | F40: =IF(A40="","",IFERROR(INDEX(前日確定!$R$26:$R$45,MATCH(A40,前日確定!$B$26:$B$45,0)),"")) | I40: =IF(A40="","",IF(D40=1,E40,IFERROR(INDEX($AA$26:$AA$39,MATCH(AC40,$Z$26:$Z$39,0)),""))) | K40: =IF(A40="","",IF(D40=1,F40,IFERROR(INDEX($AB$26:$AB$39,MATCH(AC40,$Z$26:$Z$39,0)),""))) | Z40: =IF(B40="","",B40&"#"&D40) | AA40: =IF(A40="","",IF(J40="",I40,IF(J40<1,AD40+J40,J40))) | AB40: =IF(A40="","",IF(COUNTA(L40:Q40)=0,K40,_xlfn.TEXTJOIN("・",TRUE(),L40:Q40))) | AC40: =IF(B40="","",B40&"#"&(D40-1)) | AD40: =IF(A40="","",IFERROR(INDEX(前日確定!$X$26:$X$45,MATCH(A40,前日確定!$B$26:$B$45,0)),""))
B41: =IF(A41="","",IFERROR(INDEX(前日確定!$C$26:$C$45,MATCH(A41,前日確定!$B$26:$B$45,0)),"作業が見つかりません")) | C41: =IF(A41="","",IFERROR(INDEX(前日確定!$D$26:$D$45,MATCH(A41,前日確定!$B$26:$B$45,0)),"")) | D41: =IF(B41="","",COUNTIF(B$26:B41,B41)) | E41: =IF(A41="","",IFERROR(IF(INDEX(前日確定!$Y$26:$Y$45,MATCH(A41,前日確定!$B$26:$B$45,0))="","",INDEX(前日確定!$Y$26:$Y$45,MATCH(A41,前日確定!$B$26:$B$45,0))),"")) | F41: =IF(A41="","",IFERROR(INDEX(前日確定!$R$26:$R$45,MATCH(A41,前日確定!$B$26:$B$45,0)),"")) | I41: =IF(A41="","",IF(D41=1,E41,IFERROR(INDEX($AA$26:$AA$40,MATCH(AC41,$Z$26:$Z$40,0)),""))) | K41: =IF(A41="","",IF(D41=1,F41,IFERROR(INDEX($AB$26:$AB$40,MATCH(AC41,$Z$26:$Z$40,0)),""))) | Z41: =IF(B41="","",B41&"#"&D41) | AA41: =IF(A41="","",IF(J41="",I41,IF(J41<1,AD41+J41,J41))) | AB41: =IF(A41="","",IF(COUNTA(L41:Q41)=0,K41,_xlfn.TEXTJOIN("・",TRUE(),L41:Q41))) | AC41: =IF(B41="","",B41&"#"&(D41-1)) | AD41: =IF(A41="","",IFERROR(INDEX(前日確定!$X$26:$X$45,MATCH(A41,前日確定!$B$26:$B$45,0)),""))
B42: =IF(A42="","",IFERROR(INDEX(前日確定!$C$26:$C$45,MATCH(A42,前日確定!$B$26:$B$45,0)),"作業が見つかりません")) | C42: =IF(A42="","",IFERROR(INDEX(前日確定!$D$26:$D$45,MATCH(A42,前日確定!$B$26:$B$45,0)),"")) | D42: =IF(B42="","",COUNTIF(B$26:B42,B42)) | E42: =IF(A42="","",IFERROR(IF(INDEX(前日確定!$Y$26:$Y$45,MATCH(A42,前日確定!$B$26:$B$45,0))="","",INDEX(前日確定!$Y$26:$Y$45,MATCH(A42,前日確定!$B$26:$B$45,0))),"")) | F42: =IF(A42="","",IFERROR(INDEX(前日確定!$R$26:$R$45,MATCH(A42,前日確定!$B$26:$B$45,0)),"")) | I42: =IF(A42="","",IF(D42=1,E42,IFERROR(INDEX($AA$26:$AA$41,MATCH(AC42,$Z$26:$Z$41,0)),""))) | K42: =IF(A42="","",IF(D42=1,F42,IFERROR(INDEX($AB$26:$AB$41,MATCH(AC42,$Z$26:$Z$41,0)),""))) | Z42: =IF(B42="","",B42&"#"&D42) | AA42: =IF(A42="","",IF(J42="",I42,IF(J42<1,AD42+J42,J42))) | AB42: =IF(A42="","",IF(COUNTA(L42:Q42)=0,K42,_xlfn.TEXTJOIN("・",TRUE(),L42:Q42))) | AC42: =IF(B42="","",B42&"#"&(D42-1)) | AD42: =IF(A42="","",IFERROR(INDEX(前日確定!$X$26:$X$45,MATCH(A42,前日確定!$B$26:$B$45,0)),""))
B43: =IF(A43="","",IFERROR(INDEX(前日確定!$C$26:$C$45,MATCH(A43,前日確定!$B$26:$B$45,0)),"作業が見つかりません")) | C43: =IF(A43="","",IFERROR(INDEX(前日確定!$D$26:$D$45,MATCH(A43,前日確定!$B$26:$B$45,0)),"")) | D43: =IF(B43="","",COUNTIF(B$26:B43,B43)) | E43: =IF(A43="","",IFERROR(IF(INDEX(前日確定!$Y$26:$Y$45,MATCH(A43,前日確定!$B$26:$B$45,0))="","",INDEX(前日確定!$Y$26:$Y$45,MATCH(A43,前日確定!$B$26:$B$45,0))),"")) | F43: =IF(A43="","",IFERROR(INDEX(前日確定!$R$26:$R$45,MATCH(A43,前日確定!$B$26:$B$45,0)),"")) | I43: =IF(A43="","",IF(D43=1,E43,IFERROR(INDEX($AA$26:$AA$42,MATCH(AC43,$Z$26:$Z$42,0)),""))) | K43: =IF(A43="","",IF(D43=1,F43,IFERROR(INDEX($AB$26:$AB$42,MATCH(AC43,$Z$26:$Z$42,0)),""))) | Z43: =IF(B43="","",B43&"#"&D43) | AA43: =IF(A43="","",IF(J43="",I43,IF(J43<1,AD43+J43,J43))) | AB43: =IF(A43="","",IF(COUNTA(L43:Q43)=0,K43,_xlfn.TEXTJOIN("・",TRUE(),L43:Q43))) | AC43: =IF(B43="","",B43&"#"&(D43-1)) | AD43: =IF(A43="","",IFERROR(INDEX(前日確定!$X$26:$X$45,MATCH(A43,前日確定!$B$26:$B$45,0)),""))
...

Sheet 入渠
A1: 入渠（作業に使えない期間）
A2: 誰が：上田（製鉄曳船）・西日本海運担当者（西日本海運）、他社は分かる範囲 何を見て：入渠の記録 どこへ：A6から1隻・1回ごとに1行
A3: 集計先：「集計」の入渠で使えない船数・供給可能船の確認
A5: 船名【入力・選択】 | B5: 会社【自動】 | C5: 入渠開始日【入力】 | D5: 作業復帰日【入力】 | E5: 情報元【入力】 | F5: 確認状況【入力・選択】 | G5: 対象日に使えない【自動】 | H5: 集計船名【自動】
B6: =IF(A6="","",IFERROR(IF(IFERROR(INDEX(マスター!$C$6:$C$125,MATCH(A6,マスター!$N$6:$N$125,0)),NA())="","未確認",IFERROR(INDEX(マスター!$C$6:$C$125,MATCH(A6,マスター!$N$6:$N$125,0)),NA())),"マスター未登録")) | G6: =IF(OR(A6="",C6=""),"",IF(AND(集計!$C$5>=C6,OR(D6="",集計!$C$5<D6)),"○","")) | H6: =IF(A6="","",IFERROR(INDEX(マスター!$K$6:$K$125,MATCH(A6,マスター!$N$6:$N$125,0)),A6))
B7: =IF(A7="","",IFERROR(IF(IFERROR(INDEX(マスター!$C$6:$C$125,MATCH(A7,マスター!$N$6:$N$125,0)),NA())="","未確認",IFERROR(INDEX(マスター!$C$6:$C$125,MATCH(A7,マスター!$N$6:$N$125,0)),NA())),"マスター未登録")) | G7: =IF(OR(A7="",C7=""),"",IF(AND(集計!$C$5>=C7,OR(D7="",集計!$C$5<D7)),"○","")) | H7: =IF(A7="","",IFERROR(INDEX(マスター!$K$6:$K$125,MATCH(A7,マスター!$N$6:$N$125,0)),A7))
B8: =IF(A8="","",IFERROR(IF(IFERROR(INDEX(マスター!$C$6:$C$125,MATCH(A8,マスター!$N$6:$N$125,0)),NA())="","未確認",IFERROR(INDEX(マスター!$C$6:$C$125,MATCH(A8,マスター!$N$6:$N$125,0)),NA())),"マスター未登録")) | G8: =IF(OR(A8="",C8=""),"",IF(AND(集計!$C$5>=C8,OR(D8="",集計!$C$5<D8)),"○","")) | H8: =IF(A8="","",IFERROR(INDEX(マスター!$K$6:$K$125,MATCH(A8,マスター!$N$6:$N$125,0)),A8))
B9: =IF(A9="","",IFERROR(IF(IFERROR(INDEX(マスター!$C$6:$C$125,MATCH(A9,マスター!$N$6:$N$125,0)),NA())="","未確認",IFERROR(INDEX(マスター!$C$6:$C$125,MATCH(A9,マスター!$N$6:$N$125,0)),NA())),"マスター未登録")) | G9: =IF(OR(A9="",C9=""),"",IF(AND(集計!$C$5>=C9,OR(D9="",集計!$C$5<D9)),"○","")) | H9: =IF(A9="","",IFERROR(INDEX(マスター!$K$6:$K$125,MATCH(A9,マスター!$N$6:$N$125,0)),A9))
B10: =IF(A10="","",IFERROR(IF(IFERROR(INDEX(マスター!$C$6:$C$125,MATCH(A10,マスター!$N$6:$N$125,0)),NA())="","未確認",IFERROR(INDEX(マスター!$C$6:$C$125,MATCH(A10,マスター!$N$6:$N$125,0)),NA())),"マスター未登録")) | G10: =IF(OR(A10="",C10=""),"",IF(AND(集計!$C$5>=C10,OR(D10="",集計!$C$5<D10)),"○","")) | H10: =IF(A10="","",IFERROR(INDEX(マスター!$K$6:$K$125,MATCH(A10,マスター!$N$6:$N$125,0)),A10))
B11: =IF(A11="","",IFERROR(IF(IFERROR(INDEX(マスター!$C$6:$C$125,MATCH(A11,マスター!$N$6:$N$125,0)),NA())="","未確認",IFERROR(INDEX(マスター!$C$6:$C$125,MATCH(A11,マスター!$N$6:$N$125,0)),NA())),"マスター未登録")) | G11: =IF(OR(A11="",C11=""),"",IF(AND(集計!$C$5>=C11,OR(D11="",集計!$C$5<D11)),"○","")) | H11: =IF(A11="","",IFERROR(INDEX(マスター!$K$6:$K$125,MATCH(A11,マスター!$N$6:$N$125,0)),A11))
B12: =IF(A12="","",IFERROR(IF(IFERROR(INDEX(マスター!$C$6:$C$125,MATCH(A12,マスター!$N$6:$N$125,0)),NA())="","未確認",IFERROR(INDEX(マスター!$C$6:$C$125,MATCH(A12,マスター!$N$6:$N$125,0)),NA())),"マスター未登録")) | G12: =IF(OR(A12="",C12=""),"",IF(AND(集計!$C$5>=C12,OR(D12="",集計!$C$5<D12)),"○","")) | H12: =IF(A12="","",IFERROR(INDEX(マスター!$K$6:$K$125,MATCH(A12,マスター!$N$6:$N$125,0)),A12))
B13: =IF(A13="","",IFERROR(IF(IFERROR(INDEX(マスター!$C$6:$C$125,MATCH(A13,マスター!$N$6:$N$125,0)),NA())="","未確認",IFERROR(INDEX(マスター!$C$6:$C$125,MATCH(A13,マスター!$N$6:$N$125,0)),NA())),"マスター未登録")) | G13: =IF(OR(A13="",C13=""),"",IF(AND(集計!$C$5>=C13,OR(D13="",集計!$C$5<D13)),"○","")) | H13: =IF(A13="","",IFERROR(INDEX(マスター!$K$6:$K$125,MATCH(A13,マスター!$N$6:$N$125,0)),A13))
B14: =IF(A14="","",IFERROR(IF(IFERROR(INDEX(マスター!$C$6:$C$125,MATCH(A14,マスター!$N$6:$N$125,0)),NA())="","未確認",IFERROR(INDEX(マスター!$C$6:$C$125,MATCH(A14,マスター!$N$6:$N$125,0)),NA())),"マスター未登録")) | G14: =IF(OR(A14="",C14=""),"",IF(AND(集計!$C$5>=C14,OR(D14="",集計!$C$5<D14)),"○","")) | H14: =IF(A14="","",IFERROR(INDEX(マスター!$K$6:$K$125,MATCH(A14,マスター!$N$6:$N$125,0)),A14))
B15: =IF(A15="","",IFERROR(IF(IFERROR(INDEX(マスター!$C$6:$C$125,MATCH(A15,マスター!$N$6:$N$125,0)),NA())="","未確認",IFERROR(INDEX(マスター!$C$6:$C$125,MATCH(A15,マスター!$N$6:$N$125,0)),NA())),"マスター未登録")) | G15: =IF(OR(A15="",C15=""),"",IF(AND(集計!$C$5>=C15,OR(D15="",集計!$C$5<D15)),"○","")) | H15: =IF(A15="","",IFERROR(INDEX(マスター!$K$6:$K$125,MATCH(A15,マスター!$N$6:$N$125,0)),A15))
B16: =IF(A16="","",IFERROR(IF(IFERROR(INDEX(マスター!$C$6:$C$125,MATCH(A16,マスター!$N$6:$N$125,0)),NA())="","未確認",IFERROR(INDEX(マスター!$C$6:$C$125,MATCH(A16,マスター!$N$6:$N$125,0)),NA())),"マスター未登録")) | G16: =IF(OR(A16="",C16=""),"",IF(AND(集計!$C$5>=C16,OR(D16="",集計!$C$5<D16)),"○","")) | H16: =IF(A16="","",IFERROR(INDEX(マスター!$K$6:$K$125,MATCH(A16,マスター!$N$6:$N$125,0)),A16))
B17: =IF(A17="","",IFERROR(IF(IFERROR(INDEX(マスター!$C$6:$C$125,MATCH(A17,マスター!$N$6:$N$125,0)),NA())="","未確認",IFERROR(INDEX(マスター!$C$6:$C$125,MATCH(A17,マスター!$N$6:$N$125,0)),NA())),"マスター未登録")) | G17: =IF(OR(A17="",C17=""),"",IF(AND(集計!$C$5>=C17,OR(D17="",集計!$C$5<D17)),"○","")) | H17: =IF(A17="","",IFERROR(INDEX(マスター!$K$6:$K$125,MATCH(A17,マスター!$N$6:$N$125,0)),A17))
... B55: =IF(A55="","",IFERROR(IF(IFERROR(INDEX(マスター!$C$6:$C$125,MATCH(A55,マスター!$N$6:$N$125,0)),NA())="","未確認",IFERROR(INDEX(マスター!$C$6:$C$125,MATCH(A55,マスター!$N$6:$N$125,0)),NA())),"マスター未登録")) | G55: =IF(OR(A55="",C55=""),"",IF(AND(集計!$C$5>=C55,OR(D55="",集計!$C$5<D55)),"○","")) | H55: =IF(A55="","",IFERROR(INDEX(マスター!$K$6:$K$125,MATCH(A55,マスター!$N$6:$N$125,0)),A55))

Sheet 他港作業
A1: 他港作業（西日本海運の全他港作業。関豊丸・長豊丸に限定しない）
A2: 誰が：西日本海運担当者 何を見て：西日本海運の作業記録 どこへ：A6から1作業ごとに1行。実時刻が分からない場合は「時刻の確認状況」で区別
A3: 集計先：「集計」の他港作業で拘束された船数・供給可能船の確認
A5: 船名【入力・選択】 | B5: 会社【自動】 | C5: 作業港【入力】 | D5: 基地発日時【入力】 | E5: 基地着日時【入力】 | F5: 時刻の確認状況【入力・選択】 | G5: 情報元【入力】 | H5: 確認者【入力】 | I5: 対象日に拘束【自動】 | J5: 会社の確認【自動】 | K5: 集計船名【自動】 | L5: 基地発（対象日0時からの分）【自動】 | M5: 基地着（分）【自動】
B6: =IF(A6="","",IFERROR(IF(IFERROR(INDEX(マスター!$C$6:$C$125,MATCH(A6,マスター!$N$6:$N$125,0)),NA())="","未確認",IFERROR(INDEX(マスター!$C$6:$C$125,MATCH(A6,マスター!$N$6:$N$125,0)),NA())),"マスター未登録")) | I6: =IF(OR(A6="",D6=""),"",IF(AND(D6<集計!$C$5+1,OR(E6="",E6>集計!$C$5)),"○","")) | J6: =IF(A6="","",IF(B6="西日本海運","","西日本海運以外の船です（確認してください）")) | K6: =IF(A6="","",IFERROR(INDEX(マスター!$K$6:$K$125,MATCH(A6,マスター!$N$6:$N$125,0)),A6)) | L6: =IF(OR(A6="",D6=""),"",ROUND((D6-集計!$C$5)*1440,0)) | M6: =IF(OR(A6="",E6=""),"",ROUND((E6-集計!$C$5)*1440,0))
B7: =IF(A7="","",IFERROR(IF(IFERROR(INDEX(マスター!$C$6:$C$125,MATCH(A7,マスター!$N$6:$N$125,0)),NA())="","未確認",IFERROR(INDEX(マスター!$C$6:$C$125,MATCH(A7,マスター!$N$6:$N$125,0)),NA())),"マスター未登録")) | I7: =IF(OR(A7="",D7=""),"",IF(AND(D7<集計!$C$5+1,OR(E7="",E7>集計!$C$5)),"○","")) | J7: =IF(A7="","",IF(B7="西日本海運","","西日本海運以外の船です（確認してください）")) | K7: =IF(A7="","",IFERROR(INDEX(マスター!$K$6:$K$125,MATCH(A7,マスター!$N$6:$N$125,0)),A7)) | L7: =IF(OR(A7="",D7=""),"",ROUND((D7-集計!$C$5)*1440,0)) | M7: =IF(OR(A7="",E7=""),"",ROUND((E7-集計!$C$5)*1440,0))
B8: =IF(A8="","",IFERROR(IF(IFERROR(INDEX(マスター!$C$6:$C$125,MATCH(A8,マスター!$N$6:$N$125,0)),NA())="","未確認",IFERROR(INDEX(マスター!$C$6:$C$125,MATCH(A8,マスター!$N$6:$N$125,0)),NA())),"マスター未登録")) | I8: =IF(OR(A8="",D8=""),"",IF(AND(D8<集計!$C$5+1,OR(E8="",E8>集計!$C$5)),"○","")) | J8: =IF(A8="","",IF(B8="西日本海運","","西日本海運以外の船です（確認してください）")) | K8: =IF(A8="","",IFERROR(INDEX(マスター!$K$6:$K$125,MATCH(A8,マスター!$N$6:$N$125,0)),A8)) | L8: =IF(OR(A8="",D8=""),"",ROUND((D8-集計!$C$5)*1440,0)) | M8: =IF(OR(A8="",E8=""),"",ROUND((E8-集計!$C$5)*1440,0))
B9: =IF(A9="","",IFERROR(IF(IFERROR(INDEX(マスター!$C$6:$C$125,MATCH(A9,マスター!$N$6:$N$125,0)),NA())="","未確認",IFERROR(INDEX(マスター!$C$6:$C$125,MATCH(A9,マスター!$N$6:$N$125,0)),NA())),"マスター未登録")) | I9: =IF(OR(A9="",D9=""),"",IF(AND(D9<集計!$C$5+1,OR(E9="",E9>集計!$C$5)),"○","")) | J9: =IF(A9="","",IF(B9="西日本海運","","西日本海運以外の船です（確認してください）")) | K9: =IF(A9="","",IFERROR(INDEX(マスター!$K$6:$K$125,MATCH(A9,マスター!$N$6:$N$125,0)),A9)) | L9: =IF(OR(A9="",D9=""),"",ROUND((D9-集計!$C$5)*1440,0)) | M9: =IF(OR(A9="",E9=""),"",ROUND((E9-集計!$C$5)*1440,0))
B10: =IF(A10="","",IFERROR(IF(IFERROR(INDEX(マスター!$C$6:$C$125,MATCH(A10,マスター!$N$6:$N$125,0)),NA())="","未確認",IFERROR(INDEX(マスター!$C$6:$C$125,MATCH(A10,マスター!$N$6:$N$125,0)),NA())),"マスター未登録")) | I10: =IF(OR(A10="",D10=""),"",IF(AND(D10<集計!$C$5+1,OR(E10="",E10>集計!$C$5)),"○","")) | J10: =IF(A10="","",IF(B10="西日本海運","","西日本海運以外の船です（確認してください）")) | K10: =IF(A10="","",IFERROR(INDEX(マスター!$K$6:$K$125,MATCH(A10,マスター!$N$6:$N$125,0)),A10)) | L10: =IF(OR(A10="",D10=""),"",ROUND((D10-集計!$C$5)*1440,0)) | M10: =IF(OR(A10="",E10=""),"",ROUND((E10-集計!$C$5)*1440,0))
B11: =IF(A11="","",IFERROR(IF(IFERROR(INDEX(マスター!$C$6:$C$125,MATCH(A11,マスター!$N$6:$N$125,0)),NA())="","未確認",IFERROR(INDEX(マスター!$C$6:$C$125,MATCH(A11,マスター!$N$6:$N$125,0)),NA())),"マスター未登録")) | I11: =IF(OR(A11="",D11=""),"",IF(AND(D11<集計!$C$5+1,OR(E11="",E11>集計!$C$5)),"○","")) | J11: =IF(A11="","",IF(B11="西日本海運","","西日本海運以外の船です（確認してください）")) | K11: =IF(A11="","",IFERROR(INDEX(マスター!$K$6:$K$125,MATCH(A11,マスター!$N$6:$N$125,0)),A11)) | L11: =IF(OR(A11="",D11=""),"",ROUND((D11-集計!$C$5)*1440,0)) | M11: =IF(OR(A11="",E11=""),"",ROUND((E11-集計!$C$5)*1440,0))
B12: =IF(A12="","",IFERROR(IF(IFERROR(INDEX(マスター!$C$6:$C$125,MATCH(A12,マスター!$N$6:$N$125,0)),NA())="","未確認",IFERROR(INDEX(マスター!$C$6:$C$125,MATCH(A12,マスター!$N$6:$N$125,0)),NA())),"マスター未登録")) | I12: =IF(OR(A12="",D12=""),"",IF(AND(D12<集計!$C$5+1,OR(E12="",E12>集計!$C$5)),"○","")) | J12: =IF(A12="","",IF(B12="西日本海運","","西日本海運以外の船です（確認してください）")) | K12: =IF(A12="","",IFERROR(INDEX(マスター!$K$6:$K$125,MATCH(A12,マスター!$N$6:$N$125,0)),A12)) | L12: =IF(OR(A12="",D12=""),"",ROUND((D12-集計!$C$5)*1440,0)) | M12: =IF(OR(A12="",E12=""),"",ROUND((E12-集計!$C$5)*1440,0))
