Workbook

Sheet はじめに
A2: 八幡地区の曳船体制を検証するための基礎調査
A3: 記入担当：上田さん／対象：2025年度の記録を中心に、不足する事例は2026年度以降も継続して集める。
A6: この調査で何を確認するか
A7: 電炉化に伴う減船を1隻にとどめ、常駐4隻を日鉄に認めてもらうための基礎事実を集めます。その後、必要な供給体制と負担を根拠に料金体系の見直しへ進みます。本表は、その交渉の基盤となる記録を収集する段階の資料です。
A10: 確認するのは、実施した仕事だけではありません。前日に船の時間・曳船・乗組員を確保できたか、取消・変更でも拘束が生じたか、入渠や他港作業中に応援を確保できたかを残します。上田さんに必要隻数の結論を記入してもらう表ではありません。
A14: 最初の3手順
A15: 1 「会社・曳船登録」は会社一覧、「曳船登録」は船名・会社名・基地港の一覧です。記入済みの会社や船は入力し直さず、未確認の基地港と不足する船だけ追加してください。
A17: 2 「所定時間登録」で、基地→作業→基地の所定時間を登録。実績時刻がある行は実績を優先し、所定時間を使った行には「見込み」と表示。
A19: 3 下表の入力先に、分かる記録から入力。実績入力欄は全て空欄。架空データは「7つの記入例」だけに掲載してあり、集計に含みません。
A22: 調査 | B22: 入力先 | D22: 何を残すか | F22: 主な確認元 | H22: 検証に使う視点
A23: ① | B23: 予定・実績 | D23: 前日予定、変更・取消、使用曳船、基地発着、待機 | F23: 前日版・変更版の作業予定表、作業記録 | H23: 前日に必要船を確保できるか
A24: ② | B24: 入渠 | D24: 製鉄5隻と関豊丸・長豊丸の入渠開始・復帰 | F24: 入渠記録、配船記録 | H24: 供給できない期間
A25: ③ | B25: 関豊丸・長豊丸の他港作業 | D25: 他港作業日時、回航込み拘束、料金（判明時） | F25: 他港作業記録、請求・支払記録 | H25: 応援需要と他港拘束の重なり
A26: ④ | B26: 予定・実績 | D26: 他社の応援船名。安瀬の通常分担と不足補充を区別 | F26: 予定表、変更記録、応援の記録 | H26: 応援を誰がどれだけ担ったか
A27: ⑤ | B27: 応援・時間調整 | D27: 依頼・回答理由、時間調整、水先人・代理店の回答 | F27: 照会記録、連絡記録、担当者の記憶 | H27: 応援不可・時間調整の制約
A28: ⑥ | B28: 他社の配備・在港 | D28: 実際の所在・配備期間、応援条件の回答 | F28: 他社への確認、配備・出張の記録 | H28: 在港・保有と応援可能の違い
A29: ⑦ | B29: 予定・実績／LNG警戒・交代 | D29: 入出港等は前者、警戒と曳船・乗組員交代は後者 | F29: LNG作業記録、警戒・交代記録 | H29: 同じ船・同じ時間の二重計上防止
A31: 色・単位・記録の扱い
A32: オレンジ：入力 | C32: 黄色：記録がある場合に入力 | F32: 灰色：自動表示・計算
A33: 日時は「2025/4/10 7:00」、時間は時間単位（30分＝0.5）。空欄は不明・未収集であり0ではありません。「記録」「記憶」「未確認」を必ず分け、記憶を実績時刻の証拠とは扱いません。
A35: 作業予定表の用語「予定」「船名」「荷種」「バース」「入出・転」「曳船名」「エスコート」「回頭」を使用。船名が判別できない場合は元資料を残し、確認後に船名を登録してください。
A38: 登録表がどこにつながるか
A39: 会社一覧 → 曳船登録の会社選択、会社別集計。曳船登録 → 各作業シートの船名選択、会社名・基地港の表示。「入力の選択肢」 → 各入力欄の選択肢。通常の入力では選択肢のシートへの記入は不要です。
A41: 所定時間登録 → 予定・実績の「所定合計h」。出動基地港＋バース＋荷種＋入出／転＋作業内容で照合します。安瀬の通常分担・不足補充と、応援の有無は、予定・実績の別々の欄で記録します。
A43: 曳船は「曳船登録」の空行へ1隻ずつ追加します。同じ会社に4隻あれば4行。新しい会社は会社一覧にも追加してください。空行が足りないときは、表の最終空行をコピー→表内に行を挿入→貼り付けて数式・選択欄も増やします。
A46: 後の検証で必要な区別
A47: 3隻案＝戸畑2・八幡1、4隻案＝戸畑2・八幡2。入渠、LNG、鋼材船が重なる日時と門司2隻の他港拘束を照合し、応援の実態も併せて検証します。本表では将来需要を実績へ混ぜません。
A49: LNG警戒は、1泊2日なら曳船交代なし、2泊3日なら曳船交換という運用を踏まえ、実際の交代・担当時間を記録。回頭とパイロット送りを同じ曳船が兼務した場合は1隻として記入。LNG月2回は将来の検証条件であり、実績欄に入れません。
A51: 安瀬の継続見通しは未確定。通常分担、若松分の不足補充、他社応援を分けて集めます。応援会社の所在地・保有隻数だけで応援可能とせず、実際の配備・在港、依頼への回答を根拠にします。
A54: 収集状況：ここにも記入してください
A55: 調査 | B55: 対象年度 | C55: 対象期間の開始 | D55: 対象期間の終了 | E55: 収集状況 | F55: 未収集・不足している記録 | G55: 確認担当・確認日 | H55: 補足
A56: 1
A57: 2
A58: 3
A59: 4
A60: 5
A61: 6
A62: 7

Sheet 会社・曳船登録
A2: 会社一覧：不足する会社だけ追加
A3: このシートは会社の一覧です。船名と基地港は「曳船登録」にあります。既に登録した会社は入力し直さず、不足する会社だけ空行に追加してください。
A5: 地区は会社別の整理に使います。曳船が実際にいる港は「曳船登録」の基地港と、作業・在港記録で確認します。
A7: 会社名 | B7: 地区 | C7: 入力確認（自動）
A8: 製鉄曳船 | B8: 戸畑・八幡 | C8: =IF(A8="","",IF(COUNTIF(Companies[会社名],A8)>1,"要確認：会社名重複",IF(B8="","要確認：地区未登録","登録済"))) -> 登録済
A9: 西日本海運 | B9: 関門 | C9: =IF(A9="","",IF(COUNTIF(Companies[会社名],A9)>1,"要確認：会社名重複",IF(B9="","要確認：地区未登録","登録済"))) -> 登録済
A10: 矢野海運 | B10: 若松 | C10: =IF(A10="","",IF(COUNTIF(Companies[会社名],A10)>1,"要確認：会社名重複",IF(B10="","要確認：地区未登録","登録済"))) -> 登録済
A11: 洞海マリン | B11: 若松 | C11: =IF(A11="","",IF(COUNTIF(Companies[会社名],A11)>1,"要確認：会社名重複",IF(B11="","要確認：地区未登録","登録済"))) -> 登録済
A12: グリーンシッピング | B12: 関門 | C12: =IF(A12="","",IF(COUNTIF(Companies[会社名],A12)>1,"要確認：会社名重複",IF(B12="","要確認：地区未登録","登録済"))) -> 登録済
A13: シーゲートコーポレーション | B13: 関門 | C13: =IF(A13="","",IF(COUNTIF(Companies[会社名],A13)>1,"要確認：会社名重複",IF(B13="","要確認：地区未登録","登録済"))) -> 登録済
A14: 日鉄物流 | B14: 関門 | C14: =IF(A14="","",IF(COUNTIF(Companies[会社名],A14)>1,"要確認：会社名重複",IF(B14="","要確認：地区未登録","登録済"))) -> 登録済
A15: 春風海運 | B15: 関門 | C15: =IF(A15="","",IF(COUNTIF(Companies[会社名],A15)>1,"要確認：会社名重複",IF(B15="","要確認：地区未登録","登録済"))) -> 登録済
A16: 福島海運 | B16: 苅田 | C16: =IF(A16="","",IF(COUNTIF(Companies[会社名],A16)>1,"要確認：会社名重複",IF(B16="","要確認：地区未登録","登録済"))) -> 登録済
C17: =IF(A17="","",IF(COUNTIF(Companies[会社名],A17)>1,"要確認：会社名重複",IF(B17="","要確認：地区未登録","登録済")))
C18: =IF(A18="","",IF(COUNTIF(Companies[会社名],A18)>1,"要確認：会社名重複",IF(B18="","要確認：地区未登録","登録済")))
C19: =IF(A19="","",IF(COUNTIF(Companies[会社名],A19)>1,"要確認：会社名重複",IF(B19="","要確認：地区未登録","登録済")))
C20: =IF(A20="","",IF(COUNTIF(Companies[会社名],A20)>1,"要確認：会社名重複",IF(B20="","要確認：地区未登録","登録済")))
C21: =IF(A21="","",IF(COUNTIF(Companies[会社名],A21)>1,"要確認：会社名重複",IF(B21="","要確認：地区未登録","登録済")))
C22: =IF(A22="","",IF(COUNTIF(Companies[会社名],A22)>1,"要確認：会社名重複",IF(B22="","要確認：地区未登録","登録済")))
C23: =IF(A23="","",IF(COUNTIF(Companies[会社名],A23)>1,"要確認：会社名重複",IF(B23="","要確認：地区未登録","登録済")))
C24: =IF(A24="","",IF(COUNTIF(Companies[会社名],A24)>1,"要確認：会社名重複",IF(B24="","要確認：地区未登録","登録済")))
C25: =IF(A25="","",IF(COUNTIF(Companies[会社名],A25)>1,"要確認：会社名重複",IF(B25="","要確認：地区未登録","登録済")))
C26: =IF(A26="","",IF(COUNTIF(Companies[会社名],A26)>1,"要確認：会社名重複",IF(B26="","要確認：地区未登録","登録済")))
C27: =IF(A27="","",IF(COUNTIF(Companies[会社名],A27)>1,"要確認：会社名重複",IF(B27="","要確認：地区未登録","登録済")))
C28: =IF(A28="","",IF(COUNTIF(Companies[会社名],A28)>1,"要確認：会社名重複",IF(B28="","要確認：地区未登録","登録済")))
... C107: =IF(A107="","",IF(COUNTIF(Companies[会社名],A107)>1,"要確認：会社名重複",IF(B107="","要確認：地区未登録","登録済")))

Sheet 所定時間登録
A2: 所定時間登録
A3: 実績の基地発・基地着が残っていないときの見込みに使用。基地・バース・荷種・入出／転・作業内容の組合せごとに1行。3つの時間は、0時間も含めて全て数値で登録。
A7: 基地港 | B7: バース | C7: 荷種 | D7: 入出・転 | E7: 作業内容 | F7: 行きの移動h | G7: タグ作業h | H7: 帰りの移動h | I7: 所定合計h（自動） | J7: 確認元・設定根拠 | K7: 入力確認（自動） | L7: 照合項目（自動）
I8: =IF(A8="","",IF(AND(COUNT(F8:H8)=3,MIN(F8:H8)>=0),SUM(F8:H8),"未確認")) | K8: =IF(A8="","",IF(OR(B8="",C8="",D8="",E8=""),"要確認：照合項目不足",IF(COUNTIF(Standards[照合項目（自動）],L8)>1,"要確認：同じ組合せ重複",IF(NOT(ISNUMBER(I8)),"要確認：時間不足・負数",IF(J8="","要確認：設定根拠未記入","確認済"))))) | L8: =IF(A8="","",A8&"｜"&B8&"｜"&C8&"｜"&D8&"｜"&E8)
I9: =IF(A9="","",IF(AND(COUNT(F9:H9)=3,MIN(F9:H9)>=0),SUM(F9:H9),"未確認")) | K9: =IF(A9="","",IF(OR(B9="",C9="",D9="",E9=""),"要確認：照合項目不足",IF(COUNTIF(Standards[照合項目（自動）],L9)>1,"要確認：同じ組合せ重複",IF(NOT(ISNUMBER(I9)),"要確認：時間不足・負数",IF(J9="","要確認：設定根拠未記入","確認済"))))) | L9: =IF(A9="","",A9&"｜"&B9&"｜"&C9&"｜"&D9&"｜"&E9)
I10: =IF(A10="","",IF(AND(COUNT(F10:H10)=3,MIN(F10:H10)>=0),SUM(F10:H10),"未確認")) | K10: =IF(A10="","",IF(OR(B10="",C10="",D10="",E10=""),"要確認：照合項目不足",IF(COUNTIF(Standards[照合項目（自動）],L10)>1,"要確認：同じ組合せ重複",IF(NOT(ISNUMBER(I10)),"要確認：時間不足・負数",IF(J10="","要確認：設定根拠未記入","確認済"))))) | L10: =IF(A10="","",A10&"｜"&B10&"｜"&C10&"｜"&D10&"｜"&E10)
I11: =IF(A11="","",IF(AND(COUNT(F11:H11)=3,MIN(F11:H11)>=0),SUM(F11:H11),"未確認")) | K11: =IF(A11="","",IF(OR(B11="",C11="",D11="",E11=""),"要確認：照合項目不足",IF(COUNTIF(Standards[照合項目（自動）],L11)>1,"要確認：同じ組合せ重複",IF(NOT(ISNUMBER(I11)),"要確認：時間不足・負数",IF(J11="","要確認：設定根拠未記入","確認済"))))) | L11: =IF(A11="","",A11&"｜"&B11&"｜"&C11&"｜"&D11&"｜"&E11)
I12: =IF(A12="","",IF(AND(COUNT(F12:H12)=3,MIN(F12:H12)>=0),SUM(F12:H12),"未確認")) | K12: =IF(A12="","",IF(OR(B12="",C12="",D12="",E12=""),"要確認：照合項目不足",IF(COUNTIF(Standards[照合項目（自動）],L12)>1,"要確認：同じ組合せ重複",IF(NOT(ISNUMBER(I12)),"要確認：時間不足・負数",IF(J12="","要確認：設定根拠未記入","確認済"))))) | L12: =IF(A12="","",A12&"｜"&B12&"｜"&C12&"｜"&D12&"｜"&E12)
I13: =IF(A13="","",IF(AND(COUNT(F13:H13)=3,MIN(F13:H13)>=0),SUM(F13:H13),"未確認")) | K13: =IF(A13="","",IF(OR(B13="",C13="",D13="",E13=""),"要確認：照合項目不足",IF(COUNTIF(Standards[照合項目（自動）],L13)>1,"要確認：同じ組合せ重複",IF(NOT(ISNUMBER(I13)),"要確認：時間不足・負数",IF(J13="","要確認：設定根拠未記入","確認済"))))) | L13: =IF(A13="","",A13&"｜"&B13&"｜"&C13&"｜"&D13&"｜"&E13)
I14: =IF(A14="","",IF(AND(COUNT(F14:H14)=3,MIN(F14:H14)>=0),SUM(F14:H14),"未確認")) | K14: =IF(A14="","",IF(OR(B14="",C14="",D14="",E14=""),"要確認：照合項目不足",IF(COUNTIF(Standards[照合項目（自動）],L14)>1,"要確認：同じ組合せ重複",IF(NOT(ISNUMBER(I14)),"要確認：時間不足・負数",IF(J14="","要確認：設定根拠未記入","確認済"))))) | L14: =IF(A14="","",A14&"｜"&B14&"｜"&C14&"｜"&D14&"｜"&E14)
I15: =IF(A15="","",IF(AND(COUNT(F15:H15)=3,MIN(F15:H15)>=0),SUM(F15:H15),"未確認")) | K15: =IF(A15="","",IF(OR(B15="",C15="",D15="",E15=""),"要確認：照合項目不足",IF(COUNTIF(Standards[照合項目（自動）],L15)>1,"要確認：同じ組合せ重複",IF(NOT(ISNUMBER(I15)),"要確認：時間不足・負数",IF(J15="","要確認：設定根拠未記入","確認済"))))) | L15: =IF(A15="","",A15&"｜"&B15&"｜"&C15&"｜"&D15&"｜"&E15)
I16: =IF(A16="","",IF(AND(COUNT(F16:H16)=3,MIN(F16:H16)>=0),SUM(F16:H16),"未確認")) | K16: =IF(A16="","",IF(OR(B16="",C16="",D16="",E16=""),"要確認：照合項目不足",IF(COUNTIF(Standards[照合項目（自動）],L16)>1,"要確認：同じ組合せ重複",IF(NOT(ISNUMBER(I16)),"要確認：時間不足・負数",IF(J16="","要確認：設定根拠未記入","確認済"))))) | L16: =IF(A16="","",A16&"｜"&B16&"｜"&C16&"｜"&D16&"｜"&E16)
I17: =IF(A17="","",IF(AND(COUNT(F17:H17)=3,MIN(F17:H17)>=0),SUM(F17:H17),"未確認")) | K17: =IF(A17="","",IF(OR(B17="",C17="",D17="",E17=""),"要確認：照合項目不足",IF(COUNTIF(Standards[照合項目（自動）],L17)>1,"要確認：同じ組合せ重複",IF(NOT(ISNUMBER(I17)),"要確認：時間不足・負数",IF(J17="","要確認：設定根拠未記入","確認済"))))) | L17: =IF(A17="","",A17&"｜"&B17&"｜"&C17&"｜"&D17&"｜"&E17)
I18: =IF(A18="","",IF(AND(COUNT(F18:H18)=3,MIN(F18:H18)>=0),SUM(F18:H18),"未確認")) | K18: =IF(A18="","",IF(OR(B18="",C18="",D18="",E18=""),"要確認：照合項目不足",IF(COUNTIF(Standards[照合項目（自動）],L18)>1,"要確認：同じ組合せ重複",IF(NOT(ISNUMBER(I18)),"要確認：時間不足・負数",IF(J18="","要確認：設定根拠未記入","確認済"))))) | L18: =IF(A18="","",A18&"｜"&B18&"｜"&C18&"｜"&D18&"｜"&E18)
I19: =IF(A19="","",IF(AND(COUNT(F19:H19)=3,MIN(F19:H19)>=0),SUM(F19:H19),"未確認")) | K19: =IF(A19="","",IF(OR(B19="",C19="",D19="",E19=""),"要確認：照合項目不足",IF(COUNTIF(Standards[照合項目（自動）],L19)>1,"要確認：同じ組合せ重複",IF(NOT(ISNUMBER(I19)),"要確認：時間不足・負数",IF(J19="","要確認：設定根拠未記入","確認済"))))) | L19: =IF(A19="","",A19&"｜"&B19&"｜"&C19&"｜"&D19&"｜"&E19)
... I407: =IF(A407="","",IF(AND(COUNT(F407:H407)=3,MIN(F407:H407)>=0),SUM(F407:H407),"未確認")) | K407: =IF(A407="","",IF(OR(B407="",C407="",D407="",E407=""),"要確認：照合項目不足",IF(COUNTIF(Standards[照合項目（自動）],L407)>1,"要確認：同じ組合せ重複",IF(NOT(ISNUMBER(I407)),"要確認：時間不足・負数",IF(J407="","要確認：設定根拠未記入","確認済"))))) | L407: =IF(A407="","",A407&"｜"&B407&"｜"&C407&"｜"&D407&"｜"&E407)

Sheet 予定・実績
A2: 予定・実績
A3: 曳船1隻・1作業につき1行。前日予定は消さず、変更・取消と当日使用を記録します。「安瀬の作業」は分担の内容、「応援の有無」は通常分担外の応援かを別々に選びます。
A6: 前日予定・曳船の割当 | J6: 当日の変更・使用・拘束・待機 | V6: 根拠と補足 | W6: 確認元・記録区分・補足 | Y6: 登録表との照合・集計用（自動） | Z6: 灰色：自動表示・計算
A7: 予定表の作業日 | B7: 前日版の予定時刻 | C7: 船名 | D7: 荷種 | E7: バース | F7: 入出・転 | G7: 曳船名 | H7: 前日割当 | I7: 当日使用 | J7: 本船作業の最終結果 | K7: 最終作業日時 | L7: 変更・取消理由 | M7: 関連する前船・後船 | N7: 安瀬の作業 | O7: 応援の有無 | P7: 作業内容 | Q7: 出動基地港（変更時） | R7: 基地発（実績） | S7: 基地着（実績） | T7: 拘束h（記録の時間） | U7: 出勤・待機 | V7: 待機h | W7: 確認元 | X7: 記録区分 | Y7: 補足 | Z7: 会社（自動） | AA7: 地区（自動） | AB7: 出動基地港（自動） | AC7: 所定合計h（自動） | AD7: 拘束h（自動） | AE7: 時間根拠（自動） | AF7: 前日割当隻数（自動） | AG7: 当日使用隻数（自動） | AH7: 前日予定本船件数（自動） | AI7: 実施本船件数（自動） | AJ7: 予定年度（自動） | AK7: 実施年度（自動） | AL7: 入力確認（自動）
Z8: =IF(G8="","",IF(COUNTIF(Tugs[曳船名],G8)<>1,"未登録・重複",IF(INDEX(Tugs[会社名],MATCH(G8,Tugs[曳船名],0))="","未確認",INDEX(Tugs[会社名],MATCH(G8,Tugs[曳船名],0))))) | AA8: =IF(G8="","",IF(COUNTIF(Companies[会社名],Z8)<>1,"未登録・重複",IF(INDEX(Companies[地区],MATCH(Z8,Companies[会社名],0))="","未確認",INDEX(Companies[地区],MATCH(Z8,Companies[会社名],0))))) | AB8: =IF(G8="","",IF(Q8<>"",Q8,IF(COUNTIF(Tugs[曳船名],G8)<>1,"未登録・重複",IF(INDEX(Tugs[基地港],MATCH(G8,Tugs[曳船名],0))="","未確認",INDEX(Tugs[基地港],MATCH(G8,Tugs[曳船名],0)))))) | AC8: =IF(C8="","",IF(AND(COUNTIF(Standards[照合項目（自動）],AB8&"｜"&E8&"｜"&D8&"｜"&F8&"｜"&P8)=1,COUNTIFS(Standards[照合項目（自動）],AB8&"｜"&E8&"｜"&D8&"｜"&F8&"｜"&P8,Standards[入力確認（自動）],"確認済")=1),SUMIF(Standards[照合項目（自動）],AB8&"｜"&E8&"｜"&D8&"｜"&F8&"｜"&P8,Standards[所定合計h（自動）]),"未確認")) | AD8: =IF(C8="","",IF(AND(ISNUMBER(R8),ISNUMBER(S8),S8>=R8),ROUND((S8-R8)*24,4),IF(OR(R8<>"",S8<>""),"",IF(AND(ISNUMBER(T8),T8>=0),T8,IF(AND(I8="あり",J8="実施",ISNUMBER(AC8)),AC8,""))))) | AE8: =IF(C8="","",IF(AND(ISNUMBER(R8),ISNUMBER(S8),S8>=R8),IF(X8="記録","実績：基地発～基地着",IF(X8="記憶","記憶：基地発～基地着","未確認：基地発～基地着")),IF(OR(R8<>"",S8<>""),"要確認：時刻不足・逆転",IF(AND(ISNUMBER(T8),T8>=0),IF(X8="記録","実績：記録の時間",IF(X8="記憶","記憶：申告の時間","未確認：申告の時間")),IF(AND(I8="あり",J8="実施",ISNUMBER(AC8)),"所定時間による見込み",IF(I8="なし","使用なし","未確認")))))) | AF8: =IF(C8="","",IF(H8="あり",1,0)) | AG8: =IF(C8="","",IF(AND(I8="あり",J8="実施"),1,0)) | AH8: =IF(C8="","",IF(AND(H8="あり",X8="記録"),IF(COUNTIFS($A$8:A8,A8,$B$8:B8,B8,$C$8:C8,C8,$E$8:E8,E8,$F$8:F8,F8,$H$8:H8,"あり",$X$8:X8,"記録")=1,1,0),0)) | AI8: =IF(C8="","",IF(AND(I8="あり",J8="実施",X8="記録",ISNUMBER(K8)),IF(COUNTIFS($K$8:K8,K8,$C$8:C8,C8,$E$8:E8,E8,$F$8:F8,F8,$I$8:I8,"あり",$J$8:J8,"実施",$X$8:X8,"記録")=1,1,0),0)) | AJ8: =IF(C8="","",IF(ISNUMBER(A8),YEAR(A8)-IF(MONTH(A8)<4,1,0),"")) | AK8: =IF(C8="","",IF(J8="実施",IF(ISNUMBER(K8),YEAR(K8)-IF(MONTH(K8)<4,1,0),""),"")) | AL8: =IF(C8="",IF(OR(A8<>"",G8<>""),"要確認：船名未記入",""),IF(OR(NOT(ISNUMBER(A8)),G8="",H8="",I8="",J8="",N8="",O8="",P8="",W8="",X8=""),"要確認：基本項目不足",IF(OR(Z8="未登録・重複",AA8="未登録・重複",AB8="未確認"),"要確認：登録表を確認",IF(AND(H8="あり",NOT(ISNUMBER(B8))),"要確認：前日の予定時刻不足",IF(AND(J8="実施",I8="あり",NOT(ISNUMBER(K8))),"要確認：最終日時不足",IF(AND(J8="取消",I8="あり"),"要確認：取消と使用ありが矛盾",IF(OR(AND(ISNUMBER(T8),T8<0),AND(ISNUMBER(V8),V8<0),AE8="要確認：時刻不足・逆転"),"要確認：時間を確認",IF(COUNTIFS(Work[予定表の作業日],A8,Work[前日版の予定時刻],B8,Work[船名],C8,Work[バース],E8,Work[入出・転],F8,Work[曳船名],G8)>1,"要確認：同じ作業・曳船が重複",IF(AND(I8="あり",J8="実施",NOT(ISNUMBER(AD8))),"要確認：拘束時間未確認",IF(OR(H8="未確認",I8="未確認",J8="未確認",X8="未確認",N8="未確認",O8="未確認"),"要確認：未確認を含む","確認済"))))))))))
Z9: =IF(G9="","",IF(COUNTIF(Tugs[曳船名],G9)<>1,"未登録・重複",IF(INDEX(Tugs[会社名],MATCH(G9,Tugs[曳船名],0))="","未確認",INDEX(Tugs[会社名],MATCH(G9,Tugs[曳船名],0))))) | AA9: =IF(G9="","",IF(COUNTIF(Companies[会社名],Z9)<>1,"未登録・重複",IF(INDEX(Companies[地区],MATCH(Z9,Companies[会社名],0))="","未確認",INDEX(Companies[地区],MATCH(Z9,Companies[会社名],0))))) | AB9: =IF(G9="","",IF(Q9<>"",Q9,IF(COUNTIF(Tugs[曳船名],G9)<>1,"未登録・重複",IF(INDEX(Tugs[基地港],MATCH(G9,Tugs[曳船名],0))="","未確認",INDEX(Tugs[基地港],MATCH(G9,Tugs[曳船名],0)))))) | AC9: =IF(C9="","",IF(AND(COUNTIF(Standards[照合項目（自動）],AB9&"｜"&E9&"｜"&D9&"｜"&F9&"｜"&P9)=1,COUNTIFS(Standards[照合項目（自動）],AB9&"｜"&E9&"｜"&D9&"｜"&F9&"｜"&P9,Standards[入力確認（自動）],"確認済")=1),SUMIF(Standards[照合項目（自動）],AB9&"｜"&E9&"｜"&D9&"｜"&F9&"｜"&P9,Standards[所定合計h（自動）]),"未確認")) | AD9: =IF(C9="","",IF(AND(ISNUMBER(R9),ISNUMBER(S9),S9>=R9),ROUND((S9-R9)*24,4),IF(OR(R9<>"",S9<>""),"",IF(AND(ISNUMBER(T9),T9>=0),T9,IF(AND(I9="あり",J9="実施",ISNUMBER(AC9)),AC9,""))))) | AE9: =IF(C9="","",IF(AND(ISNUMBER(R9),ISNUMBER(S9),S9>=R9),IF(X9="記録","実績：基地発～基地着",IF(X9="記憶","記憶：基地発～基地着","未確認：基地発～基地着")),IF(OR(R9<>"",S9<>""),"要確認：時刻不足・逆転",IF(AND(ISNUMBER(T9),T9>=0),IF(X9="記録","実績：記録の時間",IF(X9="記憶","記憶：申告の時間","未確認：申告の時間")),IF(AND(I9="あり",J9="実施",ISNUMBER(AC9)),"所定時間による見込み",IF(I9="なし","使用なし","未確認")))))) | AF9: =IF(C9="","",IF(H9="あり",1,0)) | AG9: =IF(C9="","",IF(AND(I9="あり",J9="実施"),1,0)) | AH9: =IF(C9="","",IF(AND(H9="あり",X9="記録"),IF(COUNTIFS($A$8:A9,A9,$B$8:B9,B9,$C$8:C9,C9,$E$8:E9,E9,$F$8:F9,F9,$H$8:H9,"あり",$X$8:X9,"記録")=1,1,0),0)) | AI9: =IF(C9="","",IF(AND(I9="あり",J9="実施",X9="記録",ISNUMBER(K9)),IF(COUNTIFS($K$8:K9,K9,$C$8:C9,C9,$E$8:E9,E9,$F$8:F9,F9,$I$8:I9,"あり",$J$8:J9,"実施",$X$8:X9,"記録")=1,1,0),0)) | AJ9: =IF(C9="","",IF(ISNUMBER(A9),YEAR(A9)-IF(MONTH(A9)<4,1,0),"")) | AK9: =IF(C9="","",IF(J9="実施",IF(ISNUMBER(K9),YEAR(K9)-IF(MONTH(K9)<4,1,0),""),"")) | AL9: =IF(C9="",IF(OR(A9<>"",G9<>""),"要確認：船名未記入",""),IF(OR(NOT(ISNUMBER(A9)),G9="",H9="",I9="",J9="",N9="",O9="",P9="",W9="",X9=""),"要確認：基本項目不足",IF(OR(Z9="未登録・重複",AA9="未登録・重複",AB9="未確認"),"要確認：登録表を確認",IF(AND(H9="あり",NOT(ISNUMBER(B9))),"要確認：前日の予定時刻不足",IF(AND(J9="実施",I9="あり",NOT(ISNUMBER(K9))),"要確認：最終日時不足",IF(AND(J9="取消",I9="あり"),"要確認：取消と使用ありが矛盾",IF(OR(AND(ISNUMBER(T9),T9<0),AND(ISNUMBER(V9),V9<0),AE9="要確認：時刻不足・逆転"),"要確認：時間を確認",IF(COUNTIFS(Work[予定表の作業日],A9,Work[前日版の予定時刻],B9,Work[船名],C9,Work[バース],E9,Work[入出・転],F9,Work[曳船名],G9)>1,"要確認：同じ作業・曳船が重複",IF(AND(I9="あり",J9="実施",NOT(ISNUMBER(AD9))),"要確認：拘束時間未確認",IF(OR(H9="未確認",I9="未確認",J9="未確認",X9="未確認",N9="未確認",O9="未確認"),"要確認：未確認を含む","確認済"))))))))))
Z10: =IF(G10="","",IF(COUNTIF(Tugs[曳船名],G10)<>1,"未登録・重複",IF(INDEX(Tugs[会社名],MATCH(G10,Tugs[曳船名],0))="","未確認",INDEX(Tugs[会社名],MATCH(G10,Tugs[曳船名],0))))) | AA10: =IF(G10="","",IF(COUNTIF(Companies[会社名],Z10)<>1,"未登録・重複",IF(INDEX(Companies[地区],MATCH(Z10,Companies[会社名],0))="","未確認",INDEX(Companies[地区],MATCH(Z10,Companies[会社名],0))))) | AB10: =IF(G10="","",IF(Q10<>"",Q10,IF(COUNTIF(Tugs[曳船名],G10)<>1,"未登録・重複",IF(INDEX(Tugs[基地港],MATCH(G10,Tugs[曳船名],0))="","未確認",INDEX(Tugs[基地港],MATCH(G10,Tugs[曳船名],0)))))) | AC10: =IF(C10="","",IF(AND(COUNTIF(Standards[照合項目（自動）],AB10&"｜"&E10&"｜"&D10&"｜"&F10&"｜"&P10)=1,COUNTIFS(Standards[照合項目（自動）],AB10&"｜"&E10&"｜"&D10&"｜"&F10&"｜"&P10,Standards[入力確認（自動）],"確認済")=1),SUMIF(Standards[照合項目（自動）],AB10&"｜"&E10&"｜"&D10&"｜"&F10&"｜"&P10,Standards[所定合計h（自動）]),"未確認")) | AD10: =IF(C10="","",IF(AND(ISNUMBER(R10),ISNUMBER(S10),S10>=R10),ROUND((S10-R10)*24,4),IF(OR(R10<>"",S10<>""),"",IF(AND(ISNUMBER(T10),T10>=0),T10,IF(AND(I10="あり",J10="実施",ISNUMBER(AC10)),AC10,""))))) | AE10: =IF(C10="","",IF(AND(ISNUMBER(R10),ISNUMBER(S10),S10>=R10),IF(X10="記録","実績：基地発～基地着",IF(X10="記憶","記憶：基地発～基地着","未確認：基地発～基地着")),IF(OR(R10<>"",S10<>""),"要確認：時刻不足・逆転",IF(AND(ISNUMBER(T10),T10>=0),IF(X10="記録","実績：記録の時間",IF(X10="記憶","記憶：申告の時間","未確認：申告の時間")),IF(AND(I10="あり",J10="実施",ISNUMBER(AC10)),"所定時間による見込み",IF(I10="なし","使用なし","未確認")))))) | AF10: =IF(C10="","",IF(H10="あり",1,0)) | AG10: =IF(C10="","",IF(AND(I10="あり",J10="実施"),1,0)) | AH10: =IF(C10="","",IF(AND(H10="あり",X10="記録"),IF(COUNTIFS($A$8:A10,A10,$B$8:B10,B10,$C$8:C10,C10,$E$8:E10,E10,$F$8:F10,F10,$H$8:H10,"あり",$X$8:X10,"記録")=1,1,0),0)) | AI10: =IF(C10="","",IF(AND(I10="あり",J10="実施",X10="記録",ISNUMBER(K10)),IF(COUNTIFS($K$8:K10,K10,$C$8:C10,C10,$E$8:E10,E10,$F$8:F10,F10,$I$8:I10,"あり",$J$8:J10,"実施",$X$8:X10,"記録")=1,1,0),0)) | AJ10: =IF(C10="","",IF(ISNUMBER(A10),YEAR(A10)-IF(MONTH(A10)<4,1,0),"")) | AK10: =IF(C10="","",IF(J10="実施",IF(ISNUMBER(K10),YEAR(K10)-IF(MONTH(K10)<4,1,0),""),"")) | AL10: =IF(C10="",IF(OR(A10<>"",G10<>""),"要確認：船名未記入",""),IF(OR(NOT(ISNUMBER(A10)),G10="",H10="",I10="",J10="",N10="",O10="",P10="",W10="",X10=""),"要確認：基本項目不足",IF(OR(Z10="未登録・重複",AA10="未登録・重複",AB10="未確認"),"要確認：登録表を確認",IF(AND(H10="あり",NOT(ISNUMBER(B10))),"要確認：前日の予定時刻不足",IF(AND(J10="実施",I10="あり",NOT(ISNUMBER(K10))),"要確認：最終日時不足",IF(AND(J10="取消",I10="あり"),"要確認：取消と使用ありが矛盾",IF(OR(AND(ISNUMBER(T10),T10<0),AND(ISNUMBER(V10),V10<0),AE10="要確認：時刻不足・逆転"),"要確認：時間を確認",IF(COUNTIFS(Work[予定表の作業日],A10,Work[前日版の予定時刻],B10,Work[船名],C10,Work[バース],E10,Work[入出・転],F10,Work[曳船名],G10)>1,"要確認：同じ作業・曳船が重複",IF(AND(I10="あり",J10="実施",NOT(ISNUMBER(AD10))),"要確認：拘束時間未確認",IF(OR(H10="未確認",I10="未確認",J10="未確認",X10="未確認",N10="未確認",O10="未確認"),"要確認：未確認を含む","確認済"))))))))))
Z11: =IF(G11="","",IF(COUNTIF(Tugs[曳船名],G11)<>1,"未登録・重複",IF(INDEX(Tugs[会社名],MATCH(G11,Tugs[曳船名],0))="","未確認",INDEX(Tugs[会社名],MATCH(G11,Tugs[曳船名],0))))) | AA11: =IF(G11="","",IF(COUNTIF(Companies[会社名],Z11)<>1,"未登録・重複",IF(INDEX(Companies[地区],MATCH(Z11,Companies[会社名],0))="","未確認",INDEX(Companies[地区],MATCH(Z11,Companies[会社名],0))))) | AB11: =IF(G11="","",IF(Q11<>"",Q11,IF(COUNTIF(Tugs[曳船名],G11)<>1,"未登録・重複",IF(INDEX(Tugs[基地港],MATCH(G11,Tugs[曳船名],0))="","未確認",INDEX(Tugs[基地港],MATCH(G11,Tugs[曳船名],0)))))) | AC11: =IF(C11="","",IF(AND(COUNTIF(Standards[照合項目（自動）],AB11&"｜"&E11&"｜"&D11&"｜"&F11&"｜"&P11)=1,COUNTIFS(Standards[照合項目（自動）],AB11&"｜"&E11&"｜"&D11&"｜"&F11&"｜"&P11,Standards[入力確認（自動）],"確認済")=1),SUMIF(Standards[照合項目（自動）],AB11&"｜"&E11&"｜"&D11&"｜"&F11&"｜"&P11,Standards[所定合計h（自動）]),"未確認")) | AD11: =IF(C11="","",IF(AND(ISNUMBER(R11),ISNUMBER(S11),S11>=R11),ROUND((S11-R11)*24,4),IF(OR(R11<>"",S11<>""),"",IF(AND(ISNUMBER(T11),T11>=0),T11,IF(AND(I11="あり",J11="実施",ISNUMBER(AC11)),AC11,""))))) | AE11: =IF(C11="","",IF(AND(ISNUMBER(R11),ISNUMBER(S11),S11>=R11),IF(X11="記録","実績：基地発～基地着",IF(X11="記憶","記憶：基地発～基地着","未確認：基地発～基地着")),IF(OR(R11<>"",S11<>""),"要確認：時刻不足・逆転",IF(AND(ISNUMBER(T11),T11>=0),IF(X11="記録","実績：記録の時間",IF(X11="記憶","記憶：申告の時間","未確認：申告の時間")),IF(AND(I11="あり",J11="実施",ISNUMBER(AC11)),"所定時間による見込み",IF(I11="なし","使用なし","未確認")))))) | AF11: =IF(C11="","",IF(H11="あり",1,0)) | AG11: =IF(C11="","",IF(AND(I11="あり",J11="実施"),1,0)) | AH11: =IF(C11="","",IF(AND(H11="あり",X11="記録"),IF(COUNTIFS($A$8:A11,A11,$B$8:B11,B11,$C$8:C11,C11,$E$8:E11,E11,$F$8:F11,F11,$H$8:H11,"あり",$X$8:X11,"記録")=1,1,0),0)) | AI11: =IF(C11="","",IF(AND(I11="あり",J11="実施",X11="記録",ISNUMBER(K11)),IF(COUNTIFS($K$8:K11,K11,$C$8:C11,C11,$E$8:E11,E11,$F$8:F11,F11,$I$8:I11,"あり",$J$8:J11,"実施",$X$8:X11,"記録")=1,1,0),0)) | AJ11: =IF(C11="","",IF(ISNUMBER(A11),YEAR(A11)-IF(MONTH(A11)<4,1,0),"")) | AK11: =IF(C11="","",IF(J11="実施",IF(ISNUMBER(K11),YEAR(K11)-IF(MONTH(K11)<4,1,0),""),"")) | AL11: =IF(C11="",IF(OR(A11<>"",G11<>""),"要確認：船名未記入",""),IF(OR(NOT(ISNUMBER(A11)),G11="",H11="",I11="",J11="",N11="",O11="",P11="",W11="",X11=""),"要確認：基本項目不足",IF(OR(Z11="未登録・重複",AA11="未登録・重複",AB11="未確認"),"要確認：登録表を確認",IF(AND(H11="あり",NOT(ISNUMBER(B11))),"要確認：前日の予定時刻不足",IF(AND(J11="実施",I11="あり",NOT(ISNUMBER(K11))),"要確認：最終日時不足",IF(AND(J11="取消",I11="あり"),"要確認：取消と使用ありが矛盾",IF(OR(AND(ISNUMBER(T11),T11<0),AND(ISNUMBER(V11),V11<0),AE11="要確認：時刻不足・逆転"),"要確認：時間を確認",IF(COUNTIFS(Work[予定表の作業日],A11,Work[前日版の予定時刻],B11,Work[船名],C11,Work[バース],E11,Work[入出・転],F11,Work[曳船名],G11)>1,"要確認：同じ作業・曳船が重複",IF(AND(I11="あり",J11="実施",NOT(ISNUMBER(AD11))),"要確認：拘束時間未確認",IF(OR(H11="未確認",I11="未確認",J11="未確認",X11="未確認",N11="未確認",O11="未確認"),"要確認：未確認を含む","確認済"))))))))))
Z12: =IF(G12="","",IF(COUNTIF(Tugs[曳船名],G12)<>1,"未登録・重複",IF(INDEX(Tugs[会社名],MATCH(G12,Tugs[曳船名],0))="","未確認",INDEX(Tugs[会社名],MATCH(G12,Tugs[曳船名],0))))) | AA12: =IF(G12="","",IF(COUNTIF(Companies[会社名],Z12)<>1,"未登録・重複",IF(INDEX(Companies[地区],MATCH(Z12,Companies[会社名],0))="","未確認",INDEX(Companies[地区],MATCH(Z12,Companies[会社名],0))))) | AB12: =IF(G12="","",IF(Q12<>"",Q12,IF(COUNTIF(Tugs[曳船名],G12)<>1,"未登録・重複",IF(INDEX(Tugs[基地港],MATCH(G12,Tugs[曳船名],0))="","未確認",INDEX(Tugs[基地港],MATCH(G12,Tugs[曳船名],0)))))) | AC12: =IF(C12="","",IF(AND(COUNTIF(Standards[照合項目（自動）],AB12&"｜"&E12&"｜"&D12&"｜"&F12&"｜"&P12)=1,COUNTIFS(Standards[照合項目（自動）],AB12&"｜"&E12&"｜"&D12&"｜"&F12&"｜"&P12,Standards[入力確認（自動）],"確認済")=1),SUMIF(Standards[照合項目（自動）],AB12&"｜"&E12&"｜"&D12&"｜"&F12&"｜"&P12,Standards[所定合計h（自動）]),"未確認")) | AD12: =IF(C12="","",IF(AND(ISNUMBER(R12),ISNUMBER(S12),S12>=R12),ROUND((S12-R12)*24,4),IF(OR(R12<>"",S12<>""),"",IF(AND(ISNUMBER(T12),T12>=0),T12,IF(AND(I12="あり",J12="実施",ISNUMBER(AC12)),AC12,""))))) | AE12: =IF(C12="","",IF(AND(ISNUMBER(R12),ISNUMBER(S12),S12>=R12),IF(X12="記録","実績：基地発～基地着",IF(X12="記憶","記憶：基地発～基地着","未確認：基地発～基地着")),IF(OR(R12<>"",S12<>""),"要確認：時刻不足・逆転",IF(AND(ISNUMBER(T12),T12>=0),IF(X12="記録","実績：記録の時間",IF(X12="記憶","記憶：申告の時間","未確認：申告の時間")),IF(AND(I12="あり",J12="実施",ISNUMBER(AC12)),"所定時間による見込み",IF(I12="なし","使用なし","未確認")))))) | AF12: =IF(C12="","",IF(H12="あり",1,0)) | AG12: =IF(C12="","",IF(AND(I12="あり",J12="実施"),1,0)) | AH12: =IF(C12="","",IF(AND(H12="あり",X12="記録"),IF(COUNTIFS($A$8:A12,A12,$B$8:B12,B12,$C$8:C12,C12,$E$8:E12,E12,$F$8:F12,F12,$H$8:H12,"あり",$X$8:X12,"記録")=1,1,0),0)) | AI12: =IF(C12="","",IF(AND(I12="あり",J12="実施",X12="記録",ISNUMBER(K12)),IF(COUNTIFS($K$8:K12,K12,$C$8:C12,C12,$E$8:E12,E12,$F$8:F12,F12,$I$8:I12,"あり",$J$8:J12,"実施",$X$8:X12,"記録")=1,1,0),0)) | AJ12: =IF(C12="","",IF(ISNUMBER(A12),YEAR(A12)-IF(MONTH(A12)<4,1,0),"")) | AK12: =IF(C12="","",IF(J12="実施",IF(ISNUMBER(K12),YEAR(K12)-IF(MONTH(K12)<4,1,0),""),"")) | AL12: =IF(C12="",IF(OR(A12<>"",G12<>""),"要確認：船名未記入",""),IF(OR(NOT(ISNUMBER(A12)),G12="",H12="",I12="",J12="",N12="",O12="",P12="",W12="",X12=""),"要確認：基本項目不足",IF(OR(Z12="未登録・重複",AA12="未登録・重複",AB12="未確認"),"要確認：登録表を確認",IF(AND(H12="あり",NOT(ISNUMBER(B12))),"要確認：前日の予定時刻不足",IF(AND(J12="実施",I12="あり",NOT(ISNUMBER(K12))),"要確認：最終日時不足",IF(AND(J12="取消",I12="あり"),"要確認：取消と使用ありが矛盾",IF(OR(AND(ISNUMBER(T12),T12<0),AND(ISNUMBER(V12),V12<0),AE12="要確認：時刻不足・逆転"),"要確認：時間を確認",IF(COUNTIFS(Work[予定表の作業日],A12,Work[前日版の予定時刻],B12,Work[船名],C12,Work[バース],E12,Work[入出・転],F12,Work[曳船名],G12)>1,"要確認：同じ作業・曳船が重複",IF(AND(I12="あり",J12="実施",NOT(ISNUMBER(AD12))),"要確認：拘束時間未確認",IF(OR(H12="未確認",I12="未確認",J12="未確認",X12="未確認",N12="未確認",O12="未確認"),"要確認：未確認を含む","確認済"))))))))))
Z13: =IF(G13="","",IF(COUNTIF(Tugs[曳船名],G13)<>1,"未登録・重複",IF(INDEX(Tugs[会社名],MATCH(G13,Tugs[曳船名],0))="","未確認",INDEX(Tugs[会社名],MATCH(G13,Tugs[曳船名],0))))) | AA13: =IF(G13="","",IF(COUNTIF(Companies[会社名],Z13)<>1,"未登録・重複",IF(INDEX(Companies[地区],MATCH(Z13,Companies[会社名],0))="","未確認",INDEX(Companies[地区],MATCH(Z13,Companies[会社名],0))))) | AB13: =IF(G13="","",IF(Q13<>"",Q13,IF(COUNTIF(Tugs[曳船名],G13)<>1,"未登録・重複",IF(INDEX(Tugs[基地港],MATCH(G13,Tugs[曳船名],0))="","未確認",INDEX(Tugs[基地港],MATCH(G13,Tugs[曳船名],0)))))) | AC13: =IF(C13="","",IF(AND(COUNTIF(Standards[照合項目（自動）],AB13&"｜"&E13&"｜"&D13&"｜"&F13&"｜"&P13)=1,COUNTIFS(Standards[照合項目（自動）],AB13&"｜"&E13&"｜"&D13&"｜"&F13&"｜"&P13,Standards[入力確認（自動）],"確認済")=1),SUMIF(Standards[照合項目（自動）],AB13&"｜"&E13&"｜"&D13&"｜"&F13&"｜"&P13,Standards[所定合計h（自動）]),"未確認")) | AD13: =IF(C13="","",IF(AND(ISNUMBER(R13),ISNUMBER(S13),S13>=R13),ROUND((S13-R13)*24,4),IF(OR(R13<>"",S13<>""),"",IF(AND(ISNUMBER(T13),T13>=0),T13,IF(AND(I13="あり",J13="実施",ISNUMBER(AC13)),AC13,""))))) | AE13: =IF(C13="","",IF(AND(ISNUMBER(R13),ISNUMBER(S13),S13>=R13),IF(X13="記録","実績：基地発～基地着",IF(X13="記憶","記憶：基地発～基地着","未確認：基地発～基地着")),IF(OR(R13<>"",S13<>""),"要確認：時刻不足・逆転",IF(AND(ISNUMBER(T13),T13>=0),IF(X13="記録","実績：記録の時間",IF(X13="記憶","記憶：申告の時間","未確認：申告の時間")),IF(AND(I13="あり",J13="実施",ISNUMBER(AC13)),"所定時間による見込み",IF(I13="なし","使用なし","未確認")))))) | AF13: =IF(C13="","",IF(H13="あり",1,0)) | AG13: =IF(C13="","",IF(AND(I13="あり",J13="実施"),1,0)) | AH13: =IF(C13="","",IF(AND(H13="あり",X13="記録"),IF(COUNTIFS($A$8:A13,A13,$B$8:B13,B13,$C$8:C13,C13,$E$8:E13,E13,$F$8:F13,F13,$H$8:H13,"あり",$X$8:X13,"記録")=1,1,0),0)) | AI13: =IF(C13="","",IF(AND(I13="あり",J13="実施",X13="記録",ISNUMBER(K13)),IF(COUNTIFS($K$8:K13,K13,$C$8:C13,C13,$E$8:E13,E13,$F$8:F13,F13,$I$8:I13,"あり",$J$8:J13,"実施",$X$8:X13,"記録")=1,1,0),0)) | AJ13: =IF(C13="","",IF(ISNUMBER(A13),YEAR(A13)-IF(MONTH(A13)<4,1,0),"")) | AK13: =IF(C13="","",IF(J13="実施",IF(ISNUMBER(K13),YEAR(K13)-IF(MONTH(K13)<4,1,0),""),"")) | AL13: =IF(C13="",IF(OR(A13<>"",G13<>""),"要確認：船名未記入",""),IF(OR(NOT(ISNUMBER(A13)),G13="",H13="",I13="",J13="",N13="",O13="",P13="",W13="",X13=""),"要確認：基本項目不足",IF(OR(Z13="未登録・重複",AA13="未登録・重複",AB13="未確認"),"要確認：登録表を確認",IF(AND(H13="あり",NOT(ISNUMBER(B13))),"要確認：前日の予定時刻不足",IF(AND(J13="実施",I13="あり",NOT(ISNUMBER(K13))),"要確認：最終日時不足",IF(AND(J13="取消",I13="あり"),"要確認：取消と使用ありが矛盾",IF(OR(AND(ISNUMBER(T13),T13<0),AND(ISNUMBER(V13),V13<0),AE13="要確認：時刻不足・逆転"),"要確認：時間を確認",IF(COUNTIFS(Work[予定表の作業日],A13,Work[前日版の予定時刻],B13,Work[船名],C13,Work[バース],E13,Work[入出・転],F13,Work[曳船名],G13)>1,"要確認：同じ作業・曳船が重複",IF(AND(I13="あり",J13="実施",NOT(ISNUMBER(AD13))),"要確認：拘束時間未確認",IF(OR(H13="未確認",I13="未確認",J13="未確認",X13="未確認",N13="未確認",O13="未確認"),"要確認：未確認を含む","確認済"))))))))))
Z14: =IF(G14="","",IF(COUNTIF(Tugs[曳船名],G14)<>1,"未登録・重複",IF(INDEX(Tugs[会社名],MATCH(G14,Tugs[曳船名],0))="","未確認",INDEX(Tugs[会社名],MATCH(G14,Tugs[曳船名],0))))) | AA14: =IF(G14="","",IF(COUNTIF(Companies[会社名],Z14)<>1,"未登録・重複",IF(INDEX(Companies[地区],MATCH(Z14,Companies[会社名],0))="","未確認",INDEX(Companies[地区],MATCH(Z14,Companies[会社名],0))))) | AB14: =IF(G14="","",IF(Q14<>"",Q14,IF(COUNTIF(Tugs[曳船名],G14)<>1,"未登録・重複",IF(INDEX(Tugs[基地港],MATCH(G14,Tugs[曳船名],0))="","未確認",INDEX(Tugs[基地港],MATCH(G14,Tugs[曳船名],0)))))) | AC14: =IF(C14="","",IF(AND(COUNTIF(Standards[照合項目（自動）],AB14&"｜"&E14&"｜"&D14&"｜"&F14&"｜"&P14)=1,COUNTIFS(Standards[照合項目（自動）],AB14&"｜"&E14&"｜"&D14&"｜"&F14&"｜"&P14,Standards[入力確認（自動）],"確認済")=1),SUMIF(Standards[照合項目（自動）],AB14&"｜"&E14&"｜"&D14&"｜"&F14&"｜"&P14,Standards[所定合計h（自動）]),"未確認")) | AD14: =IF(C14="","",IF(AND(ISNUMBER(R14),ISNUMBER(S14),S14>=R14),ROUND((S14-R14)*24,4),IF(OR(R14<>"",S14<>""),"",IF(AND(ISNUMBER(T14),T14>=0),T14,IF(AND(I14="あり",J14="実施",ISNUMBER(AC14)),AC14,""))))) | AE14: =IF(C14="","",IF(AND(ISNUMBER(R14),ISNUMBER(S14),S14>=R14),IF(X14="記録","実績：基地発～基地着",IF(X14="記憶","記憶：基地発～基地着","未確認：基地発～基地着")),IF(OR(R14<>"",S14<>""),"要確認：時刻不足・逆転",IF(AND(ISNUMBER(T14),T14>=0),IF(X14="記録","実績：記録の時間",IF(X14="記憶","記憶：申告の時間","未確認：申告の時間")),IF(AND(I14="あり",J14="実施",ISNUMBER(AC14)),"所定時間による見込み",IF(I14="なし","使用なし","未確認")))))) | AF14: =IF(C14="","",IF(H14="あり",1,0)) | AG14: =IF(C14="","",IF(AND(I14="あり",J14="実施"),1,0)) | AH14: =IF(C14="","",IF(AND(H14="あり",X14="記録"),IF(COUNTIFS($A$8:A14,A14,$B$8:B14,B14,$C$8:C14,C14,$E$8:E14,E14,$F$8:F14,F14,$H$8:H14,"あり",$X$8:X14,"記録")=1,1,0),0)) | AI14: =IF(C14="","",IF(AND(I14="あり",J14="実施",X14="記録",ISNUMBER(K14)),IF(COUNTIFS($K$8:K14,K14,$C$8:C14,C14,$E$8:E14,E14,$F$8:F14,F14,$I$8:I14,"あり",$J$8:J14,"実施",$X$8:X14,"記録")=1,1,0),0)) | AJ14: =IF(C14="","",IF(ISNUMBER(A14),YEAR(A14)-IF(MONTH(A14)<4,1,0),"")) | AK14: =IF(C14="","",IF(J14="実施",IF(ISNUMBER(K14),YEAR(K14)-IF(MONTH(K14)<4,1,0),""),"")) | AL14: =IF(C14="",IF(OR(A14<>"",G14<>""),"要確認：船名未記入",""),IF(OR(NOT(ISNUMBER(A14)),G14="",H14="",I14="",J14="",N14="",O14="",P14="",W14="",X14=""),"要確認：基本項目不足",IF(OR(Z14="未登録・重複",AA14="未登録・重複",AB14="未確認"),"要確認：登録表を確認",IF(AND(H14="あり",NOT(ISNUMBER(B14))),"要確認：前日の予定時刻不足",IF(AND(J14="実施",I14="あり",NOT(ISNUMBER(K14))),"要確認：最終日時不足",IF(AND(J14="取消",I14="あり"),"要確認：取消と使用ありが矛盾",IF(OR(AND(ISNUMBER(T14),T14<0),AND(ISNUMBER(V14),V14<0),AE14="要確認：時刻不足・逆転"),"要確認：時間を確認",IF(COUNTIFS(Work[予定表の作業日],A14,Work[前日版の予定時刻],B14,Work[船名],C14,Work[バース],E14,Work[入出・転],F14,Work[曳船名],G14)>1,"要確認：同じ作業・曳船が重複",IF(AND(I14="あり",J14="実施",NOT(ISNUMBER(AD14))),"要確認：拘束時間未確認",IF(OR(H14="未確認",I14="未確認",J14="未確認",X14="未確認",N14="未確認",O14="未確認"),"要確認：未確認を含む","確認済"))))))))))
Z15: =IF(G15="","",IF(COUNTIF(Tugs[曳船名],G15)<>1,"未登録・重複",IF(INDEX(Tugs[会社名],MATCH(G15,Tugs[曳船名],0))="","未確認",INDEX(Tugs[会社名],MATCH(G15,Tugs[曳船名],0))))) | AA15: =IF(G15="","",IF(COUNTIF(Companies[会社名],Z15)<>1,"未登録・重複",IF(INDEX(Companies[地区],MATCH(Z15,Companies[会社名],0))="","未確認",INDEX(Companies[地区],MATCH(Z15,Companies[会社名],0))))) | AB15: =IF(G15="","",IF(Q15<>"",Q15,IF(COUNTIF(Tugs[曳船名],G15)<>1,"未登録・重複",IF(INDEX(Tugs[基地港],MATCH(G15,Tugs[曳船名],0))="","未確認",INDEX(Tugs[基地港],MATCH(G15,Tugs[曳船名],0)))))) | AC15: =IF(C15="","",IF(AND(COUNTIF(Standards[照合項目（自動）],AB15&"｜"&E15&"｜"&D15&"｜"&F15&"｜"&P15)=1,COUNTIFS(Standards[照合項目（自動）],AB15&"｜"&E15&"｜"&D15&"｜"&F15&"｜"&P15,Standards[入力確認（自動）],"確認済")=1),SUMIF(Standards[照合項目（自動）],AB15&"｜"&E15&"｜"&D15&"｜"&F15&"｜"&P15,Standards[所定合計h（自動）]),"未確認")) | AD15: =IF(C15="","",IF(AND(ISNUMBER(R15),ISNUMBER(S15),S15>=R15),ROUND((S15-R15)*24,4),IF(OR(R15<>"",S15<>""),"",IF(AND(ISNUMBER(T15),T15>=0),T15,IF(AND(I15="あり",J15="実施",ISNUMBER(AC15)),AC15,""))))) | AE15: =IF(C15="","",IF(AND(ISNUMBER(R15),ISNUMBER(S15),S15>=R15),IF(X15="記録","実績：基地発～基地着",IF(X15="記憶","記憶：基地発～基地着","未確認：基地発～基地着")),IF(OR(R15<>"",S15<>""),"要確認：時刻不足・逆転",IF(AND(ISNUMBER(T15),T15>=0),IF(X15="記録","実績：記録の時間",IF(X15="記憶","記憶：申告の時間","未確認：申告の時間")),IF(AND(I15="あり",J15="実施",ISNUMBER(AC15)),"所定時間による見込み",IF(I15="なし","使用なし","未確認")))))) | AF15: =IF(C15="","",IF(H15="あり",1,0)) | AG15: =IF(C15="","",IF(AND(I15="あり",J15="実施"),1,0)) | AH15: =IF(C15="","",IF(AND(H15="あり",X15="記録"),IF(COUNTIFS($A$8:A15,A15,$B$8:B15,B15,$C$8:C15,C15,$E$8:E15,E15,$F$8:F15,F15,$H$8:H15,"あり",$X$8:X15,"記録")=1,1,0),0)) | AI15: =IF(C15="","",IF(AND(I15="あり",J15="実施",X15="記録",ISNUMBER(K15)),IF(COUNTIFS($K$8:K15,K15,$C$8:C15,C15,$E$8:E15,E15,$F$8:F15,F15,$I$8:I15,"あり",$J$8:J15,"実施",$X$8:X15,"記録")=1,1,0),0)) | AJ15: =IF(C15="","",IF(ISNUMBER(A15),YEAR(A15)-IF(MONTH(A15)<4,1,0),"")) | AK15: =IF(C15="","",IF(J15="実施",IF(ISNUMBER(K15),YEAR(K15)-IF(MONTH(K15)<4,1,0),""),"")) | AL15: =IF(C15="",IF(OR(A15<>"",G15<>""),"要確認：船名未記入",""),IF(OR(NOT(ISNUMBER(A15)),G15="",H15="",I15="",J15="",N15="",O15="",P15="",W15="",X15=""),"要確認：基本項目不足",IF(OR(Z15="未登録・重複",AA15="未登録・重複",AB15="未確認"),"要確認：登録表を確認",IF(AND(H15="あり",NOT(ISNUMBER(B15))),"要確認：前日の予定時刻不足",IF(AND(J15="実施",I15="あり",NOT(ISNUMBER(K15))),"要確認：最終日時不足",IF(AND(J15="取消",I15="あり"),"要確認：取消と使用ありが矛盾",IF(OR(AND(ISNUMBER(T15),T15<0),AND(ISNUMBER(V15),V15<0),AE15="要確認：時刻不足・逆転"),"要確認：時間を確認",IF(COUNTIFS(Work[予定表の作業日],A15,Work[前日版の予定時刻],B15,Work[船名],C15,Work[バース],E15,Work[入出・転],F15,Work[曳船名],G15)>1,"要確認：同じ作業・曳船が重複",IF(AND(I15="あり",J15="実施",NOT(ISNUMBER(AD15))),"要確認：拘束時間未確認",IF(OR(H15="未確認",I15="未確認",J15="未確認",X15="未確認",N15="未確認",O15="未確認"),"要確認：未確認を含む","確認済"))))))))))
Z16: =IF(G16="","",IF(COUNTIF(Tugs[曳船名],G16)<>1,"未登録・重複",IF(INDEX(Tugs[会社名],MATCH(G16,Tugs[曳船名],0))="","未確認",INDEX(Tugs[会社名],MATCH(G16,Tugs[曳船名],0))))) | AA16: =IF(G16="","",IF(COUNTIF(Companies[会社名],Z16)<>1,"未登録・重複",IF(INDEX(Companies[地区],MATCH(Z16,Companies[会社名],0))="","未確認",INDEX(Companies[地区],MATCH(Z16,Companies[会社名],0))))) | AB16: =IF(G16="","",IF(Q16<>"",Q16,IF(COUNTIF(Tugs[曳船名],G16)<>1,"未登録・重複",IF(INDEX(Tugs[基地港],MATCH(G16,Tugs[曳船名],0))="","未確認",INDEX(Tugs[基地港],MATCH(G16,Tugs[曳船名],0)))))) | AC16: =IF(C16="","",IF(AND(COUNTIF(Standards[照合項目（自動）],AB16&"｜"&E16&"｜"&D16&"｜"&F16&"｜"&P16)=1,COUNTIFS(Standards[照合項目（自動）],AB16&"｜"&E16&"｜"&D16&"｜"&F16&"｜"&P16,Standards[入力確認（自動）],"確認済")=1),SUMIF(Standards[照合項目（自動）],AB16&"｜"&E16&"｜"&D16&"｜"&F16&"｜"&P16,Standards[所定合計h（自動）]),"未確認")) | AD16: =IF(C16="","",IF(AND(ISNUMBER(R16),ISNUMBER(S16),S16>=R16),ROUND((S16-R16)*24,4),IF(OR(R16<>"",S16<>""),"",IF(AND(ISNUMBER(T16),T16>=0),T16,IF(AND(I16="あり",J16="実施",ISNUMBER(AC16)),AC16,""))))) | AE16: =IF(C16="","",IF(AND(ISNUMBER(R16),ISNUMBER(S16),S16>=R16),IF(X16="記録","実績：基地発～基地着",IF(X16="記憶","記憶：基地発～基地着","未確認：基地発～基地着")),IF(OR(R16<>"",S16<>""),"要確認：時刻不足・逆転",IF(AND(ISNUMBER(T16),T16>=0),IF(X16="記録","実績：記録の時間",IF(X16="記憶","記憶：申告の時間","未確認：申告の時間")),IF(AND(I16="あり",J16="実施",ISNUMBER(AC16)),"所定時間による見込み",IF(I16="なし","使用なし","未確認")))))) | AF16: =IF(C16="","",IF(H16="あり",1,0)) | AG16: =IF(C16="","",IF(AND(I16="あり",J16="実施"),1,0)) | AH16: =IF(C16="","",IF(AND(H16="あり",X16="記録"),IF(COUNTIFS($A$8:A16,A16,$B$8:B16,B16,$C$8:C16,C16,$E$8:E16,E16,$F$8:F16,F16,$H$8:H16,"あり",$X$8:X16,"記録")=1,1,0),0)) | AI16: =IF(C16="","",IF(AND(I16="あり",J16="実施",X16="記録",ISNUMBER(K16)),IF(COUNTIFS($K$8:K16,K16,$C$8:C16,C16,$E$8:E16,E16,$F$8:F16,F16,$I$8:I16,"あり",$J$8:J16,"実施",$X$8:X16,"記録")=1,1,0),0)) | AJ16: =IF(C16="","",IF(ISNUMBER(A16),YEAR(A16)-IF(MONTH(A16)<4,1,0),"")) | AK16: =IF(C16="","",IF(J16="実施",IF(ISNUMBER(K16),YEAR(K16)-IF(MONTH(K16)<4,1,0),""),"")) | AL16: =IF(C16="",IF(OR(A16<>"",G16<>""),"要確認：船名未記入",""),IF(OR(NOT(ISNUMBER(A16)),G16="",H16="",I16="",J16="",N16="",O16="",P16="",W16="",X16=""),"要確認：基本項目不足",IF(OR(Z16="未登録・重複",AA16="未登録・重複",AB16="未確認"),"要確認：登録表を確認",IF(AND(H16="あり",NOT(ISNUMBER(B16))),"要確認：前日の予定時刻不足",IF(AND(J16="実施",I16="あり",NOT(ISNUMBER(K16))),"要確認：最終日時不足",IF(AND(J16="取消",I16="あり"),"要確認：取消と使用ありが矛盾",IF(OR(AND(ISNUMBER(T16),T16<0),AND(ISNUMBER(V16),V16<0),AE16="要確認：時刻不足・逆転"),"要確認：時間を確認",IF(COUNTIFS(Work[予定表の作業日],A16,Work[前日版の予定時刻],B16,Work[船名],C16,Work[バース],E16,Work[入出・転],F16,Work[曳船名],G16)>1,"要確認：同じ作業・曳船が重複",IF(AND(I16="あり",J16="実施",NOT(ISNUMBER(AD16))),"要確認：拘束時間未確認",IF(OR(H16="未確認",I16="未確認",J16="未確認",X16="未確認",N16="未確認",O16="未確認"),"要確認：未確認を含む","確認済"))))))))))
Z17: =IF(G17="","",IF(COUNTIF(Tugs[曳船名],G17)<>1,"未登録・重複",IF(INDEX(Tugs[会社名],MATCH(G17,Tugs[曳船名],0))="","未確認",INDEX(Tugs[会社名],MATCH(G17,Tugs[曳船名],0))))) | AA17: =IF(G17="","",IF(COUNTIF(Companies[会社名],Z17)<>1,"未登録・重複",IF(INDEX(Companies[地区],MATCH(Z17,Companies[会社名],0))="","未確認",INDEX(Companies[地区],MATCH(Z17,Companies[会社名],0))))) | AB17: =IF(G17="","",IF(Q17<>"",Q17,IF(COUNTIF(Tugs[曳船名],G17)<>1,"未登録・重複",IF(INDEX(Tugs[基地港],MATCH(G17,Tugs[曳船名],0))="","未確認",INDEX(Tugs[基地港],MATCH(G17,Tugs[曳船名],0)))))) | AC17: =IF(C17="","",IF(AND(COUNTIF(Standards[照合項目（自動）],AB17&"｜"&E17&"｜"&D17&"｜"&F17&"｜"&P17)=1,COUNTIFS(Standards[照合項目（自動）],AB17&"｜"&E17&"｜"&D17&"｜"&F17&"｜"&P17,Standards[入力確認（自動）],"確認済")=1),SUMIF(Standards[照合項目（自動）],AB17&"｜"&E17&"｜"&D17&"｜"&F17&"｜"&P17,Standards[所定合計h（自動）]),"未確認")) | AD17: =IF(C17="","",IF(AND(ISNUMBER(R17),ISNUMBER(S17),S17>=R17),ROUND((S17-R17)*24,4),IF(OR(R17<>"",S17<>""),"",IF(AND(ISNUMBER(T17),T17>=0),T17,IF(AND(I17="あり",J17="実施",ISNUMBER(AC17)),AC17,""))))) | AE17: =IF(C17="","",IF(AND(ISNUMBER(R17),ISNUMBER(S17),S17>=R17),IF(X17="記録","実績：基地発～基地着",IF(X17="記憶","記憶：基地発～基地着","未確認：基地発～基地着")),IF(OR(R17<>"",S17<>""),"要確認：時刻不足・逆転",IF(AND(ISNUMBER(T17),T17>=0),IF(X17="記録","実績：記録の時間",IF(X17="記憶","記憶：申告の時間","未確認：申告の時間")),IF(AND(I17="あり",J17="実施",ISNUMBER(AC17)),"所定時間による見込み",IF(I17="なし","使用なし","未確認")))))) | AF17: =IF(C17="","",IF(H17="あり",1,0)) | AG17: =IF(C17="","",IF(AND(I17="あり",J17="実施"),1,0)) | AH17: =IF(C17="","",IF(AND(H17="あり",X17="記録"),IF(COUNTIFS($A$8:A17,A17,$B$8:B17,B17,$C$8:C17,C17,$E$8:E17,E17,$F$8:F17,F17,$H$8:H17,"あり",$X$8:X17,"記録")=1,1,0),0)) | AI17: =IF(C17="","",IF(AND(I17="あり",J17="実施",X17="記録",ISNUMBER(K17)),IF(COUNTIFS($K$8:K17,K17,$C$8:C17,C17,$E$8:E17,E17,$F$8:F17,F17,$I$8:I17,"あり",$J$8:J17,"実施",$X$8:X17,"記録")=1,1,0),0)) | AJ17: =IF(C17="","",IF(ISNUMBER(A17),YEAR(A17)-IF(MONTH(A17)<4,1,0),"")) | AK17: =IF(C17="","",IF(J17="実施",IF(ISNUMBER(K17),YEAR(K17)-IF(MONTH(K17)<4,1,0),""),"")) | AL17: =IF(C17="",IF(OR(A17<>"",G17<>""),"要確認：船名未記入",""),IF(OR(NOT(ISNUMBER(A17)),G17="",H17="",I17="",J17="",N17="",O17="",P17="",W17="",X17=""),"要確認：基本項目不足",IF(OR(Z17="未登録・重複",AA17="未登録・重複",AB17="未確認"),"要確認：登録表を確認",IF(AND(H17="あり",NOT(ISNUMBER(B17))),"要確認：前日の予定時刻不足",IF(AND(J17="実施",I17="あり",NOT(ISNUMBER(K17))),"要確認：最終日時不足",IF(AND(J17="取消",I17="あり"),"要確認：取消と使用ありが矛盾",IF(OR(AND(ISNUMBER(T17),T17<0),AND(ISNUMBER(V17),V17<0),AE17="要確認：時刻不足・逆転"),"要確認：時間を確認",IF(COUNTIFS(Work[予定表の作業日],A17,Work[前日版の予定時刻],B17,Work[船名],C17,Work[バース],E17,Work[入出・転],F17,Work[曳船名],G17)>1,"要確認：同じ作業・曳船が重複",IF(AND(I17="あり",J17="実施",NOT(ISNUMBER(AD17))),"要確認：拘束時間未確認",IF(OR(H17="未確認",I17="未確認",J17="未確認",X17="未確認",N17="未確認",O17="未確認"),"要確認：未確認を含む","確認済"))))))))))
Z18: =IF(G18="","",IF(COUNTIF(Tugs[曳船名],G18)<>1,"未登録・重複",IF(INDEX(Tugs[会社名],MATCH(G18,Tugs[曳船名],0))="","未確認",INDEX(Tugs[会社名],MATCH(G18,Tugs[曳船名],0))))) | AA18: =IF(G18="","",IF(COUNTIF(Companies[会社名],Z18)<>1,"未登録・重複",IF(INDEX(Companies[地区],MATCH(Z18,Companies[会社名],0))="","未確認",INDEX(Companies[地区],MATCH(Z18,Companies[会社名],0))))) | AB18: =IF(G18="","",IF(Q18<>"",Q18,IF(COUNTIF(Tugs[曳船名],G18)<>1,"未登録・重複",IF(INDEX(Tugs[基地港],MATCH(G18,Tugs[曳船名],0))="","未確認",INDEX(Tugs[基地港],MATCH(G18,Tugs[曳船名],0)))))) | AC18: =IF(C18="","",IF(AND(COUNTIF(Standards[照合項目（自動）],AB18&"｜"&E18&"｜"&D18&"｜"&F18&"｜"&P18)=1,COUNTIFS(Standards[照合項目（自動）],AB18&"｜"&E18&"｜"&D18&"｜"&F18&"｜"&P18,Standards[入力確認（自動）],"確認済")=1),SUMIF(Standards[照合項目（自動）],AB18&"｜"&E18&"｜"&D18&"｜"&F18&"｜"&P18,Standards[所定合計h（自動）]),"未確認")) | AD18: =IF(C18="","",IF(AND(ISNUMBER(R18),ISNUMBER(S18),S18>=R18),ROUND((S18-R18)*24,4),IF(OR(R18<>"",S18<>""),"",IF(AND(ISNUMBER(T18),T18>=0),T18,IF(AND(I18="あり",J18="実施",ISNUMBER(AC18)),AC18,""))))) | AE18: =IF(C18="","",IF(AND(ISNUMBER(R18),ISNUMBER(S18),S18>=R18),IF(X18="記録","実績：基地発～基地着",IF(X18="記憶","記憶：基地発～基地着","未確認：基地発～基地着")),IF(OR(R18<>"",S18<>""),"要確認：時刻不足・逆転",IF(AND(ISNUMBER(T18),T18>=0),IF(X18="記録","実績：記録の時間",IF(X18="記憶","記憶：申告の時間","未確認：申告の時間")),IF(AND(I18="あり",J18="実施",ISNUMBER(AC18)),"所定時間による見込み",IF(I18="なし","使用なし","未確認")))))) | AF18: =IF(C18="","",IF(H18="あり",1,0)) | AG18: =IF(C18="","",IF(AND(I18="あり",J18="実施"),1,0)) | AH18: =IF(C18="","",IF(AND(H18="あり",X18="記録"),IF(COUNTIFS($A$8:A18,A18,$B$8:B18,B18,$C$8:C18,C18,$E$8:E18,E18,$F$8:F18,F18,$H$8:H18,"あり",$X$8:X18,"記録")=1,1,0),0)) | AI18: =IF(C18="","",IF(AND(I18="あり",J18="実施",X18="記録",ISNUMBER(K18)),IF(COUNTIFS($K$8:K18,K18,$C$8:C18,C18,$E$8:E18,E18,$F$8:F18,F18,$I$8:I18,"あり",$J$8:J18,"実施",$X$8:X18,"記録")=1,1,0),0)) | AJ18: =IF(C18="","",IF(ISNUMBER(A18),YEAR(A18)-IF(MONTH(A18)<4,1,0),"")) | AK18: =IF(C18="","",IF(J18="実施",IF(ISNUMBER(K18),YEAR(K18)-IF(MONTH(K18)<4,1,0),""),"")) | AL18: =IF(C18="",IF(OR(A18<>"",G18<>""),"要確認：船名未記入",""),IF(OR(NOT(ISNUMBER(A18)),G18="",H18="",I18="",J18="",N18="",O18="",P18="",W18="",X18=""),"要確認：基本項目不足",IF(OR(Z18="未登録・重複",AA18="未登録・重複",AB18="未確認"),"要確認：登録表を確認",IF(AND(H18="あり",NOT(ISNUMBER(B18))),"要確認：前日の予定時刻不足",IF(AND(J18="実施",I18="あり",NOT(ISNUMBER(K18))),"要確認：最終日時不足",IF(AND(J18="取消",I18="あり"),"要確認：取消と使用ありが矛盾",IF(OR(AND(ISNUMBER(T18),T18<0),AND(ISNUMBER(V18),V18<0),AE18="要確認：時刻不足・逆転"),"要確認：時間を確認",IF(COUNTIFS(Work[予定表の作業日],A18,Work[前日版の予定時刻],B18,Work[船名],C18,Work[バース],E18,Work[入出・転],F18,Work[曳船名],G18)>1,"要確認：同じ作業・曳船が重複",IF(AND(I18="あり",J18="実施",NOT(ISNUMBER(AD18))),"要確認：拘束時間未確認",IF(OR(H18="未確認",I18="未確認",J18="未確認",X18="未確認",N18="未確認",O18="未確認"),"要確認：未確認を含む","確認済"))))))))))
Z19: =IF(G19="","",IF(COUNTIF(Tugs[曳船名],G19)<>1,"未登録・重複",IF(INDEX(Tugs[会社名],MATCH(G19,Tugs[曳船名],0))="","未確認",INDEX(Tugs[会社名],MATCH(G19,Tugs[曳船名],0))))) | AA19: =IF(G19="","",IF(COUNTIF(Companies[会社名],Z19)<>1,"未登録・重複",IF(INDEX(Companies[地区],MATCH(Z19,Companies[会社名],0))="","未確認",INDEX(Companies[地区],MATCH(Z19,Companies[会社名],0))))) | AB19: =IF(G19="","",IF(Q19<>"",Q19,IF(COUNTIF(Tugs[曳船名],G19)<>1,"未登録・重複",IF(INDEX(Tugs[基地港],MATCH(G19,Tugs[曳船名],0))="","未確認",INDEX(Tugs[基地港],MATCH(G19,Tugs[曳船名],0)))))) | AC19: =IF(C19="","",IF(AND(COUNTIF(Standards[照合項目（自動）],AB19&"｜"&E19&"｜"&D19&"｜"&F19&"｜"&P19)=1,COUNTIFS(Standards[照合項目（自動）],AB19&"｜"&E19&"｜"&D19&"｜"&F19&"｜"&P19,Standards[入力確認（自動）],"確認済")=1),SUMIF(Standards[照合項目（自動）],AB19&"｜"&E19&"｜"&D19&"｜"&F19&"｜"&P19,Standards[所定合計h（自動）]),"未確認")) | AD19: =IF(C19="","",IF(AND(ISNUMBER(R19),ISNUMBER(S19),S19>=R19),ROUND((S19-R19)*24,4),IF(OR(R19<>"",S19<>""),"",IF(AND(ISNUMBER(T19),T19>=0),T19,IF(AND(I19="あり",J19="実施",ISNUMBER(AC19)),AC19,""))))) | AE19: =IF(C19="","",IF(AND(ISNUMBER(R19),ISNUMBER(S19),S19>=R19),IF(X19="記録","実績：基地発～基地着",IF(X19="記憶","記憶：基地発～基地着","未確認：基地発～基地着")),IF(OR(R19<>"",S19<>""),"要確認：時刻不足・逆転",IF(AND(ISNUMBER(T19),T19>=0),IF(X19="記録","実績：記録の時間",IF(X19="記憶","記憶：申告の時間","未確認：申告の時間")),IF(AND(I19="あり",J19="実施",ISNUMBER(AC19)),"所定時間による見込み",IF(I19="なし","使用なし","未確認")))))) | AF19: =IF(C19="","",IF(H19="あり",1,0)) | AG19: =IF(C19="","",IF(AND(I19="あり",J19="実施"),1,0)) | AH19: =IF(C19="","",IF(AND(H19="あり",X19="記録"),IF(COUNTIFS($A$8:A19,A19,$B$8:B19,B19,$C$8:C19,C19,$E$8:E19,E19,$F$8:F19,F19,$H$8:H19,"あり",$X$8:X19,"記録")=1,1,0),0)) | AI19: =IF(C19="","",IF(AND(I19="あり",J19="実施",X19="記録",ISNUMBER(K19)),IF(COUNTIFS($K$8:K19,K19,$C$8:C19,C19,$E$8:E19,E19,$F$8:F19,F19,$I$8:I19,"あり",$J$8:J19,"実施",$X$8:X19,"記録")=1,1,0),0)) | AJ19: =IF(C19="","",IF(ISNUMBER(A19),YEAR(A19)-IF(MONTH(A19)<4,1,0),"")) | AK19: =IF(C19="","",IF(J19="実施",IF(ISNUMBER(K19),YEAR(K19)-IF(MONTH(K19)<4,1,0),""),"")) | AL19: =IF(C19="",IF(OR(A19<>"",G19<>""),"要確認：船名未記入",""),IF(OR(NOT(ISNUMBER(A19)),G19="",H19="",I19="",J19="",N19="",O19="",P19="",W19="",X19=""),"要確認：基本項目不足",IF(OR(Z19="未登録・重複",AA19="未登録・重複",AB19="未確認"),"要確認：登録表を確認",IF(AND(H19="あり",NOT(ISNUMBER(B19))),"要確認：前日の予定時刻不足",IF(AND(J19="実施",I19="あり",NOT(ISNUMBER(K19))),"要確認：最終日時不足",IF(AND(J19="取消",I19="あり"),"要確認：取消と使用ありが矛盾",IF(OR(AND(ISNUMBER(T19),T19<0),AND(ISNUMBER(V19),V19<0),AE19="要確認：時刻不足・逆転"),"要確認：時間を確認",IF(COUNTIFS(Work[予定表の作業日],A19,Work[前日版の予定時刻],B19,Work[船名],C19,Work[バース],E19,Work[入出・転],F19,Work[曳船名],G19)>1,"要確認：同じ作業・曳船が重複",IF(AND(I19="あり",J19="実施",NOT(ISNUMBER(AD19))),"要確認：拘束時間未確認",IF(OR(H19="未確認",I19="未確認",J19="未確認",X19="未確認",N19="未確認",O19="未確認"),"要確認：未確認を含む","確認済"))))))))))
... Z1007: =IF(G1007="","",IF(COUNTIF(Tugs[曳船名],G1007)<>1,"未登録・重複",IF(INDEX(Tugs[会社名],MATCH(G1007,Tugs[曳船名],0))="","未確認",INDEX(Tugs[会社名],MATCH(G1007,Tugs[曳船名],0))))) | AA1007: =IF(G1007="","",IF(COUNTIF(Companies[会社名],Z1007)<>1,"未登録・重複",IF(INDEX(Companies[地区],MATCH(Z1007,Companies[会社名],0))="","未確認",INDEX(Companies[地区],MATCH(Z1007,Companies[会社名],0))))) | AB1007: =IF(G1007="","",IF(Q1007<>"",Q1007,IF(COUNTIF(Tugs[曳船名],G1007)<>1,"未登録・重複",IF(INDEX(Tugs[基地港],MATCH(G1007,Tugs[曳船名],0))="","未確認",INDEX(Tugs[基地港],MATCH(G1007,Tugs[曳船名],0)))))) | AC1007: =IF(C1007="","",IF(AND(COUNTIF(Standards[照合項目（自動）],AB1007&"｜"&E1007&"｜"&D1007&"｜"&F1007&"｜"&P1007)=1,COUNTIFS(Standards[照合項目（自動）],AB1007&"｜"&E1007&"｜"&D1007&"｜"&F1007&"｜"&P1007,Standards[入力確認（自動）],"確認済")=1),SUMIF(Standards[照合項目（自動）],AB1007&"｜"&E1007&"｜"&D1007&"｜"&F1007&"｜"&P1007,Standards[所定合計h（自動）]),"未確認")) | AD1007: =IF(C1007="","",IF(AND(ISNUMBER(R1007),ISNUMBER(S1007),S1007>=R1007),ROUND((S1007-R1007)*24,4),IF(OR(R1007<>"",S1007<>""),"",IF(AND(ISNUMBER(T1007),T1007>=0),T1007,IF(AND(I1007="あり",J1007="実施",ISNUMBER(AC1007)),AC1007,""))))) | AE1007: =IF(C1007="","",IF(AND(ISNUMBER(R1007),ISNUMBER(S1007),S1007>=R1007),IF(X1007="記録","実績：基地発～基地着",IF(X1007="記憶","記憶：基地発～基地着","未確認：基地発～基地着")),IF(OR(R1007<>"",S1007<>""),"要確認：時刻不足・逆転",IF(AND(ISNUMBER(T1007),T1007>=0),IF(X1007="記録","実績：記録の時間",IF(X1007="記憶","記憶：申告の時間","未確認：申告の時間")),IF(AND(I1007="あり",J1007="実施",ISNUMBER(AC1007)),"所定時間による見込み",IF(I1007="なし","使用なし","未確認")))))) | AF1007: =IF(C1007="","",IF(H1007="あり",1,0)) | AG1007: =IF(C1007="","",IF(AND(I1007="あり",J1007="実施"),1,0)) | AH1007: =IF(C1007="","",IF(AND(H1007="あり",X1007="記録"),IF(COUNTIFS($A$8:A1007,A1007,$B$8:B1007,B1007,$C$8:C1007,C1007,$E$8:E1007,E1007,$F$8:F1007,F1007,$H$8:H1007,"あり",$X$8:X1007,"記録")=1,1,0),0)) | AI1007: =IF(C1007="","",IF(AND(I1007="あり",J1007="実施",X1007="記録",ISNUMBER(K1007)),IF(COUNTIFS($K$8:K1007,K1007,$C$8:C1007,C1007,$E$8:E1007,E1007,$F$8:F1007,F1007,$I$8:I1007,"あり",$J$8:J1007,"実施",$X$8:X1007,"記録")=1,1,0),0)) | AJ1007: =IF(C1007="","",IF(ISNUMBER(A1007),YEAR(A1007)-IF(MONTH(A1007)<4,1,0),"")) | AK1007: =IF(C1007="","",IF(J1007="実施",IF(ISNUMBER(K1007),YEAR(K1007)-IF(MONTH(K1007)<4,1,0),""),"")) | AL1007: =IF(C1007="",IF(OR(A1007<>"",G1007<>""),"要確認：船名未記入",""),IF(OR(NOT(ISNUMBER(A1007)),G1007="",H1007="",I1007="",J1007="",N1007="",O1007="",P1007="",W1007="",X1007=""),"要確認：基本項目不足",IF(OR(Z1007="未登録・重複",AA1007="未登録・重複",AB1007="未確認"),"要確認：登録表を確認",IF(AND(H1007="あり",NOT(ISNUMBER(B1007))),"要確認：前日の予定時刻不足",IF(AND(J1007="実施",I1007="あり",NOT(ISNUMBER(K1007))),"要確認：最終日時不足",IF(AND(J1007="取消",I1007="あり"),"要確認：取消と使用ありが矛盾",IF(OR(AND(ISNUMBER(T1007),T1007<0),AND(ISNUMBER(V1007),V1007<0),AE1007="要確認：時刻不足・逆転"),"要確認：時間を確認",IF(COUNTIFS(Work[予定表の作業日],A1007,Work[前日版の予定時刻],B1007,Work[船名],C1007,Work[バース],E1007,Work[入出・転],F1007,Work[曳船名],G1007)>1,"要確認：同じ作業・曳船が重複",IF(AND(I1007="あり",J1007="実施",NOT(ISNUMBER(AD1007))),"要確認：拘束時間未確認",IF(OR(H1007="未確認",I1007="未確認",J1007="未確認",X1007="未確認",N1007="未確認",O1007="未確認"),"要確認：未確認を含む","確認済"))))))))))

Sheet 入渠
A2: 入渠
A3: 製鉄曳船5隻と関豊丸・長豊丸が対象。復帰日は作業に戻った日。開始日から復帰日前日までを数える。年度をまたぐ入渠は選択年度に重なる日数だけ集計。
A7: 曳船名 | B7: 入渠開始日 | C7: 作業復帰日 | D7: 確認元 | E7: 記録区分 | F7: 補足 | G7: 会社（自動） | H7: 基地港（自動） | I7: 不稼働日数（自動） | J7: 選択年度の日数（自動） | K7: 入力確認（自動）
G8: =IF(A8="","",IF(COUNTIF(Tugs[曳船名],A8)<>1,"未登録・重複",IF(INDEX(Tugs[会社名],MATCH(A8,Tugs[曳船名],0))="","未確認",INDEX(Tugs[会社名],MATCH(A8,Tugs[曳船名],0))))) | H8: =IF(A8="","",IF(COUNTIF(Tugs[曳船名],A8)<>1,"未登録・重複",IF(INDEX(Tugs[基地港],MATCH(A8,Tugs[曳船名],0))="","未確認",INDEX(Tugs[基地港],MATCH(A8,Tugs[曳船名],0))))) | I8: =IF(A8="","",IF(AND(ISNUMBER(B8),ISNUMBER(C8),C8>=B8),C8-B8,"")) | J8: =IF(A8="","",IF(AND(ISNUMBER(B8),ISNUMBER(C8),C8>=B8),MAX(0,MIN(C8,DATE(集計・確認!$B$5+1,4,1))-MAX(B8,DATE(集計・確認!$B$5,4,1))),"")) | K8: =IF(A8="","",IF(OR(NOT(ISNUMBER(B8)),NOT(ISNUMBER(C8)),C8<B8,D8="",E8="",G8="未登録・重複"),"要確認：日付・登録・根拠を確認",IF(COUNTIFS(Docks[曳船名],A8,Docks[入渠開始日],B8)>1,"要確認：同じ入渠が重複",IF(E8="未確認","要確認：未確認を含む","確認済"))))
G9: =IF(A9="","",IF(COUNTIF(Tugs[曳船名],A9)<>1,"未登録・重複",IF(INDEX(Tugs[会社名],MATCH(A9,Tugs[曳船名],0))="","未確認",INDEX(Tugs[会社名],MATCH(A9,Tugs[曳船名],0))))) | H9: =IF(A9="","",IF(COUNTIF(Tugs[曳船名],A9)<>1,"未登録・重複",IF(INDEX(Tugs[基地港],MATCH(A9,Tugs[曳船名],0))="","未確認",INDEX(Tugs[基地港],MATCH(A9,Tugs[曳船名],0))))) | I9: =IF(A9="","",IF(AND(ISNUMBER(B9),ISNUMBER(C9),C9>=B9),C9-B9,"")) | J9: =IF(A9="","",IF(AND(ISNUMBER(B9),ISNUMBER(C9),C9>=B9),MAX(0,MIN(C9,DATE(集計・確認!$B$5+1,4,1))-MAX(B9,DATE(集計・確認!$B$5,4,1))),"")) | K9: =IF(A9="","",IF(OR(NOT(ISNUMBER(B9)),NOT(ISNUMBER(C9)),C9<B9,D9="",E9="",G9="未登録・重複"),"要確認：日付・登録・根拠を確認",IF(COUNTIFS(Docks[曳船名],A9,Docks[入渠開始日],B9)>1,"要確認：同じ入渠が重複",IF(E9="未確認","要確認：未確認を含む","確認済"))))
G10: =IF(A10="","",IF(COUNTIF(Tugs[曳船名],A10)<>1,"未登録・重複",IF(INDEX(Tugs[会社名],MATCH(A10,Tugs[曳船名],0))="","未確認",INDEX(Tugs[会社名],MATCH(A10,Tugs[曳船名],0))))) | H10: =IF(A10="","",IF(COUNTIF(Tugs[曳船名],A10)<>1,"未登録・重複",IF(INDEX(Tugs[基地港],MATCH(A10,Tugs[曳船名],0))="","未確認",INDEX(Tugs[基地港],MATCH(A10,Tugs[曳船名],0))))) | I10: =IF(A10="","",IF(AND(ISNUMBER(B10),ISNUMBER(C10),C10>=B10),C10-B10,"")) | J10: =IF(A10="","",IF(AND(ISNUMBER(B10),ISNUMBER(C10),C10>=B10),MAX(0,MIN(C10,DATE(集計・確認!$B$5+1,4,1))-MAX(B10,DATE(集計・確認!$B$5,4,1))),"")) | K10: =IF(A10="","",IF(OR(NOT(ISNUMBER(B10)),NOT(ISNUMBER(C10)),C10<B10,D10="",E10="",G10="未登録・重複"),"要確認：日付・登録・根拠を確認",IF(COUNTIFS(Docks[曳船名],A10,Docks[入渠開始日],B10)>1,"要確認：同じ入渠が重複",IF(E10="未確認","要確認：未確認を含む","確認済"))))
G11: =IF(A11="","",IF(COUNTIF(Tugs[曳船名],A11)<>1,"未登録・重複",IF(INDEX(Tugs[会社名],MATCH(A11,Tugs[曳船名],0))="","未確認",INDEX(Tugs[会社名],MATCH(A11,Tugs[曳船名],0))))) | H11: =IF(A11="","",IF(COUNTIF(Tugs[曳船名],A11)<>1,"未登録・重複",IF(INDEX(Tugs[基地港],MATCH(A11,Tugs[曳船名],0))="","未確認",INDEX(Tugs[基地港],MATCH(A11,Tugs[曳船名],0))))) | I11: =IF(A11="","",IF(AND(ISNUMBER(B11),ISNUMBER(C11),C11>=B11),C11-B11,"")) | J11: =IF(A11="","",IF(AND(ISNUMBER(B11),ISNUMBER(C11),C11>=B11),MAX(0,MIN(C11,DATE(集計・確認!$B$5+1,4,1))-MAX(B11,DATE(集計・確認!$B$5,4,1))),"")) | K11: =IF(A11="","",IF(OR(NOT(ISNUMBER(B11)),NOT(ISNUMBER(C11)),C11<B11,D11="",E11="",G11="未登録・重複"),"要確認：日付・登録・根拠を確認",IF(COUNTIFS(Docks[曳船名],A11,Docks[入渠開始日],B11)>1,"要確認：同じ入渠が重複",IF(E11="未確認","要確認：未確認を含む","確認済"))))
G12: =IF(A12="","",IF(COUNTIF(Tugs[曳船名],A12)<>1,"未登録・重複",IF(INDEX(Tugs[会社名],MATCH(A12,Tugs[曳船名],0))="","未確認",INDEX(Tugs[会社名],MATCH(A12,Tugs[曳船名],0))))) | H12: =IF(A12="","",IF(COUNTIF(Tugs[曳船名],A12)<>1,"未登録・重複",IF(INDEX(Tugs[基地港],MATCH(A12,Tugs[曳船名],0))="","未確認",INDEX(Tugs[基地港],MATCH(A12,Tugs[曳船名],0))))) | I12: =IF(A12="","",IF(AND(ISNUMBER(B12),ISNUMBER(C12),C12>=B12),C12-B12,"")) | J12: =IF(A12="","",IF(AND(ISNUMBER(B12),ISNUMBER(C12),C12>=B12),MAX(0,MIN(C12,DATE(集計・確認!$B$5+1,4,1))-MAX(B12,DATE(集計・確認!$B$5,4,1))),"")) | K12: =IF(A12="","",IF(OR(NOT(ISNUMBER(B12)),NOT(ISNUMBER(C12)),C12<B12,D12="",E12="",G12="未登録・重複"),"要確認：日付・登録・根拠を確認",IF(COUNTIFS(Docks[曳船名],A12,Docks[入渠開始日],B12)>1,"要確認：同じ入渠が重複",IF(E12="未確認","要確認：未確認を含む","確認済"))))
G13: =IF(A13="","",IF(COUNTIF(Tugs[曳船名],A13)<>1,"未登録・重複",IF(INDEX(Tugs[会社名],MATCH(A13,Tugs[曳船名],0))="","未確認",INDEX(Tugs[会社名],MATCH(A13,Tugs[曳船名],0))))) | H13: =IF(A13="","",IF(COUNTIF(Tugs[曳船名],A13)<>1,"未登録・重複",IF(INDEX(Tugs[基地港],MATCH(A13,Tugs[曳船名],0))="","未確認",INDEX(Tugs[基地港],MATCH(A13,Tugs[曳船名],0))))) | I13: =IF(A13="","",IF(AND(ISNUMBER(B13),ISNUMBER(C13),C13>=B13),C13-B13,"")) | J13: =IF(A13="","",IF(AND(ISNUMBER(B13),ISNUMBER(C13),C13>=B13),MAX(0,MIN(C13,DATE(集計・確認!$B$5+1,4,1))-MAX(B13,DATE(集計・確認!$B$5,4,1))),"")) | K13: =IF(A13="","",IF(OR(NOT(ISNUMBER(B13)),NOT(ISNUMBER(C13)),C13<B13,D13="",E13="",G13="未登録・重複"),"要確認：日付・登録・根拠を確認",IF(COUNTIFS(Docks[曳船名],A13,Docks[入渠開始日],B13)>1,"要確認：同じ入渠が重複",IF(E13="未確認","要確認：未確認を含む","確認済"))))
G14: =IF(A14="","",IF(COUNTIF(Tugs[曳船名],A14)<>1,"未登録・重複",IF(INDEX(Tugs[会社名],MATCH(A14,Tugs[曳船名],0))="","未確認",INDEX(Tugs[会社名],MATCH(A14,Tugs[曳船名],0))))) | H14: =IF(A14="","",IF(COUNTIF(Tugs[曳船名],A14)<>1,"未登録・重複",IF(INDEX(Tugs[基地港],MATCH(A14,Tugs[曳船名],0))="","未確認",INDEX(Tugs[基地港],MATCH(A14,Tugs[曳船名],0))))) | I14: =IF(A14="","",IF(AND(ISNUMBER(B14),ISNUMBER(C14),C14>=B14),C14-B14,"")) | J14: =IF(A14="","",IF(AND(ISNUMBER(B14),ISNUMBER(C14),C14>=B14),MAX(0,MIN(C14,DATE(集計・確認!$B$5+1,4,1))-MAX(B14,DATE(集計・確認!$B$5,4,1))),"")) | K14: =IF(A14="","",IF(OR(NOT(ISNUMBER(B14)),NOT(ISNUMBER(C14)),C14<B14,D14="",E14="",G14="未登録・重複"),"要確認：日付・登録・根拠を確認",IF(COUNTIFS(Docks[曳船名],A14,Docks[入渠開始日],B14)>1,"要確認：同じ入渠が重複",IF(E14="未確認","要確認：未確認を含む","確認済"))))
G15: =IF(A15="","",IF(COUNTIF(Tugs[曳船名],A15)<>1,"未登録・重複",IF(INDEX(Tugs[会社名],MATCH(A15,Tugs[曳船名],0))="","未確認",INDEX(Tugs[会社名],MATCH(A15,Tugs[曳船名],0))))) | H15: =IF(A15="","",IF(COUNTIF(Tugs[曳船名],A15)<>1,"未登録・重複",IF(INDEX(Tugs[基地港],MATCH(A15,Tugs[曳船名],0))="","未確認",INDEX(Tugs[基地港],MATCH(A15,Tugs[曳船名],0))))) | I15: =IF(A15="","",IF(AND(ISNUMBER(B15),ISNUMBER(C15),C15>=B15),C15-B15,"")) | J15: =IF(A15="","",IF(AND(ISNUMBER(B15),ISNUMBER(C15),C15>=B15),MAX(0,MIN(C15,DATE(集計・確認!$B$5+1,4,1))-MAX(B15,DATE(集計・確認!$B$5,4,1))),"")) | K15: =IF(A15="","",IF(OR(NOT(ISNUMBER(B15)),NOT(ISNUMBER(C15)),C15<B15,D15="",E15="",G15="未登録・重複"),"要確認：日付・登録・根拠を確認",IF(COUNTIFS(Docks[曳船名],A15,Docks[入渠開始日],B15)>1,"要確認：同じ入渠が重複",IF(E15="未確認","要確認：未確認を含む","確認済"))))
G16: =IF(A16="","",IF(COUNTIF(Tugs[曳船名],A16)<>1,"未登録・重複",IF(INDEX(Tugs[会社名],MATCH(A16,Tugs[曳船名],0))="","未確認",INDEX(Tugs[会社名],MATCH(A16,Tugs[曳船名],0))))) | H16: =IF(A16="","",IF(COUNTIF(Tugs[曳船名],A16)<>1,"未登録・重複",IF(INDEX(Tugs[基地港],MATCH(A16,Tugs[曳船名],0))="","未確認",INDEX(Tugs[基地港],MATCH(A16,Tugs[曳船名],0))))) | I16: =IF(A16="","",IF(AND(ISNUMBER(B16),ISNUMBER(C16),C16>=B16),C16-B16,"")) | J16: =IF(A16="","",IF(AND(ISNUMBER(B16),ISNUMBER(C16),C16>=B16),MAX(0,MIN(C16,DATE(集計・確認!$B$5+1,4,1))-MAX(B16,DATE(集計・確認!$B$5,4,1))),"")) | K16: =IF(A16="","",IF(OR(NOT(ISNUMBER(B16)),NOT(ISNUMBER(C16)),C16<B16,D16="",E16="",G16="未登録・重複"),"要確認：日付・登録・根拠を確認",IF(COUNTIFS(Docks[曳船名],A16,Docks[入渠開始日],B16)>1,"要確認：同じ入渠が重複",IF(E16="未確認","要確認：未確認を含む","確認済"))))
G17: =IF(A17="","",IF(COUNTIF(Tugs[曳船名],A17)<>1,"未登録・重複",IF(INDEX(Tugs[会社名],MATCH(A17,Tugs[曳船名],0))="","未確認",INDEX(Tugs[会社名],MATCH(A17,Tugs[曳船名],0))))) | H17: =IF(A17="","",IF(COUNTIF(Tugs[曳船名],A17)<>1,"未登録・重複",IF(INDEX(Tugs[基地港],MATCH(A17,Tugs[曳船名],0))="","未確認",INDEX(Tugs[基地港],MATCH(A17,Tugs[曳船名],0))))) | I17: =IF(A17="","",IF(AND(ISNUMBER(B17),ISNUMBER(C17),C17>=B17),C17-B17,"")) | J17: =IF(A17="","",IF(AND(ISNUMBER(B17),ISNUMBER(C17),C17>=B17),MAX(0,MIN(C17,DATE(集計・確認!$B$5+1,4,1))-MAX(B17,DATE(集計・確認!$B$5,4,1))),"")) | K17: =IF(A17="","",IF(OR(NOT(ISNUMBER(B17)),NOT(ISNUMBER(C17)),C17<B17,D17="",E17="",G17="未登録・重複"),"要確認：日付・登録・根拠を確認",IF(COUNTIFS(Docks[曳船名],A17,Docks[入渠開始日],B17)>1,"要確認：同じ入渠が重複",IF(E17="未確認","要確認：未確認を含む","確認済"))))
G18: =IF(A18="","",IF(COUNTIF(Tugs[曳船名],A18)<>1,"未登録・重複",IF(INDEX(Tugs[会社名],MATCH(A18,Tugs[曳船名],0))="","未確認",INDEX(Tugs[会社名],MATCH(A18,Tugs[曳船名],0))))) | H18: =IF(A18="","",IF(COUNTIF(Tugs[曳船名],A18)<>1,"未登録・重複",IF(INDEX(Tugs[基地港],MATCH(A18,Tugs[曳船名],0))="","未確認",INDEX(Tugs[基地港],MATCH(A18,Tugs[曳船名],0))))) | I18: =IF(A18="","",IF(AND(ISNUMBER(B18),ISNUMBER(C18),C18>=B18),C18-B18,"")) | J18: =IF(A18="","",IF(AND(ISNUMBER(B18),ISNUMBER(C18),C18>=B18),MAX(0,MIN(C18,DATE(集計・確認!$B$5+1,4,1))-MAX(B18,DATE(集計・確認!$B$5,4,1))),"")) | K18: =IF(A18="","",IF(OR(NOT(ISNUMBER(B18)),NOT(ISNUMBER(C18)),C18<B18,D18="",E18="",G18="未登録・重複"),"要確認：日付・登録・根拠を確認",IF(COUNTIFS(Docks[曳船名],A18,Docks[入渠開始日],B18)>1,"要確認：同じ入渠が重複",IF(E18="未確認","要確認：未確認を含む","確認済"))))
G19: =IF(A19="","",IF(COUNTIF(Tugs[曳船名],A19)<>1,"未登録・重複",IF(INDEX(Tugs[会社名],MATCH(A19,Tugs[曳船名],0))="","未確認",INDEX(Tugs[会社名],MATCH(A19,Tugs[曳船名],0))))) | H19: =IF(A19="","",IF(COUNTIF(Tugs[曳船名],A19)<>1,"未登録・重複",IF(INDEX(Tugs[基地港],MATCH(A19,Tugs[曳船名],0))="","未確認",INDEX(Tugs[基地港],MATCH(A19,Tugs[曳船名],0))))) | I19: =IF(A19="","",IF(AND(ISNUMBER(B19),ISNUMBER(C19),C19>=B19),C19-B19,"")) | J19: =IF(A19="","",IF(AND(ISNUMBER(B19),ISNUMBER(C19),C19>=B19),MAX(0,MIN(C19,DATE(集計・確認!$B$5+1,4,1))-MAX(B19,DATE(集計・確認!$B$5,4,1))),"")) | K19: =IF(A19="","",IF(OR(NOT(ISNUMBER(B19)),NOT(ISNUMBER(C19)),C19<B19,D19="",E19="",G19="未登録・重複"),"要確認：日付・登録・根拠を確認",IF(COUNTIFS(Docks[曳船名],A19,Docks[入渠開始日],B19)>1,"要確認：同じ入渠が重複",IF(E19="未確認","要確認：未確認を含む","確認済"))))
... G307: =IF(A307="","",IF(COUNTIF(Tugs[曳船名],A307)<>1,"未登録・重複",IF(INDEX(Tugs[会社名],MATCH(A307,Tugs[曳船名],0))="","未確認",INDEX(Tugs[会社名],MATCH(A307,Tugs[曳船名],0))))) | H307: =IF(A307="","",IF(COUNTIF(Tugs[曳船名],A307)<>1,"未登録・重複",IF(INDEX(Tugs[基地港],MATCH(A307,Tugs[曳船名],0))="","未確認",INDEX(Tugs[基地港],MATCH(A307,Tugs[曳船名],0))))) | I307: =IF(A307="","",IF(AND(ISNUMBER(B307),ISNUMBER(C307),C307>=B307),C307-B307,"")) | J307: =IF(A307="","",IF(AND(ISNUMBER(B307),ISNUMBER(C307),C307>=B307),MAX(0,MIN(C307,DATE(集計・確認!$B$5+1,4,1))-MAX(B307,DATE(集計・確認!$B$5,4,1))),"")) | K307: =IF(A307="","",IF(OR(NOT(ISNUMBER(B307)),NOT(ISNUMBER(C307)),C307<B307,D307="",E307="",G307="未登録・重複"),"要確認：日付・登録・根拠を確認",IF(COUNTIFS(Docks[曳船名],A307,Docks[入渠開始日],B307)>1,"要確認：同じ入渠が重複",IF(E307="未確認","要確認：未確認を含む","確認済"))))

Sheet 関豊丸・長豊丸の他港作業
A2: 関豊丸・長豊丸の他港作業
A3: 関豊丸・長豊丸が他港の仕事で門司を離れた時間を記録。料金は分かる場合だけ入力し、不明は空欄。港名は実際の港を登録。回航込みの拘束時間と請求時間を混同しない。
A7: 作業日 | B7: 曳船名 | C7: 他港の港名 | D7: 船名 | E7: 入出・転／作業内容 | F7: 門司港発 | G7: 他港作業開始 | H7: 他港作業終了 | I7: 門司港着 | J7: 回航込みh（記録の時間） | K7: 作業料金円 | L7: 確認元 | M7: 記録区分 | N7: 補足 | O7: 回航込み拘束h（自動） | P7: 時間根拠（自動） | Q7: 年度（自動） | R7: 入力確認（自動） | S7: 料金未確認（自動）
O8: =IF(B8="","",IF(AND(ISNUMBER(F8),ISNUMBER(I8),I8>=F8),ROUND((I8-F8)*24,4),IF(OR(F8<>"",I8<>""),"",IF(AND(ISNUMBER(J8),J8>=0),J8,"")))) | P8: =IF(B8="","",IF(AND(ISNUMBER(F8),ISNUMBER(I8),I8>=F8),"実績：門司発～門司着",IF(OR(F8<>"",I8<>""),"要確認：時刻不足・逆転",IF(AND(ISNUMBER(J8),J8>=0),"実績：記録の時間","未確認")))) | Q8: =IF(B8="","",IF(ISNUMBER(A8),YEAR(A8)-IF(MONTH(A8)<4,1,0),"")) | R8: =IF(B8="","",IF(OR(NOT(ISNUMBER(A8)),C8="",D8="",L8="",M8="",AND(B8<>"関豊丸",B8<>"長豊丸")),"要確認：対象船・基本項目",IF(OR(P8="要確認：時刻不足・逆転",AND(ISNUMBER(G8),ISNUMBER(H8),H8<G8),AND(ISNUMBER(F8),ISNUMBER(G8),G8<F8),AND(ISNUMBER(H8),ISNUMBER(I8),I8<H8),AND(ISNUMBER(J8),J8<0),AND(ISNUMBER(K8),K8<0)),"要確認：時刻・時間・料金",IF(COUNTIFS(OtherPorts[作業日],A8,OtherPorts[曳船名],B8,OtherPorts[船名],D8,OtherPorts[門司港発],F8)>1,"要確認：同じ他港作業が重複",IF(OR(NOT(ISNUMBER(O8)),M8="未確認"),"要確認：時間・根拠未確認","確認済"))))) | S8: =IF(B8="","",IF(ISNUMBER(K8),0,1))
O9: =IF(B9="","",IF(AND(ISNUMBER(F9),ISNUMBER(I9),I9>=F9),ROUND((I9-F9)*24,4),IF(OR(F9<>"",I9<>""),"",IF(AND(ISNUMBER(J9),J9>=0),J9,"")))) | P9: =IF(B9="","",IF(AND(ISNUMBER(F9),ISNUMBER(I9),I9>=F9),"実績：門司発～門司着",IF(OR(F9<>"",I9<>""),"要確認：時刻不足・逆転",IF(AND(ISNUMBER(J9),J9>=0),"実績：記録の時間","未確認")))) | Q9: =IF(B9="","",IF(ISNUMBER(A9),YEAR(A9)-IF(MONTH(A9)<4,1,0),"")) | R9: =IF(B9="","",IF(OR(NOT(ISNUMBER(A9)),C9="",D9="",L9="",M9="",AND(B9<>"関豊丸",B9<>"長豊丸")),"要確認：対象船・基本項目",IF(OR(P9="要確認：時刻不足・逆転",AND(ISNUMBER(G9),ISNUMBER(H9),H9<G9),AND(ISNUMBER(F9),ISNUMBER(G9),G9<F9),AND(ISNUMBER(H9),ISNUMBER(I9),I9<H9),AND(ISNUMBER(J9),J9<0),AND(ISNUMBER(K9),K9<0)),"要確認：時刻・時間・料金",IF(COUNTIFS(OtherPorts[作業日],A9,OtherPorts[曳船名],B9,OtherPorts[船名],D9,OtherPorts[門司港発],F9)>1,"要確認：同じ他港作業が重複",IF(OR(NOT(ISNUMBER(O9)),M9="未確認"),"要確認：時間・根拠未確認","確認済"))))) | S9: =IF(B9="","",IF(ISNUMBER(K9),0,1))
O10: =IF(B10="","",IF(AND(ISNUMBER(F10),ISNUMBER(I10),I10>=F10),ROUND((I10-F10)*24,4),IF(OR(F10<>"",I10<>""),"",IF(AND(ISNUMBER(J10),J10>=0),J10,"")))) | P10: =IF(B10="","",IF(AND(ISNUMBER(F10),ISNUMBER(I10),I10>=F10),"実績：門司発～門司着",IF(OR(F10<>"",I10<>""),"要確認：時刻不足・逆転",IF(AND(ISNUMBER(J10),J10>=0),"実績：記録の時間","未確認")))) | Q10: =IF(B10="","",IF(ISNUMBER(A10),YEAR(A10)-IF(MONTH(A10)<4,1,0),"")) | R10: =IF(B10="","",IF(OR(NOT(ISNUMBER(A10)),C10="",D10="",L10="",M10="",AND(B10<>"関豊丸",B10<>"長豊丸")),"要確認：対象船・基本項目",IF(OR(P10="要確認：時刻不足・逆転",AND(ISNUMBER(G10),ISNUMBER(H10),H10<G10),AND(ISNUMBER(F10),ISNUMBER(G10),G10<F10),AND(ISNUMBER(H10),ISNUMBER(I10),I10<H10),AND(ISNUMBER(J10),J10<0),AND(ISNUMBER(K10),K10<0)),"要確認：時刻・時間・料金",IF(COUNTIFS(OtherPorts[作業日],A10,OtherPorts[曳船名],B10,OtherPorts[船名],D10,OtherPorts[門司港発],F10)>1,"要確認：同じ他港作業が重複",IF(OR(NOT(ISNUMBER(O10)),M10="未確認"),"要確認：時間・根拠未確認","確認済"))))) | S10: =IF(B10="","",IF(ISNUMBER(K10),0,1))
O11: =IF(B11="","",IF(AND(ISNUMBER(F11),ISNUMBER(I11),I11>=F11),ROUND((I11-F11)*24,4),IF(OR(F11<>"",I11<>""),"",IF(AND(ISNUMBER(J11),J11>=0),J11,"")))) | P11: =IF(B11="","",IF(AND(ISNUMBER(F11),ISNUMBER(I11),I11>=F11),"実績：門司発～門司着",IF(OR(F11<>"",I11<>""),"要確認：時刻不足・逆転",IF(AND(ISNUMBER(J11),J11>=0),"実績：記録の時間","未確認")))) | Q11: =IF(B11="","",IF(ISNUMBER(A11),YEAR(A11)-IF(MONTH(A11)<4,1,0),"")) | R11: =IF(B11="","",IF(OR(NOT(ISNUMBER(A11)),C11="",D11="",L11="",M11="",AND(B11<>"関豊丸",B11<>"長豊丸")),"要確認：対象船・基本項目",IF(OR(P11="要確認：時刻不足・逆転",AND(ISNUMBER(G11),ISNUMBER(H11),H11<G11),AND(ISNUMBER(F11),ISNUMBER(G11),G11<F11),AND(ISNUMBER(H11),ISNUMBER(I11),I11<H11),AND(ISNUMBER(J11),J11<0),AND(ISNUMBER(K11),K11<0)),"要確認：時刻・時間・料金",IF(COUNTIFS(OtherPorts[作業日],A11,OtherPorts[曳船名],B11,OtherPorts[船名],D11,OtherPorts[門司港発],F11)>1,"要確認：同じ他港作業が重複",IF(OR(NOT(ISNUMBER(O11)),M11="未確認"),"要確認：時間・根拠未確認","確認済"))))) | S11: =IF(B11="","",IF(ISNUMBER(K11),0,1))
O12: =IF(B12="","",IF(AND(ISNUMBER(F12),ISNUMBER(I12),I12>=F12),ROUND((I12-F12)*24,4),IF(OR(F12<>"",I12<>""),"",IF(AND(ISNUMBER(J12),J12>=0),J12,"")))) | P12: =IF(B12="","",IF(AND(ISNUMBER(F12),ISNUMBER(I12),I12>=F12),"実績：門司発～門司着",IF(OR(F12<>"",I12<>""),"要確認：時刻不足・逆転",IF(AND(ISNUMBER(J12),J12>=0),"実績：記録の時間","未確認")))) | Q12: =IF(B12="","",IF(ISNUMBER(A12),YEAR(A12)-IF(MONTH(A12)<4,1,0),"")) | R12: =IF(B12="","",IF(OR(NOT(ISNUMBER(A12)),C12="",D12="",L12="",M12="",AND(B12<>"関豊丸",B12<>"長豊丸")),"要確認：対象船・基本項目",IF(OR(P12="要確認：時刻不足・逆転",AND(ISNUMBER(G12),ISNUMBER(H12),H12<G12),AND(ISNUMBER(F12),ISNUMBER(G12),G12<F12),AND(ISNUMBER(H12),ISNUMBER(I12),I12<H12),AND(ISNUMBER(J12),J12<0),AND(ISNUMBER(K12),K12<0)),"要確認：時刻・時間・料金",IF(COUNTIFS(OtherPorts[作業日],A12,OtherPorts[曳船名],B12,OtherPorts[船名],D12,OtherPorts[門司港発],F12)>1,"要確認：同じ他港作業が重複",IF(OR(NOT(ISNUMBER(O12)),M12="未確認"),"要確認：時間・根拠未確認","確認済"))))) | S12: =IF(B12="","",IF(ISNUMBER(K12),0,1))
